Workbook

Sheet Sheet2
A1: Sr No | B1: Material | C1: Material Description | D1: Qty | E1: NOK | F1: Net Opening | G1: VIN Done | H1: Inwarded | I1: Fresh VIN Opening | J1: Remark
A2: 1 | B2: 544254610241 | C2: WH MAIN_Accomplished + (NA+CNG) | D2: 15 | E2: 2 | F2: =D2-E2 -> 13 | G2: 0 | H2: =10 -> 10 | I2: =F2+G2-H2 -> 3 | J2: (As discussed With Aptive Qre and 02 wiring are 34 connector Aviblae But required 24 connector)
A3: 2 | B3: 544254640254 | C3: WH MAIN | D3: 0 | E3: 0 | F3: =D3-E3 -> 0 | G3: 0 | I3: =F3+G3-H3 -> 0
A4: 3 | B4: 544254630510 | C4: WH MAIN | D4: 40 | E4: 9 | F4: =D4-E4 -> 31 | G4: 0 | H4: 10 | I4: =F4+G4-H4 -> 21 | J4: (As discussed With Aptive Qre and 09 wiring are 34 connector Aviblae But required 24 connector)
A5: 4 | B5: 544254640219 | C5: WH MAIN | D5: 28 | E5: 12 | F5: =D5-E5 -> 16 | G5: 0 | H5: 10 | I5: =F5+G5-H5 -> 6 | J5: (As discussed With Aptive Qre and 12 wiring are 34 connector Aviblae But required 24 connector)
A6: 5 | B6: 544254630512 | C6: WH MAIN | D6: 1 | E6: 1 | F6: =D6-E6 -> 0 | G6: 0 | I6: =F6+G6-H6 -> 0 | J6: (wiring are 34 connector Available But required 24 connector)
A7: 6 | B7: 544254630499 | C7: WH MAIN | D7: 3 | E7: 3 | F7: =D7-E7 -> 0 | G7: 0 | I7: =F7+G7-H7 -> 0 | J7: (wiring are 34 connector Available But required 24 connector)
A8: 7 | B8: 544254610239 | C8: WH MAIN | D8: 0 | E8: 0 | F8: =D8-E8 -> 0 | G8: 0 | I8: =F8+G8-H8 -> 0
A9: 8 | B9: 544254640251 | C9: WH MAIN | D9: 0 | E9: 0 | F9: =D9-E9 -> 0 | G9: 0 | I9: =F9+G9-H9 -> 0
A10: 9 | B10: 544254630476 | C10: WH MAIN | D10: 0 | E10: 0 | F10: =D10-E10 -> 0 | G10: 0 | I10: =F10+G10-H10 -> 0
A11: 10 | B11: 544254630490 | C11: WH MAIN | D11: 0 | E11: 0 | F11: =D11-E11 -> 0 | G11: 0 | I11: =F11+G11-H11 -> 0
A12: 11 | B12: 544254630871 | C12: WH MAIN | D12: 0 | E12: 0 | F12: =D12-E12 -> 0 | G12: 0 | I12: =F12+G12-H12 -> 0
A13: 12 | B13: 544254640267 | C13: WH MAIN | D13: 7 | E13: 0 | F13: =D13-E13 -> 7 | G13: 0 | H13: 5 | I13: =F13+G13-H13 -> 2
A14: 13 | B14: 544254640203 | C14: WH MAIN | D14: 0 | E14: 0 | F14: =D14-E14 -> 0 | G14: 0 | I14: =F14+G14-H14 -> 0
A15: 14 | B15: 544254640202 | C15: WH MAIN | D15: 0 | E15: 0 | F15: =D15-E15 -> 0 | G15: 0 | I15: =F15+G15-H15 -> 0
A16: 15 | B16: 544254640248 | C16: WH MAIN | D16: 7 | E16: 0 | F16: =D16-E16 -> 7 | G16: 0 | H16: =5 -> 5 | I16: =F16+G16-H16 -> 2
A17: 16 | B17: 544254640213 | C17: WH MAIN | D17: 7 | E17: 0 | F17: =D17-E17 -> 7 | G17: 0 | H17: 5 | I17: =F17+G17-H17 -> 2
A18: 17 | B18: 544254640197 | C18: WH MAIN | D18: 10 | E18: 0 | F18: =D18-E18 -> 10 | G18: 0 | H18: 5 | I18: =F18+G18-H18 -> 5
B21: 544254630512
B22: 544254630510
B23: 544254640219
B24: 544254630499
B25: 544254640202
B26: 544254640207
B27: 544254610240
B28: 544254630486
B29: 544254610239
B30: 544254630490
B31: 544254630503
B32: 544254630476
... B53: 544254640251

Sheet Fresh VIN PPC
A1: Date : 09.06.2022 | C1: ='3 D P'!P1 -> Date | D1: 549754600102
M2: =SUM(M140,M146) -> 401 | S2: =+S140+S146 -> 0 | T2: =T140+T146 -> #REF! | AC2: opening 31otc
X3: =SUM(X140,X146) -> 0
A4: Part No | B4: Pre | C4: : | D4: AB12 Part No | E4: VC No | F4: Model | G4: PLAN | H4: W/H Requirement | I4: Month O/P | J4: Inwards | K4: Consumption | L4: Balance Production | M4: Today's O/P | N4: ='3 D P'!L2 -> 46221 | O4: ='3 D P'!M2 -> 46222 | P4: ='3 D P'!N2 -> 46223 | Q4: Cumulative Dispatch | R4: Consumption | S4: A SHIFT BIW LIFTING | T4: B SHIFT BIW LIFTING | U4: Float Coverage at 6:30am | V4: Float Coverage at 3 pm | W4: Float Coverage at 11:30 pm | X4: Paint float 06:30am | Y4: Balance To Inward | AA4: Safety Stock | AF4: PBS FLOAT | AG4: PBS TO POLISHING | AH4: POLISHING TO TOPCOAT | AI4: TOPCOAT TO WETSANDING ROOFBLACK | AJ4: TOPCOAT TO WETSANDING FRESH | AK4: WETSANDING TO SEALANT | AL4: TOTAL UPTO SEALANT | AM4: PT ENTRY TO SEALENT | AN4: BIW LIFTING TO PT | AO4: PT BYPASS | AP4: Total
B5: 544254630181 | C5: 544254630390 | D5: 544254630390 | E5: 54425125A | F5: ALTROZ XE 1.2P BS6GEN1+ | G5: 0 | H5: =G5 -> 0 | I5: 22 | J5: =Q5 -> 0 | K5: =R5 -> 0 | L5: =H5-K5 -> 0 | M5: =I5+J5-K5 -> 22 | N5: =SUMIF('3 D P'!$D:$D,Cockpit!$E$5:$E$146,'3 D P'!L:L) -> 0 | O5: =SUMIF('3 D P'!$D:$D,Cockpit!$E$5:$E$146,'3 D P'!M:M) -> 0 | P5: =SUMIF('3 D P'!$D:$D,Cockpit!$E$5:$E$146,'3 D P'!N:N) -> 0 | Q5: =IFERROR(VLOOKUP($D5,'Aptiv Dispatch'!$A:$B,2,FALSE),0) -> 0 | R5: =SUMIF('Consumption MTD'!B:B,Cockpit!$E$5:$E$146,'Consumption MTD'!C:C) -> 0 | S5: =SUMIF('BIW Lifting A Shift'!$B:$B,Cockpit!$E$5:$E$146,'BIW Lifting A Shift'!C:C) -> 0 | T5: =SUMIF('BIW Lifting A Shift'!$B:$B,Cockpit!$E$5:$E$146,'BIW Lifting A Shift'!#REF!) -> #REF! | U5: =M5-X5 -> 22 | V5: =M5-S5-X5 -> 22 | W5: =V5-T5 -> #REF! | X5: =SUMIF(FLOAT!$D:$D,Cockpit!$E$5:$E$146,FLOAT!F:F) -> 0 | Y5: =IFERROR(VLOOKUP(E5,[4]Sheet1!$D$4:$G$83,4,0),0) -> 0 | Z5: =IFERROR(VLOOKUP(E5,'[5]Cockpit Main'!$D$4:$G$83,4,0),0) -> 0 | AA5: 0 | AC5: 19 | AF5: =SUMIF(FLOAT!$D:$D,Cockpit!$E5:$E146,FLOAT!G:G) -> 0 | AG5: =SUMIF(FLOAT!$D:$D,Cockpit!$E5:$E146,FLOAT!H:H) -> 0 | AH5: =SUMIF(FLOAT!$D:$D,Cockpit!$E5:$E146,FLOAT!I:I) -> 0 | AI5: =SUMIF(FLOAT!$D:$D,Cockpit!$E5:$E146,FLOAT!J:J) -> 0 | AJ5: =SUMIF(FLOAT!$D:$D,Cockpit!$E5:$E146,FLOAT!K:K) -> 0 | AK5: =SUMIF(FLOAT!$D:$D,Cockpit!$E5:$E146,FLOAT!L:L) -> 0 | AL5: =SUMIF(FLOAT!$D:$D,Cockpit!$E5:$E146,FLOAT!M:M) -> 0 | AM5: =SUMIF(FLOAT!$D:$D,Cockpit!$E5:$E146,FLOAT!N:N) -> 0 | AN5: =SUMIF(FLOAT!$D:$D,Cockpit!$E5:$E146,FLOAT!O:O) -> 0 | AO5: =SUMIF(FLOAT!$D:$D,Cockpit!$E5:$E146,FLOAT!P:P) -> 0 | AP5: =AF5+AG5+AH5+AI5+AJ5+AK5+AM5+AN5+AO5 -> 0
C6: 544254600375 | D6: 544254600108 | E6: 54421826A | F6: ALTROZ XE 1.2 P BS6 PH2 (REVARIANT) | G6: 0 | H6: =G6 -> 0 | I6: 0 | J6: =Q6 -> 0 | K6: =R6 -> 0 | L6: =H6-K6 -> 0 | M6: =I6+J6-K6 -> 0 | N6: =SUMIF('3 D P'!$D:$D,Cockpit!$E$5:$E$146,'3 D P'!L:L) -> 0 | O6: =SUMIF('3 D P'!$D:$D,Cockpit!$E$5:$E$146,'3 D P'!M:M) -> 0 | P6: =SUMIF('3 D P'!$D:$D,Cockpit!$E$5:$E$146,'3 D P'!N:N) -> 0 | Q6: =IFERROR(VLOOKUP($D6,'Aptiv Dispatch'!$A:$B,2,FALSE),0) -> 0 | R6: =SUMIF('Consumption MTD'!B:B,Cockpit!$E$5:$E$146,'Consumption MTD'!C:C) -> 0 | S6: =SUMIF('BIW Lifting A Shift'!$B:$B,Cockpit!$E$5:$E$146,'BIW Lifting A Shift'!C:C) -> 0 | T6: =SUMIF('BIW Lifting A Shift'!$B:$B,Cockpit!$E$5:$E$146,'BIW Lifting A Shift'!#REF!) -> #REF! | U6: =M6-X6 -> 0 | V6: =M6-S6-X6 -> 0 | W6: =V6-T6 -> #REF! | X6: =SUMIF(FLOAT!$D:$D,Cockpit!$E$5:$E$146,FLOAT!F:F) -> 0 | Y6: =IFERROR(VLOOKUP(E6,[4]Sheet1!$D$4:$G$83,4,0),0) -> 0 | Z6: =IFERROR(VLOOKUP(E6,'[5]Cockpit Main'!$D$4:$G$83,4,0),0) -> 0 | AA6: 3 | AC6: 13 | AF6: =SUMIF(FLOAT!$D:$D,Cockpit!$E6:$E150,FLOAT!G:G) -> 0 | AG6: =SUMIF(FLOAT!$D:$D,Cockpit!$E6:$E150,FLOAT!H:H) -> 0 | AH6: =SUMIF(FLOAT!$D:$D,Cockpit!$E6:$E150,FLOAT!I:I) -> 0 | AI6: =SUMIF(FLOAT!$D:$D,Cockpit!$E6:$E150,FLOAT!J:J) -> 0 | AJ6: =SUMIF(FLOAT!$D:$D,Cockpit!$E6:$E150,FLOAT!K:K) -> 0 | AK6: =SUMIF(FLOAT!$D:$D,Cockpit!$E6:$E150,FLOAT!L:L) -> 0 | AL6: =SUMIF(FLOAT!$D:$D,Cockpit!$E6:$E150,FLOAT!M:M) -> 0 | AM6: =SUMIF(FLOAT!$D:$D,Cockpit!$E6:$E150,FLOAT!N:N) -> 0 | AN6: =SUMIF(FLOAT!$D:$D,Cockpit!$E6:$E150,FLOAT!O:O) -> 0 | AO6: =SUMIF(FLOAT!$D:$D,Cockpit!$E6:$E150,FLOAT!P:P) -> 0 | AP6: =AF6+AG6+AH6+AI6+AJ6+AK6+AM6+AN6+AO6 -> 0
A7: 544254620249 | B7: 544254630159 | C7: 544254630392 | D7: 544254630392 | E7: 54420225A | F7: Altroz XE+ Diesel | G7: 0 | H7: =SUM(G7:G8) -> 0 | I7: 43 | J7: =Q7 -> 0 | K7: =SUM(R7:R8) -> 0 | L7: =H7-K7 -> 0 | M7: =I7+J7-K7 -> 43 | N7: =SUMIF('3 D P'!$D:$D,Cockpit!$E$5:$E$146,'3 D P'!L:L) -> 0 | O7: =SUMIF('3 D P'!$D:$D,Cockpit!$E$5:$E$146,'3 D P'!M:M) -> 0 | P7: =SUMIF('3 D P'!$D:$D,Cockpit!$E$5:$E$146,'3 D P'!N:N) -> 0 | Q7: =IFERROR(VLOOKUP($D7,'Aptiv Dispatch'!$A:$B,2,FALSE),0) -> 0 | R7: =SUMIF('Consumption MTD'!B:B,Cockpit!$E$5:$E$146,'Consumption MTD'!C:C) -> 0 | S7: =SUMIF('BIW Lifting A Shift'!$B:$B,Cockpit!$E$5:$E$146,'BIW Lifting A Shift'!C:C) -> 0 | T7: =SUMIF('BIW Lifting A Shift'!$B:$B,Cockpit!$E$5:$E$146,'BIW Lifting A Shift'!#REF!) -> #REF! | U7: =M7-X7-X8 -> 43 | V7: =M7-X7-X8-S7-S8 -> 43 | W7: =V7-SUM(T7:T8) -> #REF! | X7: =SUMIF(FLOAT!$D:$D,Cockpit!$E$5:$E$146,FLOAT!F:F) -> 0 | Y7: =IFERROR(VLOOKUP(E7,[4]Sheet1!$D$4:$G$83,4,0),0) -> 0 | Z7: =IFERROR(VLOOKUP(E7,'[5]Cockpit Main'!$D$4:$G$83,4,0),0) -> 0 | AA7: 3 | AC7: 27 | AF7: =SUMIF(FLOAT!$D:$D,Cockpit!$E7:$E151,FLOAT!G:G) -> 0 | AG7: =SUMIF(FLOAT!$D:$D,Cockpit!$E7:$E151,FLOAT!H:H) -> 0 | AH7: =SUMIF(FLOAT!$D:$D,Cockpit!$E7:$E151,FLOAT!I:I) -> 0 | AI7: =SUMIF(FLOAT!$D:$D,Cockpit!$E7:$E151,FLOAT!J:J) -> 0 | AJ7: =SUMIF(FLOAT!$D:$D,Cockpit!$E7:$E151,FLOAT!K:K) -> 0 | AK7: =SUMIF(FLOAT!$D:$D,Cockpit!$E7:$E151,FLOAT!L:L) -> 0 | AL7: =SUMIF(FLOAT!$D:$D,Cockpit!$E7:$E151,FLOAT!M:M) -> 0 | AM7: =SUMIF(FLOAT!$D:$D,Cockpit!$E7:$E151,FLOAT!N:N) -> 0 | AN7: =SUMIF(FLOAT!$D:$D,Cockpit!$E7:$E151,FLOAT!O:O) -> 0 | AO7: =SUMIF(FLOAT!$D:$D,Cockpit!$E7:$E151,FLOAT!P:P) -> 0 | AP7: =AF7+AG7+AH7+AI7+AJ7+AK7+AM7+AN7+AO7 -> 0
B8: 544254630186 | E8: 54426225A | F8: ALTROZ XE+ 1.2P BS6GEN1+ | G8: 0 | N8: =SUMIF('3 D P'!$D:$D,Cockpit!$E$5:$E$146,'3 D P'!L:L) -> 0 | O8: =SUMIF('3 D P'!$D:$D,Cockpit!$E$5:$E$146,'3 D P'!M:M) -> 0 | P8: =SUMIF('3 D P'!$D:$D,Cockpit!$E$5:$E$146,'3 D P'!N:N) -> 0 | Q8: =IFERROR(VLOOKUP($D8,'Aptiv Dispatch'!$A:$B,2,FALSE),0) -> 0 | R8: =SUMIF('Consumption MTD'!B:B,Cockpit!$E$5:$E$146,'Consumption MTD'!C:C) -> 0 | S8: =SUMIF('BIW Lifting A Shift'!$B:$B,Cockpit!$E$5:$E$146,'BIW Lifting A Shift'!C:C) -> 0 | T8: =SUMIF('BIW Lifting A Shift'!$B:$B,Cockpit!$E$5:$E$146,'BIW Lifting A Shift'!#REF!) -> #REF! | X8: =SUMIF(FLOAT!$D:$D,Cockpit!$E$5:$E$146,FLOAT!F:F) -> 0 | Y8: =IFERROR(VLOOKUP(E8,[4]Sheet1!$D$4:$G$83,4,0),0) -> 0 | Z8: =IFERROR(VLOOKUP(E8,'[5]Cockpit Main'!$D$4:$G$83,4,0),0) -> 0 | AA8: 0 | AF8: =SUMIF(FLOAT!$D:$D,Cockpit!$E8:$E152,FLOAT!G:G) -> 0 | AG8: =SUMIF(FLOAT!$D:$D,Cockpit!$E8:$E152,FLOAT!H:H) -> 0 | AH8: =SUMIF(FLOAT!$D:$D,Cockpit!$E8:$E152,FLOAT!I:I) -> 0 | AI8: =SUMIF(FLOAT!$D:$D,Cockpit!$E8:$E152,FLOAT!J:J) -> 0 | AJ8: =SUMIF(FLOAT!$D:$D,Cockpit!$E8:$E152,FLOAT!K:K) -> 0 | AK8: =SUMIF(FLOAT!$D:$D,Cockpit!$E8:$E152,FLOAT!L:L) -> 0 | AL8: =SUMIF(FLOAT!$D:$D,Cockpit!$E8:$E152,FLOAT!M:M) -> 0 | AM8: =SUMIF(FLOAT!$D:$D,Cockpit!$E8:$E152,FLOAT!N:N) -> 0 | AN8: =SUMIF(FLOAT!$D:$D,Cockpit!$E8:$E152,FLOAT!O:O) -> 0 | AO8: =SUMIF(FLOAT!$D:$D,Cockpit!$E8:$E152,FLOAT!P:P) -> 0 | AP8: =AF8+AG8+AH8+AI8+AJ8+AK8+AM8+AN8+AO8 -> 0
C9: 544254600376 | D9: 544254600109 | E9: 54422126A | F9: ALTROZ XM 1.2P BS6 PH2(REVARIANT) | G9: 0 | H9: =G9 -> 0 | I9: 0 | J9: =Q9 -> 0 | K9: =R9 -> 0 | L9: =H9-K9 -> 0 | M9: =I9+J9-K9 -> 0 | N9: =SUMIF('3 D P'!$D:$D,Cockpit!$E$5:$E$146,'3 D P'!L:L) -> 0 | O9: =SUMIF('3 D P'!$D:$D,Cockpit!$E$5:$E$146,'3 D P'!M:M) -> 0 | P9: =SUMIF('3 D P'!$D:$D,Cockpit!$E$5:$E$146,'3 D P'!N:N) -> 0 | Q9: =IFERROR(VLOOKUP($D9,'Aptiv Dispatch'!$A:$B,2,FALSE),0) -> 0 | R9: =SUMIF('Consumption MTD'!B:B,Cockpit!$E$5:$E$146,'Consumption MTD'!C:C) -> 0 | S9: =SUMIF('BIW Lifting A Shift'!$B:$B,Cockpit!$E$5:$E$146,'BIW Lifting A Shift'!C:C) -> 0 | T9: =SUMIF('BIW Lifting A Shift'!$B:$B,Cockpit!$E$5:$E$146,'BIW Lifting A Shift'!#REF!) -> #REF! | U9: =M9-X9 -> 0 | V9: =M9-S9-X9 -> 0 | W9: =V9-T9 -> #REF! | X9: =SUMIF(FLOAT!$D:$D,Cockpit!$E$5:$E$146,FLOAT!F:F) -> 0 | Y9: =IFERROR(VLOOKUP(E9,[4]Sheet1!$D$4:$G$83,4,0),0) -> 0 | Z9: =IFERROR(VLOOKUP(E9,'[5]Cockpit Main'!$D$4:$G$83,4,0),0) -> 0 | AA9: 3 | AC9: 42 | AF9: =SUMIF(FLOAT!$D:$D,Cockpit!$E9:$E153,FLOAT!G:G) -> 0 | AG9: =SUMIF(FLOAT!$D:$D,Cockpit!$E9:$E153,FLOAT!H:H) -> 0 | AH9: =SUMIF(FLOAT!$D:$D,Cockpit!$E9:$E153,FLOAT!I:I) -> 0 | AI9: =SUMIF(FLOAT!$D:$D,Cockpit!$E9:$E153,FLOAT!J:J) -> 0 | AJ9: =SUMIF(FLOAT!$D:$D,Cockpit!$E9:$E153,FLOAT!K:K) -> 0 | AK9: =SUMIF(FLOAT!$D:$D,Cockpit!$E9:$E153,FLOAT!L:L) -> 0 | AL9: =SUMIF(FLOAT!$D:$D,Cockpit!$E9:$E153,FLOAT!M:M) -> 0 | AM9: =SUMIF(FLOAT!$D:$D,Cockpit!$E9:$E153,FLOAT!N:N) -> 0 | AN9: =SUMIF(FLOAT!$D:$D,Cockpit!$E9:$E153,FLOAT!O:O) -> 0 | AO9: =SUMIF(FLOAT!$D:$D,Cockpit!$E9:$E153,FLOAT!P:P) -> 0 | AP9: =AF9+AG9+AH9+AI9+AJ9+AK9+AM9+AN9+AO9 -> 0
C10: 544254600377 | D10: 544254600110 | E10: 54422026A | F10: ALTROZ XM (S)1.2P BS6 PH2(REVARIANT) | G10: 0 | H10: =G10 -> 0 | I10: 0 | J10: =Q10 -> 0 | K10: =R10 -> 0 | L10: =H10-K10 -> 0 | M10: =I10+J10-K10 -> 0 | N10: =SUMIF('3 D P'!$D:$D,Cockpit!$E$5:$E$146,'3 D P'!L:L) -> 0 | O10: =SUMIF('3 D P'!$D:$D,Cockpit!$E$5:$E$146,'3 D P'!M:M) -> 0 | P10: =SUMIF('3 D P'!$D:$D,Cockpit!$E$5:$E$146,'3 D P'!N:N) -> 0 | Q10: =IFERROR(VLOOKUP($D10,'Aptiv Dispatch'!$A:$B,2,FALSE),0) -> 0 | R10: =SUMIF('Consumption MTD'!B:B,Cockpit!$E$5:$E$146,'Consumption MTD'!C:C) -> 0 | S10: =SUMIF('BIW Lifting A Shift'!$B:$B,Cockpit!$E$5:$E$146,'BIW Lifting A Shift'!C:C) -> 0 | T10: =SUMIF('BIW Lifting A Shift'!$B:$B,Cockpit!$E$5:$E$146,'BIW Lifting A Shift'!#REF!) -> #REF! | U10: =M10-X10 -> 0 | V10: =M10-S10-X10 -> 0 | W10: =V10-T10 -> #REF! | X10: =SUMIF(FLOAT!$D:$D,Cockpit!$E$5:$E$146,FLOAT!F:F) -> 0 | Y10: =IFERROR(VLOOKUP(E10,[4]Sheet1!$D$4:$G$83,4,0),0) -> 0 | Z10: =IFERROR(VLOOKUP(E10,'[5]Cockpit Main'!$D$4:$G$83,4,0),0) -> 0 | AA10: 3 | AC10: 10 | AF10: =SUMIF(FLOAT!$D:$D,Cockpit!$E10:$E154,FLOAT!G:G) -> 0 | AG10: =SUMIF(FLOAT!$D:$D,Cockpit!$E10:$E154,FLOAT!H:H) -> 0 | AH10: =SUMIF(FLOAT!$D:$D,Cockpit!$E10:$E154,FLOAT!I:I) -> 0 | AI10: =SUMIF(FLOAT!$D:$D,Cockpit!$E10:$E154,FLOAT!J:J) -> 0 | AJ10: =SUMIF(FLOAT!$D:$D,Cockpit!$E10:$E154,FLOAT!K:K) -> 0 | AK10: =SUMIF(FLOAT!$D:$D,Cockpit!$E10:$E154,FLOAT!L:L) -> 0 | AL10: =SUMIF(FLOAT!$D:$D,Cockpit!$E10:$E154,FLOAT!M:M) -> 0 | AM10: =SUMIF(FLOAT!$D:$D,Cockpit!$E10:$E154,FLOAT!N:N) -> 0 | AN10: =SUMIF(FLOAT!$D:$D,Cockpit!$E10:$E154,FLOAT!O:O) -> 0 | AO10: =SUMIF(FLOAT!$D:$D,Cockpit!$E10:$E154,FLOAT!P:P) -> 0 | AP10: =AF10+AG10+AH10+AI10+AJ10+AK10+AM10+AN10+AO10 -> 0
B11: 544254630185 | C11: 544254630391 | D11: 544254600212 | E11: 54426325A | F11: ALTROZ XM+ 1.2P BS6GEN1+ | G11: 0 | H11: =SUM(G11:G12) -> 0 | I11: 0 | J11: =Q11 -> 0 | K11: =SUM(R11:R12) -> 0 | L11: =H11-K11 -> 0 | M11: =I11+J11-K11 -> 0 | N11: =SUMIF('3 D P'!$D:$D,Cockpit!$E$5:$E$146,'3 D P'!L:L) -> 0 | O11: =SUMIF('3 D P'!$D:$D,Cockpit!$E$5:$E$146,'3 D P'!M:M) -> 0 | P11: =SUMIF('3 D P'!$D:$D,Cockpit!$E$5:$E$146,'3 D P'!N:N) -> 0 | Q11: =IFERROR(VLOOKUP($D11,'Aptiv Dispatch'!$A:$B,2,FALSE),0) -> 0 | R11: =SUMIF('Consumption MTD'!B:B,Cockpit!$E$5:$E$146,'Consumption MTD'!C:C) -> 0 | S11: =SUMIF('BIW Lifting A Shift'!$B:$B,Cockpit!$E$5:$E$146,'BIW Lifting A Shift'!C:C) -> 0 | T11: =SUMIF('BIW Lifting A Shift'!$B:$B,Cockpit!$E$5:$E$146,'BIW Lifting A Shift'!#REF!) -> #REF! | U11: =M11-X11-X12 -> 0 | V11: =M11-X11-X12-S11-S12 -> 0 | W11: =V11-SUM(T11:T12) -> #REF! | X11: =SUMIF(FLOAT!$D:$D,Cockpit!$E$5:$E$146,FLOAT!F:F) -> 0 | Y11: =IFERROR(VLOOKUP(E11,[4]Sheet1!$D$4:$G$83,4,0),0) -> 0 | Z11: =IFERROR(VLOOKUP(E11,'[5]Cockpit Main'!$D$4:$G$83,4,0),0) -> 0 | AA11: 3 | AC11: 16 | AF11: =SUMIF(FLOAT!$D:$D,Cockpit!$E11:$E155,FLOAT!G:G) -> 0 | AG11: =SUMIF(FLOAT!$D:$D,Cockpit!$E11:$E155,FLOAT!H:H) -> 0 | AH11: =SUMIF(FLOAT!$D:$D,Cockpit!$E11:$E155,FLOAT!I:I) -> 0 | AI11: =SUMIF(FLOAT!$D:$D,Cockpit!$E11:$E155,FLOAT!J:J) -> 0 | AJ11: =SUMIF(FLOAT!$D:$D,Cockpit!$E11:$E155,FLOAT!K:K) -> 0 | AK11: =SUMIF(FLOAT!$D:$D,Cockpit!$E11:$E155,FLOAT!L:L) -> 0 | AL11: =SUMIF(FLOAT!$D:$D,Cockpit!$E11:$E155,FLOAT!M:M) -> 0 | AM11: =SUMIF(FLOAT!$D:$D,Cockpit!$E11:$E155,FLOAT!N:N) -> 0 | AN11: =SUMIF(FLOAT!$D:$D,Cockpit!$E11:$E155,FLOAT!O:O) -> 0 | AO11: =SUMIF(FLOAT!$D:$D,Cockpit!$E11:$E155,FLOAT!P:P) -> 0 | AP11: =AF11+AG11+AH11+AI11+AJ11+AK11+AM11+AN11+AO11 -> 0
A12: 544254620251 | E12: 54420425A | F12: Altroz XM + Diesel | G12: 0 | N12: =SUMIF('3 D P'!$D:$D,Cockpit!$E$5:$E$146,'3 D P'!L:L) -> 0 | O12: =SUMIF('3 D P'!$D:$D,Cockpit!$E$5:$E$146,'3 D P'!M:M) -> 0 | P12: =SUMIF('3 D P'!$D:$D,Cockpit!$E$5:$E$146,'3 D P'!N:N) -> 0 | Q12: =IFERROR(VLOOKUP($D12,'Aptiv Dispatch'!$A:$B,2,FALSE),0) -> 0 | R12: =SUMIF('Consumption MTD'!B:B,Cockpit!$E$5:$E$146,'Consumption MTD'!C:C) -> 0 | S12: =SUMIF('BIW Lifting A Shift'!$B:$B,Cockpit!$E$5:$E$146,'BIW Lifting A Shift'!C:C) -> 0 | T12: =SUMIF('BIW Lifting A Shift'!$B:$B,Cockpit!$E$5:$E$146,'BIW Lifting A Shift'!#REF!) -> #REF! | X12: =SUMIF(FLOAT!$D:$D,Cockpit!$E$5:$E$146,FLOAT!F:F) -> 0 | Y12: =IFERROR(VLOOKUP(E12,[4]Sheet1!$D$4:$G$83,4,0),0) -> 0 | Z12: =IFERROR(VLOOKUP(E12,'[5]Cockpit Main'!$D$4:$G$83,4,0),0) -> 0 | AA12: 0 | AF12: =SUMIF(FLOAT!$D:$D,Cockpit!$E12:$E156,FLOAT!G:G) -> 0 | AG12: =SUMIF(FLOAT!$D:$D,Cockpit!$E12:$E156,FLOAT!H:H) -> 0 | AH12: =SUMIF(FLOAT!$D:$D,Cockpit!$E12:$E156,FLOAT!I:I) -> 0 | AI12: =SUMIF(FLOAT!$D:$D,Cockpit!$E12:$E156,FLOAT!J:J) -> 0 | AJ12: =SUMIF(FLOAT!$D:$D,Cockpit!$E12:$E156,FLOAT!K:K) -> 0 | AK12: =SUMIF(FLOAT!$D:$D,Cockpit!$E12:$E156,FLOAT!L:L) -> 0 | AL12: =SUMIF(FLOAT!$D:$D,Cockpit!$E12:$E156,FLOAT!M:M) -> 0 | AM12: =SUMIF(FLOAT!$D:$D,Cockpit!$E12:$E156,FLOAT!N:N) -> 0 | AN12: =SUMIF(FLOAT!$D:$D,Cockpit!$E12:$E156,FLOAT!O:O) -> 0 | AO12: =SUMIF(FLOAT!$D:$D,Cockpit!$E12:$E156,FLOAT!P:P) -> 0 | AP12: =AF12+AG12+AH12+AI12+AJ12+AK12+AM12+AN12+AO12 -> 0
C13: 544254600378 | D13: 544254600111 | E13: 54422226A | F13: ALTROZ XM+ 1.2P BS6 PH2(REVARIANT) | G13: 0 | H13: =G13 -> 0 | I13: 0 | J13: =Q13 -> 0 | K13: =R13 -> 0 | L13: =H13-K13 -> 0 | M13: =I13+J13-K13 -> 0 | N13: =SUMIF('3 D P'!$D:$D,Cockpit!$E$5:$E$146,'3 D P'!L:L) -> 0 | O13: =SUMIF('3 D P'!$D:$D,Cockpit!$E$5:$E$146,'3 D P'!M:M) -> 0 | P13: =SUMIF('3 D P'!$D:$D,Cockpit!$E$5:$E$146,'3 D P'!N:N) -> 0 | Q13: =IFERROR(VLOOKUP($D13,'Aptiv Dispatch'!$A:$B,2,FALSE),0) -> 0 | R13: =SUMIF('Consumption MTD'!B:B,Cockpit!$E$5:$E$146,'Consumption MTD'!C:C) -> 0 | S13: =SUMIF('BIW Lifting A Shift'!$B:$B,Cockpit!$E$5:$E$146,'BIW Lifting A Shift'!C:C) -> 0 | T13: =SUMIF('BIW Lifting A Shift'!$B:$B,Cockpit!$E$5:$E$146,'BIW Lifting A Shift'!#REF!) -> #REF! | U13: =M13-X13 -> 0 | V13: =M13-S13-X13 -> 0 | W13: =V13-T13 -> #REF! | X13: =SUMIF(FLOAT!$D:$D,Cockpit!$E$5:$E$146,FLOAT!F:F) -> 0 | Y13: =IFERROR(VLOOKUP(E13,[4]Sheet1!$D$4:$G$83,4,0),0) -> 0 | Z13: =IFERROR(VLOOKUP(E13,'[5]Cockpit Main'!$D$4:$G$83,4,0),0) -> 0 | AA13: 5 | AC13: 81 | AF13: =SUMIF(FLOAT!$D:$D,Cockpit!$E13:$E157,FLOAT!G:G) -> 0 | AG13: =SUMIF(FLOAT!$D:$D,Cockpit!$E13:$E157,FLOAT!H:H) -> 0 | AH13: =SUMIF(FLOAT!$D:$D,Cockpit!$E13:$E157,FLOAT!I:I) -> 0 | AI13: =SUMIF(FLOAT!$D:$D,Cockpit!$E13:$E157,FLOAT!J:J) -> 0 | AJ13: =SUMIF(FLOAT!$D:$D,Cockpit!$E13:$E157,FLOAT!K:K) -> 0 | AK13: =SUMIF(FLOAT!$D:$D,Cockpit!$E13:$E157,FLOAT!L:L) -> 0 | AL13: =SUMIF(FLOAT!$D:$D,Cockpit!$E13:$E157,FLOAT!M:M) -> 0 | AM13: =SUMIF(FLOAT!$D:$D,Cockpit!$E13:$E157,FLOAT!N:N) -> 0 | AN13: =SUMIF(FLOAT!$D:$D,Cockpit!$E13:$E157,FLOAT!O:O) -> 0 | AO13: =SUMIF(FLOAT!$D:$D,Cockpit!$E13:$E157,FLOAT!P:P) -> 0 | AP13: =AF13+AG13+AH13+AI13+AJ13+AK13+AM13+AN13+AO13 -> 0
B14: 544254630266 | C14: 544254630393 | D14: 544254600213 | E14: 54421625A | F14: Altroz XM + DCT | G14: 0 | H14: =G14 -> 0 | I14: 5 | J14: =Q14 -> 0 | K14: =R14 -> 0 | L14: =H14-K14 -> 0 | M14: =I14+J14-K14 -> 5 | N14: =SUMIF('3 D P'!$D:$D,Cockpit!$E$5:$E$146,'3 D P'!L:L) -> 0 | O14: =SUMIF('3 D P'!$D:$D,Cockpit!$E$5:$E$146,'3 D P'!M:M) -> 0 | P14: =SUMIF('3 D P'!$D:$D,Cockpit!$E$5:$E$146,'3 D P'!N:N) -> 0 | Q14: =IFERROR(VLOOKUP($D14,'Aptiv Dispatch'!$A:$B,2,FALSE),0) -> 0 | R14: =SUMIF('Consumption MTD'!B:B,Cockpit!$E$5:$E$146,'Consumption MTD'!C:C) -> 0 | S14: =SUMIF('BIW Lifting A Shift'!$B:$B,Cockpit!$E$5:$E$146,'BIW Lifting A Shift'!C:C) -> 0 | T14: =SUMIF('BIW Lifting A Shift'!$B:$B,Cockpit!$E$5:$E$146,'BIW Lifting A Shift'!#REF!) -> #REF! | U14: =M14-X14 -> 5 | V14: =M14-S14-X14 -> 5 | W14: =V14-T14 -> #REF! | X14: =SUMIF(FLOAT!$D:$D,Cockpit!$E$5:$E$146,FLOAT!F:F) -> 0 | Y14: =IFERROR(VLOOKUP(E14,[4]Sheet1!$D$4:$G$83,4,0),0) -> 0 | Z14: =IFERROR(VLOOKUP(E14,'[5]Cockpit Main'!$D$4:$G$83,4,0),0) -> 0 | AA14: 1 | AC14: 15 | AF14: =SUMIF(FLOAT!$D:$D,Cockpit!$E14:$E158,FLOAT!G:G) -> 0 | AG14: =SUMIF(FLOAT!$D:$D,Cockpit!$E14:$E158,FLOAT!H:H) -> 0 | AH14: =SUMIF(FLOAT!$D:$D,Cockpit!$E14:$E158,FLOAT!I:I) -> 0 | AI14: =SUMIF(FLOAT!$D:$D,Cockpit!$E14:$E158,FLOAT!J:J) -> 0 | AJ14: =SUMIF(FLOAT!$D:$D,Cockpit!$E14:$E158,FLOAT!K:K) -> 0 | AK14: =SUMIF(FLOAT!$D:$D,Cockpit!$E14:$E158,FLOAT!L:L) -> 0 | AL14: =SUMIF(FLOAT!$D:$D,Cockpit!$E14:$E158,FLOAT!M:M) -> 0 | AM14: =SUMIF(FLOAT!$D:$D,Cockpit!$E14:$E158,FLOAT!N:N) -> 0 | AN14: =SUMIF(FLOAT!$D:$D,Cockpit!$E14:$E158,FLOAT!O:O) -> 0 | AO14: =SUMIF(FLOAT!$D:$D,Cockpit!$E14:$E158,FLOAT!P:P) -> 0 | AP14: =AF14+AG14+AH14+AI14+AJ14+AK14+AM14+AN14+AO14 -> 0
C15: 544254630414 | D15: 544254600215 | E15: 54420226A | F15: Altroz XM + Diesel Sun-roof | G15: 0 | H15: =SUM(G15:G16) -> 0 | I15: 11 | J15: =Q15 -> 0 | K15: =SUM(R15:R16) -> 0 | L15: =H15-K15 -> 0 | M15: =I15+J15-K15 -> 11 | N15: =SUMIF('3 D P'!$D:$D,Cockpit!$E$5:$E$146,'3 D P'!L:L) -> 0 | O15: =SUMIF('3 D P'!$D:$D,Cockpit!$E$5:$E$146,'3 D P'!M:M) -> 0 | P15: =SUMIF('3 D P'!$D:$D,Cockpit!$E$5:$E$146,'3 D P'!N:N) -> 0 | Q15: =IFERROR(VLOOKUP($D15,'Aptiv Dispatch'!$A:$B,2,FALSE),0) -> 0 | R15: =SUMIF('Consumption MTD'!B:B,Cockpit!$E$5:$E$146,'Consumption MTD'!C:C) -> 0 | S15: =SUMIF('BIW Lifting A Shift'!$B:$B,Cockpit!$E$5:$E$146,'BIW Lifting A Shift'!C:C) -> 0 | T15: =SUMIF('BIW Lifting A Shift'!$B:$B,Cockpit!$E$5:$E$146,'BIW Lifting A Shift'!#REF!) -> #REF! | U15: =M15-X15-X16 -> 11 | V15: =M15-X15-X16-S15-S16 -> 11 | W15: =V15-SUM(T15:T16) -> #REF! | X15: =SUMIF(FLOAT!$D:$D,Cockpit!$E$5:$E$146,FLOAT!F:F) -> 0 | Y15: =IFERROR(VLOOKUP(E15,[4]Sheet1!$D$4:$G$83,4,0),0) -> 0 | Z15: =IFERROR(VLOOKUP(E15,'[5]Cockpit Main'!$D$4:$G$83,4,0),0) -> 0 | AA15: 3 | AC15: 21 | AF15: =SUMIF(FLOAT!$D:$D,Cockpit!$E15:$E159,FLOAT!G:G) -> 0 | AG15: =SUMIF(FLOAT!$D:$D,Cockpit!$E15:$E159,FLOAT!H:H) -> 0 | AH15: =SUMIF(FLOAT!$D:$D,Cockpit!$E15:$E159,FLOAT!I:I) -> 0 | AI15: =SUMIF(FLOAT!$D:$D,Cockpit!$E15:$E159,FLOAT!J:J) -> 0 | AJ15: =SUMIF(FLOAT!$D:$D,Cockpit!$E15:$E159,FLOAT!K:K) -> 0 | AK15: =SUMIF(FLOAT!$D:$D,Cockpit!$E15:$E159,FLOAT!L:L) -> 0 | AL15: =SUMIF(FLOAT!$D:$D,Cockpit!$E15:$E159,FLOAT!M:M) -> 0 | AM15: =SUMIF(FLOAT!$D:$D,Cockpit!$E15:$E159,FLOAT!N:N) -> 0 | AN15: =SUMIF(FLOAT!$D:$D,Cockpit!$E15:$E159,FLOAT!O:O) -> 0 | AO15: =SUMIF(FLOAT!$D:$D,Cockpit!$E15:$E159,FLOAT!P:P) -> 0 | AP15: =AF15+AG15+AH15+AI15+AJ15+AK15+AM15+AN15+AO15 -> 0
E16: 54426326A | F16: ALTROZ XM+(S) 1.2P MT BS6 | G16: 0 | N16: =SUMIF('3 D P'!$D:$D,Cockpit!$E$5:$E$146,'3 D P'!L:L) -> 0 | O16: =SUMIF('3 D P'!$D:$D,Cockpit!$E$5:$E$146,'3 D P'!M:M) -> 0 | P16: =SUMIF('3 D P'!$D:$D,Cockpit!$E$5:$E$146,'3 D P'!N:N) -> 0 | Q16: =IFERROR(VLOOKUP($D16,'Aptiv Dispatch'!$A:$B,2,FALSE),0) -> 0 | R16: =SUMIF('Consumption MTD'!B:B,Cockpit!$E$5:$E$146,'Consumption MTD'!C:C) -> 0 | S16: =SUMIF('BIW Lifting A Shift'!$B:$B,Cockpit!$E$5:$E$146,'BIW Lifting A Shift'!C:C) -> 0 | T16: =SUMIF('BIW Lifting A Shift'!$B:$B,Cockpit!$E$5:$E$146,'BIW Lifting A Shift'!#REF!) -> #REF! | X16: =SUMIF(FLOAT!$D:$D,Cockpit!$E$5:$E$146,FLOAT!F:F) -> 0 | Y16: =IFERROR(VLOOKUP(E16,[4]Sheet1!$D$4:$G$83,4,0),0) -> 0 | Z16: =IFERROR(VLOOKUP(E16,'[5]Cockpit Main'!$D$4:$G$83,4,0),0) -> 0 | AA16: 0 | AF16: =SUMIF(FLOAT!$D:$D,Cockpit!$E16:$E160,FLOAT!G:G) -> 0 | AG16: =SUMIF(FLOAT!$D:$D,Cockpit!$E16:$E160,FLOAT!H:H) -> 0 | AH16: =SUMIF(FLOAT!$D:$D,Cockpit!$E16:$E160,FLOAT!I:I) -> 0 | AI16: =SUMIF(FLOAT!$D:$D,Cockpit!$E16:$E160,FLOAT!J:J) -> 0 | AJ16: =SUMIF(FLOAT!$D:$D,Cockpit!$E16:$E160,FLOAT!K:K) -> 0 | AK16: =SUMIF(FLOAT!$D:$D,Cockpit!$E16:$E160,FLOAT!L:L) -> 0 | AL16: =SUMIF(FLOAT!$D:$D,Cockpit!$E16:$E160,FLOAT!M:M) -> 0 | AM16: =SUMIF(FLOAT!$D:$D,Cockpit!$E16:$E160,FLOAT!N:N) -> 0 | AN16: =SUMIF(FLOAT!$D:$D,Cockpit!$E16:$E160,FLOAT!O:O) -> 0 | AO16: =SUMIF(FLOAT!$D:$D,Cockpit!$E16:$E160,FLOAT!P:P) -> 0 | AP16: =AF16+AG16+AH16+AI16+AJ16+AK16+AM16+AN16+AO16 -> 0
C17: 544254600508 | D17: 544254600214 | E17: 54422326A | F17: ALTROZ XM + (S)1.2P BS6 PH2(REVARIANT) | G17: 0 | H17: =G17 -> 0 | I17: 0 | J17: =Q17 -> 0 | K17: =R17 -> 0 | L17: =H17-K17 -> 0 | M17: =I17+J17-K17 -> 0 | N17: =SUMIF('3 D P'!$D:$D,Cockpit!$E$5:$E$146,'3 D P'!L:L) -> 0 | O17: =SUMIF('3 D P'!$D:$D,Cockpit!$E$5:$E$146,'3 D P'!M:M) -> 0 | P17: =SUMIF('3 D P'!$D:$D,Cockpit!$E$5:$E$146,'3 D P'!N:N) -> 0 | Q17: =IFERROR(VLOOKUP($D17,'Aptiv Dispatch'!$A:$B,2,FALSE),0) -> 0 | R17: =SUMIF('Consumption MTD'!B:B,Cockpit!$E$5:$E$146,'Consumption MTD'!C:C) -> 0 | S17: =SUMIF('BIW Lifting A Shift'!$B:$B,Cockpit!$E$5:$E$146,'BIW Lifting A Shift'!C:C) -> 0 | T17: =SUMIF('BIW Lifting A Shift'!$B:$B,Cockpit!$E$5:$E$146,'BIW Lifting A Shift'!#REF!) -> #REF! | U17: =M17-X17 -> 0 | V17: =M17-S17-X17 -> 0 | W17: =V17-T17 -> #REF! | X17: =SUMIF(FLOAT!$D:$D,Cockpit!$E$5:$E$146,FLOAT!F:F) -> 0 | Y17: =IFERROR(VLOOKUP(E17,[4]Sheet1!$D$4:$G$83,4,0),0) -> 0 | Z17: =IFERROR(VLOOKUP(E17,'[5]Cockpit Main'!$D$4:$G$83,4,0),0) -> 0 | AA17: 0 | AC17: 26 | AF17: =SUMIF(FLOAT!$D:$D,Cockpit!$E17:$E161,FLOAT!G:G) -> 0 | AG17: =SUMIF(FLOAT!$D:$D,Cockpit!$E17:$E161,FLOAT!H:H) -> 0 | AH17: =SUMIF(FLOAT!$D:$D,Cockpit!$E17:$E161,FLOAT!I:I) -> 0 | AI17: =SUMIF(FLOAT!$D:$D,Cockpit!$E17:$E161,FLOAT!J:J) -> 0 | AJ17: =SUMIF(FLOAT!$D:$D,Cockpit!$E17:$E161,FLOAT!K:K) -> 0 | AK17: =SUMIF(FLOAT!$D:$D,Cockpit!$E17:$E161,FLOAT!L:L) -> 0 | AL17: =SUMIF(FLOAT!$D:$D,Cockpit!$E17:$E161,FLOAT!M:M) -> 0 | AM17: =SUMIF(FLOAT!$D:$D,Cockpit!$E17:$E161,FLOAT!N:N) -> 0 | AN17: =SUMIF(FLOAT!$D:$D,Cockpit!$E17:$E161,FLOAT!O:O) -> 0 | AO17: =SUMIF(FLOAT!$D:$D,Cockpit!$E17:$E161,FLOAT!P:P) -> 0 | AP17: =AF17+AG17+AH17+AI17+AJ17+AK17+AM17+AN17+AO17 -> 0
C18: 544254630421 | D18: 544254600216 | E18: 54426526A | F18: ALTROZ DCA XM+(S)1.2P BS6PH2 | G18: 0 | H18: =G18 -> 0 | I18: 0 | J18: =Q18 -> 0 | K18: =R18 -> 0 | L18: =H18-K18 -> 0 | M18: =I18+J18-K18 -> 0 | N18: =SUMIF('3 D P'!$D:$D,Cockpit!$E$5:$E$146,'3 D P'!L:L) -> 0 | O18: =SUMIF('3 D P'!$D:$D,Cockpit!$E$5:$E$146,'3 D P'!M:M) -> 0 | P18: =SUMIF('3 D P'!$D:$D,Cockpit!$E$5:$E$146,'3 D P'!N:N) -> 0 | Q18: =IFERROR(VLOOKUP($D18,'Aptiv Dispatch'!$A:$B,2,FALSE),0) -> 0 | R18: =SUMIF('Consumption MTD'!B:B,Cockpit!$E$5:$E$146,'Consumption MTD'!C:C) -> 0 | S18: =SUMIF('BIW Lifting A Shift'!$B:$B,Cockpit!$E$5:$E$146,'BIW Lifting A Shift'!C:C) -> 0 | T18: =SUMIF('BIW Lifting A Shift'!$B:$B,Cockpit!$E$5:$E$146,'BIW Lifting A Shift'!#REF!) -> #REF! | U18: =M18-X18 -> 0 | V18: =M18-S18-X18 -> 0 | W18: =V18-T18 -> #REF! | X18: =SUMIF(FLOAT!$D:$D,Cockpit!$E$5:$E$146,FLOAT!F:F) -> 0 | Y18: =IFERROR(VLOOKUP(E18,[4]Sheet1!$D$4:$G$83,4,0),0) -> 0 | Z18: =IFERROR(VLOOKUP(E18,'[5]Cockpit Main'!$D$4:$G$83,4,0),0) -> 0 | AA18: 2 | AC18: 15 | AF18: =SUMIF(FLOAT!$D:$D,Cockpit!$E18:$E162,FLOAT!G:G) -> 0 | AG18: =SUMIF(FLOAT!$D:$D,Cockpit!$E18:$E162,FLOAT!H:H) -> 0 | AH18: =SUMIF(FLOAT!$D:$D,Cockpit!$E18:$E162,FLOAT!I:I) -> 0 | AI18: =SUMIF(FLOAT!$D:$D,Cockpit!$E18:$E162,FLOAT!J:J) -> 0 | AJ18: =SUMIF(FLOAT!$D:$D,Cockpit!$E18:$E162,FLOAT!K:K) -> 0 | AK18: =SUMIF(FLOAT!$D:$D,Cockpit!$E18:$E162,FLOAT!L:L) -> 0 | AL18: =SUMIF(FLOAT!$D:$D,Cockpit!$E18:$E162,FLOAT!M:M) -> 0 | AM18: =SUMIF(FLOAT!$D:$D,Cockpit!$E18:$E162,FLOAT!N:N) -> 0 | AN18: =SUMIF(FLOAT!$D:$D,Cockpit!$E18:$E162,FLOAT!O:O) -> 0 | AO18: =SUMIF(FLOAT!$D:$D,Cockpit!$E18:$E162,FLOAT!P:P) -> 0 | AP18: =AF18+AG18+AH18+AI18+AJ18+AK18+AM18+AN18+AO18 -> 0
A19: 544254620253 | B19: 544254630163 | C19: 544254630255 | D19: 544254650108 | E19: 54420525A | F19: Altroz XT with FATC | G19: 0 | H19: =SUM(G19:G22) -> 0 | I19: 0 | J19: =Q19 -> 0 | K19: =SUM(R19:R22) -> 0 | L19: =H19-K19 -> 0 | M19: =I19+J19-K19 -> 0 | N19: =SUMIF('3 D P'!$D:$D,Cockpit!$E$5:$E$146,'3 D P'!L:L) -> 0 | O19: =SUMIF('3 D P'!$D:$D,Cockpit!$E$5:$E$146,'3 D P'!M:M) -> 0 | P19: =SUMIF('3 D P'!$D:$D,Cockpit!$E$5:$E$146,'3 D P'!N:N) -> 0 | Q19: =IFERROR(VLOOKUP($D19,'Aptiv Dispatch'!$A:$B,2,FALSE),0) -> 0 | R19: =SUMIF('Consumption MTD'!B:B,Cockpit!$E$5:$E$146,'Consumption MTD'!C:C) -> 0 | S19: =SUMIF('BIW Lifting A Shift'!$B:$B,Cockpit!$E$5:$E$146,'BIW Lifting A Shift'!C:C) -> 0 | T19: =SUMIF('BIW Lifting A Shift'!$B:$B,Cockpit!$E$5:$E$146,'BIW Lifting A Shift'!#REF!) -> #REF! | U19: =M19-X19-X20-X21-X22 -> 0 | V19: =M19-X19-X20-X21-X22-S19-S20-S21-S22 -> 0 | W19: =V19-SUM(T19:T22) -> #REF! | X19: =SUMIF(FLOAT!$D:$D,Cockpit!$E$5:$E$146,FLOAT!F:F) -> 0 | Y19: =IFERROR(VLOOKUP(E19,[4]Sheet1!$D$4:$G$83,4,0),0) -> 0 | Z19: =IFERROR(VLOOKUP(E19,'[5]Cockpit Main'!$D$4:$G$83,4,0),0) -> 0 | AA19: 2 | AC19: 1 | AF19: =SUMIF(FLOAT!$D:$D,Cockpit!$E19:$E163,FLOAT!G:G) -> 0 | AG19: =SUMIF(FLOAT!$D:$D,Cockpit!$E19:$E163,FLOAT!H:H) -> 0 | AH19: =SUMIF(FLOAT!$D:$D,Cockpit!$E19:$E163,FLOAT!I:I) -> 0 | AI19: =SUMIF(FLOAT!$D:$D,Cockpit!$E19:$E163,FLOAT!J:J) -> 0 | AJ19: =SUMIF(FLOAT!$D:$D,Cockpit!$E19:$E163,FLOAT!K:K) -> 0 | AK19: =SUMIF(FLOAT!$D:$D,Cockpit!$E19:$E163,FLOAT!L:L) -> 0 | AL19: =SUMIF(FLOAT!$D:$D,Cockpit!$E19:$E163,FLOAT!M:M) -> 0 | AM19: =SUMIF(FLOAT!$D:$D,Cockpit!$E19:$E163,FLOAT!N:N) -> 0 | AN19: =SUMIF(FLOAT!$D:$D,Cockpit!$E19:$E163,FLOAT!O:O) -> 0 | AO19: =SUMIF(FLOAT!$D:$D,Cockpit!$E19:$E163,FLOAT!P:P) -> 0 | AP19: =AF19+AG19+AH19+AI19+AJ19+AK19+AM19+AN19+AO19 -> 0
E20: 54420925A | G20: 0 | N20: =SUMIF('3 D P'!$D:$D,Cockpit!$E$5:$E$146,'3 D P'!L:L) -> 0 | O20: =SUMIF('3 D P'!$D:$D,Cockpit!$E$5:$E$146,'3 D P'!M:M) -> 0 | P20: =SUMIF('3 D P'!$D:$D,Cockpit!$E$5:$E$146,'3 D P'!N:N) -> 0 | Q20: =IFERROR(VLOOKUP($D20,'Aptiv Dispatch'!$A:$B,2,FALSE),0) -> 0 | R20: =SUMIF('Consumption MTD'!B:B,Cockpit!$E$5:$E$146,'Consumption MTD'!C:C) -> 0 | S20: =SUMIF('BIW Lifting A Shift'!$B:$B,Cockpit!$E$5:$E$146,'BIW Lifting A Shift'!C:C) -> 0 | T20: =SUMIF('BIW Lifting A Shift'!$B:$B,Cockpit!$E$5:$E$146,'BIW Lifting A Shift'!#REF!) -> #REF! | X20: =SUMIF(FLOAT!$D:$D,Cockpit!$E$5:$E$146,FLOAT!F:F) -> 0 | Y20: =IFERROR(VLOOKUP(E20,[4]Sheet1!$D$4:$G$83,4,0),0) -> 0 | Z20: =IFERROR(VLOOKUP(E20,'[5]Cockpit Main'!$D$4:$G$83,4,0),0) -> 0 | AA20: 0 | AF20: =SUMIF(FLOAT!$D:$D,Cockpit!$E20:$E164,FLOAT!G:G) -> 0 | AG20: =SUMIF(FLOAT!$D:$D,Cockpit!$E20:$E164,FLOAT!H:H) -> 0 | AH20: =SUMIF(FLOAT!$D:$D,Cockpit!$E20:$E164,FLOAT!I:I) -> 0 | AI20: =SUMIF(FLOAT!$D:$D,Cockpit!$E20:$E164,FLOAT!J:J) -> 0 | AJ20: =SUMIF(FLOAT!$D:$D,Cockpit!$E20:$E164,FLOAT!K:K) -> 0 | AK20: =SUMIF(FLOAT!$D:$D,Cockpit!$E20:$E164,FLOAT!L:L) -> 0 | AL20: =SUMIF(FLOAT!$D:$D,Cockpit!$E20:$E164,FLOAT!M:M) -> 0 | AM20: =SUMIF(FLOAT!$D:$D,Cockpit!$E20:$E164,FLOAT!N:N) -> 0 | AN20: =SUMIF(FLOAT!$D:$D,Cockpit!$E20:$E164,FLOAT!O:O) -> 0 | AO20: =SUMIF(FLOAT!$D:$D,Cockpit!$E20:$E164,FLOAT!P:P) -> 0 | AP20: =AF20+AG20+AH20+AI20+AJ20+AK20+AM20+AN20+AO20 -> 0
E21: 54422125A | G21: 0 | N21: =SUMIF('3 D P'!$D:$D,Cockpit!$E$5:$E$146,'3 D P'!L:L) -> 0 | O21: =SUMIF('3 D P'!$D:$D,Cockpit!$E$5:$E$146,'3 D P'!M:M) -> 0 | P21: =SUMIF('3 D P'!$D:$D,Cockpit!$E$5:$E$146,'3 D P'!N:N) -> 0 | Q21: =IFERROR(VLOOKUP($D21,'Aptiv Dispatch'!$A:$B,2,FALSE),0) -> 0 | R21: =SUMIF('Consumption MTD'!B:B,Cockpit!$E$5:$E$146,'Consumption MTD'!C:C) -> 0 | S21: =SUMIF('BIW Lifting A Shift'!$B:$B,Cockpit!$E$5:$E$146,'BIW Lifting A Shift'!C:C) -> 0 | T21: =SUMIF('BIW Lifting A Shift'!$B:$B,Cockpit!$E$5:$E$146,'BIW Lifting A Shift'!#REF!) -> #REF! | X21: =SUMIF(FLOAT!$D:$D,Cockpit!$E$5:$E$146,FLOAT!F:F) -> 0 | Y21: =IFERROR(VLOOKUP(E21,[4]Sheet1!$D$4:$G$83,4,0),0) -> 0 | Z21: =IFERROR(VLOOKUP(E21,'[5]Cockpit Main'!$D$4:$G$83,4,0),0) -> 0 | AA21: 0 | AF21: =SUMIF(FLOAT!$D:$D,Cockpit!$E21:$E165,FLOAT!G:G) -> 0 | AG21: =SUMIF(FLOAT!$D:$D,Cockpit!$E21:$E165,FLOAT!H:H) -> 0 | AH21: =SUMIF(FLOAT!$D:$D,Cockpit!$E21:$E165,FLOAT!I:I) -> 0 | AI21: =SUMIF(FLOAT!$D:$D,Cockpit!$E21:$E165,FLOAT!J:J) -> 0 | AJ21: =SUMIF(FLOAT!$D:$D,Cockpit!$E21:$E165,FLOAT!K:K) -> 0 | AK21: =SUMIF(FLOAT!$D:$D,Cockpit!$E21:$E165,FLOAT!L:L) -> 0 | AL21: =SUMIF(FLOAT!$D:$D,Cockpit!$E21:$E165,FLOAT!M:M) -> 0 | AM21: =SUMIF(FLOAT!$D:$D,Cockpit!$E21:$E165,FLOAT!N:N) -> 0 | AN21: =SUMIF(FLOAT!$D:$D,Cockpit!$E21:$E165,FLOAT!O:O) -> 0 | AO21: =SUMIF(FLOAT!$D:$D,Cockpit!$E21:$E165,FLOAT!P:P) -> 0 | AP21: =AF21+AG21+AH21+AI21+AJ21+AK21+AM21+AN21+AO21 -> 0
E22: 54425325A | G22: 0 | N22: =SUMIF('3 D P'!$D:$D,Cockpit!$E$5:$E$146,'3 D P'!L:L) -> 0 | O22: =SUMIF('3 D P'!$D:$D,Cockpit!$E$5:$E$146,'3 D P'!M:M) -> 0 | P22: =SUMIF('3 D P'!$D:$D,Cockpit!$E$5:$E$146,'3 D P'!N:N) -> 0 | Q22: =IFERROR(VLOOKUP($D22,'Aptiv Dispatch'!$A:$B,2,FALSE),0) -> 0 | R22: =SUMIF('Consumption MTD'!B:B,Cockpit!$E$5:$E$146,'Consumption MTD'!C:C) -> 0 | S22: =SUMIF('BIW Lifting A Shift'!$B:$B,Cockpit!$E$5:$E$146,'BIW Lifting A Shift'!C:C) -> 0 | T22: =SUMIF('BIW Lifting A Shift'!$B:$B,Cockpit!$E$5:$E$146,'BIW Lifting A Shift'!#REF!) -> #REF! | X22: =SUMIF(FLOAT!$D:$D,Cockpit!$E$5:$E$146,FLOAT!F:F) -> 0 | Y22: =IFERROR(VLOOKUP(E22,[4]Sheet1!$D$4:$G$83,4,0),0) -> 0 | Z22: =IFERROR(VLOOKUP(E22,'[5]Cockpit Main'!$D$4:$G$83,4,0),0) -> 0 | AA22: 0 | AF22: =SUMIF(FLOAT!$D:$D,Cockpit!$E22:$E166,FLOAT!G:G) -> 0 | AG22: =SUMIF(FLOAT!$D:$D,Cockpit!$E22:$E166,FLOAT!H:H) -> 0 | AH22: =SUMIF(FLOAT!$D:$D,Cockpit!$E22:$E166,FLOAT!I:I) -> 0 | AI22: =SUMIF(FLOAT!$D:$D,Cockpit!$E22:$E166,FLOAT!J:J) -> 0 | AJ22: =SUMIF(FLOAT!$D:$D,Cockpit!$E22:$E166,FLOAT!K:K) -> 0 | AK22: =SUMIF(FLOAT!$D:$D,Cockpit!$E22:$E166,FLOAT!L:L) -> 0 | AL22: =SUMIF(FLOAT!$D:$D,Cockpit!$E22:$E166,FLOAT!M:M) -> 0 | AM22: =SUMIF(FLOAT!$D:$D,Cockpit!$E22:$E166,FLOAT!N:N) -> 0 | AN22: =SUMIF(FLOAT!$D:$D,Cockpit!$E22:$E166,FLOAT!O:O) -> 0 | AO22: =SUMIF(FLOAT!$D:$D,Cockpit!$E22:$E166,FLOAT!P:P) -> 0 | AP22: =AF22+AG22+AH22+AI22+AJ22+AK22+AM22+AN22+AO22 -> 0
C23: 544254600510 | D23: 544254650107 | E23: 54421926A | F23: ALTROZ XT 1.2 P BS6 PH2 (REVARIANT) | G23: 0 | H23: =G23 -> 0 | I23: 0 | J23: =Q23 -> 0 | K23: =R23 -> 0 | L23: =H23-K23 -> 0 | M23: =I23+J23-K23 -> 0 | N23: =SUMIF('3 D P'!$D:$D,Cockpit!$E$5:$E$146,'3 D P'!L:L) -> 0 | O23: =SUMIF('3 D P'!$D:$D,Cockpit!$E$5:$E$146,'3 D P'!M:M) -> 0 | P23: =SUMIF('3 D P'!$D:$D,Cockpit!$E$5:$E$146,'3 D P'!N:N) -> 0 | Q23: =IFERROR(VLOOKUP($D23,'Aptiv Dispatch'!$A:$B,2,FALSE),0) -> 0 | R23: =SUMIF('Consumption MTD'!B:B,Cockpit!$E$5:$E$146,'Consumption MTD'!C:C) -> 0 | S23: =SUMIF('BIW Lifting A Shift'!$B:$B,Cockpit!$E$5:$E$146,'BIW Lifting A Shift'!C:C) -> 0 | T23: =SUMIF('BIW Lifting A Shift'!$B:$B,Cockpit!$E$5:$E$146,'BIW Lifting A Shift'!#REF!) -> #REF! | U23: =M23-X23 -> 0 | V23: =M23-S23-X23 -> 0 | W23: =V23-T23 -> #REF! | X23: =SUMIF(FLOAT!$D:$D,Cockpit!$E$5:$E$146,FLOAT!F:F) -> 0 | Y23: =IFERROR(VLOOKUP(E23,[4]Sheet1!$D$4:$G$83,4,0),0) -> 0 | Z23: =IFERROR(VLOOKUP(E23,'[5]Cockpit Main'!$D$4:$G$83,4,0),0) -> 0 | AA23: 3 | AC23: 5 | AF23: =SUMIF(FLOAT!$D:$D,Cockpit!$E23:$E167,FLOAT!G:G) -> 0 | AG23: =SUMIF(FLOAT!$D:$D,Cockpit!$E23:$E167,FLOAT!H:H) -> 0 | AH23: =SUMIF(FLOAT!$D:$D,Cockpit!$E23:$E167,FLOAT!I:I) -> 0 | AI23: =SUMIF(FLOAT!$D:$D,Cockpit!$E23:$E167,FLOAT!J:J) -> 0 | AJ23: =SUMIF(FLOAT!$D:$D,Cockpit!$E23:$E167,FLOAT!K:K) -> 0 | AK23: =SUMIF(FLOAT!$D:$D,Cockpit!$E23:$E167,FLOAT!L:L) -> 0 | AL23: =SUMIF(FLOAT!$D:$D,Cockpit!$E23:$E167,FLOAT!M:M) -> 0 | AM23: =SUMIF(FLOAT!$D:$D,Cockpit!$E23:$E167,FLOAT!N:N) -> 0 | AN23: =SUMIF(FLOAT!$D:$D,Cockpit!$E23:$E167,FLOAT!O:O) -> 0 | AO23: =SUMIF(FLOAT!$D:$D,Cockpit!$E23:$E167,FLOAT!P:P) -> 0 | AP23: =AF23+AG23+AH23+AI23+AJ23+AK23+AM23+AN23+AO23 -> 0
A24: 544246200392 | B24: 544254630258 | C24: 544254630265 | D24: 544254650109 | E24: 54421725A | F24: Altroz XT DCT, XT DCT DARK | G24: 0 | H24: =SUM(G24:G25) -> 0 | I24: 0 | J24: =Q24 -> 0 | K24: =SUM(R24:R25) -> 0 | L24: =H24-K24 -> 0 | M24: =I24+J24-K24 -> 0 | N24: =SUMIF('3 D P'!$D:$D,Cockpit!$E$5:$E$146,'3 D P'!L:L) -> 0 | O24: =SUMIF('3 D P'!$D:$D,Cockpit!$E$5:$E$146,'3 D P'!M:M) -> 0 | P24: =SUMIF('3 D P'!$D:$D,Cockpit!$E$5:$E$146,'3 D P'!N:N) -> 0 | Q24: =IFERROR(VLOOKUP($D24,'Aptiv Dispatch'!$A:$B,2,FALSE),0) -> 0 | R24: =SUMIF('Consumption MTD'!B:B,Cockpit!$E$5:$E$146,'Consumption MTD'!C:C) -> 0 | S24: =SUMIF('BIW Lifting A Shift'!$B:$B,Cockpit!$E$5:$E$146,'BIW Lifting A Shift'!C:C) -> 0 | T24: =SUMIF('BIW Lifting A Shift'!$B:$B,Cockpit!$E$5:$E$146,'BIW Lifting A Shift'!#REF!) -> #REF! | U24: =M24-X24-X25 -> 0 | V24: =M24-X24-X25-S24-S25 -> 0 | W24: =V24-SUM(T24:T25) -> #REF! | X24: =SUMIF(FLOAT!$D:$D,Cockpit!$E$5:$E$146,FLOAT!F:F) -> 0 | Y24: =IFERROR(VLOOKUP(E24,[4]Sheet1!$D$4:$G$83,4,0),0) -> 0 | Z24: =IFERROR(VLOOKUP(E24,'[5]Cockpit Main'!$D$4:$G$83,4,0),0) -> 0 | AA24: 3 | AC24: 33 | AF24: =SUMIF(FLOAT!$D:$D,Cockpit!$E24:$E168,FLOAT!G:G) -> 0 | AG24: =SUMIF(FLOAT!$D:$D,Cockpit!$E24:$E168,FLOAT!H:H) -> 0 | AH24: =SUMIF(FLOAT!$D:$D,Cockpit!$E24:$E168,FLOAT!I:I) -> 0 | AI24: =SUMIF(FLOAT!$D:$D,Cockpit!$E24:$E168,FLOAT!J:J) -> 0 | AJ24: =SUMIF(FLOAT!$D:$D,Cockpit!$E24:$E168,FLOAT!K:K) -> 0 | AK24: =SUMIF(FLOAT!$D:$D,Cockpit!$E24:$E168,FLOAT!L:L) -> 0 | AL24: =SUMIF(FLOAT!$D:$D,Cockpit!$E24:$E168,FLOAT!M:M) -> 0 | AM24: =SUMIF(FLOAT!$D:$D,Cockpit!$E24:$E168,FLOAT!N:N) -> 0 | AN24: =SUMIF(FLOAT!$D:$D,Cockpit!$E24:$E168,FLOAT!O:O) -> 0 | AO24: =SUMIF(FLOAT!$D:$D,Cockpit!$E24:$E168,FLOAT!P:P) -> 0 | AP24: =AF24+AG24+AH24+AI24+AJ24+AK24+AM24+AN24+AO24 -> 0
E25: 54425525A | G25: 0 | N25: =SUMIF('3 D P'!$D:$D,Cockpit!$E$5:$E$146,'3 D P'!L:L) -> 0 | O25: =SUMIF('3 D P'!$D:$D,Cockpit!$E$5:$E$146,'3 D P'!M:M) -> 0 | P25: =SUMIF('3 D P'!$D:$D,Cockpit!$E$5:$E$146,'3 D P'!N:N) -> 0 | Q25: =IFERROR(VLOOKUP($D25,'Aptiv Dispatch'!$A:$B,2,FALSE),0) -> 0 | R25: =SUMIF('Consumption MTD'!B:B,Cockpit!$E$5:$E$146,'Consumption MTD'!C:C) -> 0 | S25: =SUMIF('BIW Lifting A Shift'!$B:$B,Cockpit!$E$5:$E$146,'BIW Lifting A Shift'!C:C) -> 0 | T25: =SUMIF('BIW Lifting A Shift'!$B:$B,Cockpit!$E$5:$E$146,'BIW Lifting A Shift'!#REF!) -> #REF! | X25: =SUMIF(FLOAT!$D:$D,Cockpit!$E$5:$E$146,FLOAT!F:F) -> 0 | Y25: =IFERROR(VLOOKUP(E25,[4]Sheet1!$D$4:$G$83,4,0),0) -> 0 | Z25: =IFERROR(VLOOKUP(E25,'[5]Cockpit Main'!$D$4:$G$83,4,0),0) -> 0 | AA25: 0 | AF25: =SUMIF(FLOAT!$D:$D,Cockpit!$E25:$E169,FLOAT!G:G) -> 0 | AG25: =SUMIF(FLOAT!$D:$D,Cockpit!$E25:$E169,FLOAT!H:H) -> 0 | AH25: =SUMIF(FLOAT!$D:$D,Cockpit!$E25:$E169,FLOAT!I:I) -> 0 | AI25: =SUMIF(FLOAT!$D:$D,Cockpit!$E25:$E169,FLOAT!J:J) -> 0 | AJ25: =SUMIF(FLOAT!$D:$D,Cockpit!$E25:$E169,FLOAT!K:K) -> 0 | AK25: =SUMIF(FLOAT!$D:$D,Cockpit!$E25:$E169,FLOAT!L:L) -> 0 | AL25: =SUMIF(FLOAT!$D:$D,Cockpit!$E25:$E169,FLOAT!M:M) -> 0 | AM25: =SUMIF(FLOAT!$D:$D,Cockpit!$E25:$E169,FLOAT!N:N) -> 0 | AN25: =SUMIF(FLOAT!$D:$D,Cockpit!$E25:$E169,FLOAT!O:O) -> 0 | AO25: =SUMIF(FLOAT!$D:$D,Cockpit!$E25:$E169,FLOAT!P:P) -> 0 | AP25: =AF25+AG25+AH25+AI25+AJ25+AK25+AM25+AN25+AO25 -> 0
A26: 544254630222 | B26: 544254630165 | C26: 544254630254 | D26: 544254650110 | E26: 54420625A | F26: ALTROZ XZ1.5RTQ MT BS6PH2 | G26: 0 | H26: =SUM(G26:G28) -> 0 | I26: 0 | J26: =Q26 -> 0 | K26: =SUM(R26:R28) -> 0 | L26: =H26-K26 -> 0 | M26: =I26+J26-K26 -> 0 | N26: =SUMIF('3 D P'!$D:$D,Cockpit!$E$5:$E$146,'3 D P'!L:L) -> 0 | O26: =SUMIF('3 D P'!$D:$D,Cockpit!$E$5:$E$146,'3 D P'!M:M) -> 0 | P26: =SUMIF('3 D P'!$D:$D,Cockpit!$E$5:$E$146,'3 D P'!N:N) -> 0 | Q26: =IFERROR(VLOOKUP($D26,'Aptiv Dispatch'!$A:$B,2,FALSE),0) -> 0 | R26: =SUMIF('Consumption MTD'!B:B,Cockpit!$E$5:$E$146,'Consumption MTD'!C:C) -> 0 | S26: =SUMIF('BIW Lifting A Shift'!$B:$B,Cockpit!$E$5:$E$146,'BIW Lifting A Shift'!C:C) -> 0 | T26: =SUMIF('BIW Lifting A Shift'!$B:$B,Cockpit!$E$5:$E$146,'BIW Lifting A Shift'!#REF!) -> #REF! | U26: =M26-X26-X27-X28 -> 0 | V26: =M26-X26-X27-X28-S26-S27-S28 -> 0 | W26: =V26-SUM(T26:T28) -> #REF! | X26: =SUMIF(FLOAT!$D:$D,Cockpit!$E$5:$E$146,FLOAT!F:F) -> 0 | Y26: =IFERROR(VLOOKUP(E26,[4]Sheet1!$D$4:$G$83,4,0),0) -> 0 | Z26: =IFERROR(VLOOKUP(E26,'[5]Cockpit Main'!$D$4:$G$83,4,0),0) -> 0 | AA26: 5 | AC26: 39 | AF26: =SUMIF(FLOAT!$D:$D,Cockpit!$E26:$E170,FLOAT!G:G) -> 0 | AG26: =SUMIF(FLOAT!$D:$D,Cockpit!$E26:$E170,FLOAT!H:H) -> 0 | AH26: =SUMIF(FLOAT!$D:$D,Cockpit!$E26:$E170,FLOAT!I:I) -> 0 | AI26: =SUMIF(FLOAT!$D:$D,Cockpit!$E26:$E170,FLOAT!J:J) -> 0 | AJ26: =SUMIF(FLOAT!$D:$D,Cockpit!$E26:$E170,FLOAT!K:K) -> 0 | AK26: =SUMIF(FLOAT!$D:$D,Cockpit!$E26:$E170,FLOAT!L:L) -> 0 | AL26: =SUMIF(FLOAT!$D:$D,Cockpit!$E26:$E170,FLOAT!M:M) -> 0 | AM26: =SUMIF(FLOAT!$D:$D,Cockpit!$E26:$E170,FLOAT!N:N) -> 0 | AN26: =SUMIF(FLOAT!$D:$D,Cockpit!$E26:$E170,FLOAT!O:O) -> 0 | AO26: =SUMIF(FLOAT!$D:$D,Cockpit!$E26:$E170,FLOAT!P:P) -> 0 | AP26: =AF26+AG26+AH26+AI26+AJ26+AK26+AM26+AN26+AO26 -> 0
E27: 54425425A | G27: 0 | N27: =SUMIF('3 D P'!$D:$D,Cockpit!$E$5:$E$146,'3 D P'!L:L) -> 0 | O27: =SUMIF('3 D P'!$D:$D,Cockpit!$E$5:$E$146,'3 D P'!M:M) -> 0 | P27: =SUMIF('3 D P'!$D:$D,Cockpit!$E$5:$E$146,'3 D P'!N:N) -> 0 | Q27: =IFERROR(VLOOKUP($D27,'Aptiv Dispatch'!$A:$B,2,FALSE),0) -> 0 | R27: =SUMIF('Consumption MTD'!B:B,Cockpit!$E$5:$E$146,'Consumption MTD'!C:C) -> 0 | S27: =SUMIF('BIW Lifting A Shift'!$B:$B,Cockpit!$E$5:$E$146,'BIW Lifting A Shift'!C:C) -> 0 | T27: =SUMIF('BIW Lifting A Shift'!$B:$B,Cockpit!$E$5:$E$146,'BIW Lifting A Shift'!#REF!) -> #REF! | X27: =SUMIF(FLOAT!$D:$D,Cockpit!$E$5:$E$146,FLOAT!F:F) -> 0 | Y27: =IFERROR(VLOOKUP(E27,[4]Sheet1!$D$4:$G$83,4,0),0) -> 0 | Z27: =IFERROR(VLOOKUP(E27,'[5]Cockpit Main'!$D$4:$G$83,4,0),0) -> 0 | AA27: 0 | AF27: =SUMIF(FLOAT!$D:$D,Cockpit!$E27:$E171,FLOAT!G:G) -> 0 | AG27: =SUMIF(FLOAT!$D:$D,Cockpit!$E27:$E171,FLOAT!H:H) -> 0 | AH27: =SUMIF(FLOAT!$D:$D,Cockpit!$E27:$E171,FLOAT!I:I) -> 0 | AI27: =SUMIF(FLOAT!$D:$D,Cockpit!$E27:$E171,FLOAT!J:J) -> 0 | AJ27: =SUMIF(FLOAT!$D:$D,Cockpit!$E27:$E171,FLOAT!K:K) -> 0 | AK27: =SUMIF(FLOAT!$D:$D,Cockpit!$E27:$E171,FLOAT!L:L) -> 0 | AL27: =SUMIF(FLOAT!$D:$D,Cockpit!$E27:$E171,FLOAT!M:M) -> 0 | AM27: =SUMIF(FLOAT!$D:$D,Cockpit!$E27:$E171,FLOAT!N:N) -> 0 | AN27: =SUMIF(FLOAT!$D:$D,Cockpit!$E27:$E171,FLOAT!O:O) -> 0 | AO27: =SUMIF(FLOAT!$D:$D,Cockpit!$E27:$E171,FLOAT!P:P) -> 0 | AP27: =AF27+AG27+AH27+AI27+AJ27+AK27+AM27+AN27+AO27 -> 0
E28: 54425925A | G28: 0 | N28: =SUMIF('3 D P'!$D:$D,Cockpit!$E$5:$E$146,'3 D P'!L:L) -> 0 | O28: =SUMIF('3 D P'!$D:$D,Cockpit!$E$5:$E$146,'3 D P'!M:M) -> 0 | P28: =SUMIF('3 D P'!$D:$D,Cockpit!$E$5:$E$146,'3 D P'!N:N) -> 0 | Q28: =IFERROR(VLOOKUP($D28,'Aptiv Dispatch'!$A:$B,2,FALSE),0) -> 0 | R28: =SUMIF('Consumption MTD'!B:B,Cockpit!$E$5:$E$146,'Consumption MTD'!C:C) -> 0 | S28: =SUMIF('BIW Lifting A Shift'!$B:$B,Cockpit!$E$5:$E$146,'BIW Lifting A Shift'!C:C) -> 0 | T28: =SUMIF('BIW Lifting A Shift'!$B:$B,Cockpit!$E$5:$E$146,'BIW Lifting A Shift'!#REF!) -> #REF! | X28: =SUMIF(FLOAT!$D:$D,Cockpit!$E$5:$E$146,FLOAT!F:F) -> 0 | Y28: =IFERROR(VLOOKUP(E28,[4]Sheet1!$D$4:$G$83,4,0),0) -> 0 | Z28: =IFERROR(VLOOKUP(E28,'[5]Cockpit Main'!$D$4:$G$83,4,0),0) -> 0 | AA28: 0 | AF28: =SUMIF(FLOAT!$D:$D,Cockpit!$E28:$E172,FLOAT!G:G) -> 0 | AG28: =SUMIF(FLOAT!$D:$D,Cockpit!$E28:$E172,FLOAT!H:H) -> 0 | AH28: =SUMIF(FLOAT!$D:$D,Cockpit!$E28:$E172,FLOAT!I:I) -> 0 | AI28: =SUMIF(FLOAT!$D:$D,Cockpit!$E28:$E172,FLOAT!J:J) -> 0 | AJ28: =SUMIF(FLOAT!$D:$D,Cockpit!$E28:$E172,FLOAT!K:K) -> 0 | AK28: =SUMIF(FLOAT!$D:$D,Cockpit!$E28:$E172,FLOAT!L:L) -> 0 | AL28: =SUMIF(FLOAT!$D:$D,Cockpit!$E28:$E172,FLOAT!M:M) -> 0 | AM28: =SUMIF(FLOAT!$D:$D,Cockpit!$E28:$E172,FLOAT!N:N) -> 0 | AN28: =SUMIF(FLOAT!$D:$D,Cockpit!$E28:$E172,FLOAT!O:O) -> 0 | AO28: =SUMIF(FLOAT!$D:$D,Cockpit!$E28:$E172,FLOAT!P:P) -> 0 | AP28: =AF28+AG28+AH28+AI28+AJ28+AK28+AM28+AN28+AO28 -> 0
A29: 544246200220 | B29: 544254630259 | C29: 544254630264 | D29: 544254630115 | E29: 54425625A | F29: Altroz XZ DCT | G29: 0 | H29: =G29 -> 0 | I29: 0 | J29: =Q29 -> 0 | K29: =R29 -> 0 | L29: =H29-K29 -> 0 | M29: =I29+J29-K29 -> 0 | N29: =SUMIF('3 D P'!$D:$D,Cockpit!$E$5:$E$146,'3 D P'!L:L) -> 0 | O29: =SUMIF('3 D P'!$D:$D,Cockpit!$E$5:$E$146,'3 D P'!M:M) -> 0 | P29: =SUMIF('3 D P'!$D:$D,Cockpit!$E$5:$E$146,'3 D P'!N:N) -> 0 | Q29: =IFERROR(VLOOKUP($D29,'Aptiv Dispatch'!$A:$B,2,FALSE),0) -> 0 | R29: =SUMIF('Consumption MTD'!B:B,Cockpit!$E$5:$E$146,'Consumption MTD'!C:C) -> 0 | S29: =SUMIF('BIW Lifting A Shift'!$B:$B,Cockpit!$E$5:$E$146,'BIW Lifting A Shift'!C:C) -> 0 | T29: =SUMIF('BIW Lifting A Shift'!$B:$B,Cockpit!$E$5:$E$146,'BIW Lifting A Shift'!#REF!) -> #REF! | U29: =M29-X29 -> 0 | V29: =M29-S29-X29 -> 0 | W29: =V29-T29 -> #REF! | X29: =SUMIF(FLOAT!$D:$D,Cockpit!$E$5:$E$146,FLOAT!F:F) -> 0 | Y29: =IFERROR(VLOOKUP(E29,[4]Sheet1!$D$4:$G$83,4,0),0) -> 0 | Z29: =IFERROR(VLOOKUP(E29,'[5]Cockpit Main'!$D$4:$G$83,4,0),0) -> 0 | AA29: 5 | AC29: 12 | AF29: =SUMIF(FLOAT!$D:$D,Cockpit!$E29:$E173,FLOAT!G:G) -> 0 | AG29: =SUMIF(FLOAT!$D:$D,Cockpit!$E29:$E173,FLOAT!H:H) -> 0 | AH29: =SUMIF(FLOAT!$D:$D,Cockpit!$E29:$E173,FLOAT!I:I) -> 0 | AI29: =SUMIF(FLOAT!$D:$D,Cockpit!$E29:$E173,FLOAT!J:J) -> 0 | AJ29: =SUMIF(FLOAT!$D:$D,Cockpit!$E29:$E173,FLOAT!K:K) -> 0 | AK29: =SUMIF(FLOAT!$D:$D,Cockpit!$E29:$E173,FLOAT!L:L) -> 0 | AL29: =SUMIF(FLOAT!$D:$D,Cockpit!$E29:$E173,FLOAT!M:M) -> 0 | AM29: =SUMIF(FLOAT!$D:$D,Cockpit!$E29:$E173,FLOAT!N:N) -> 0 | AN29: =SUMIF(FLOAT!$D:$D,Cockpit!$E29:$E173,FLOAT!O:O) -> 0 | AO29: =SUMIF(FLOAT!$D:$D,Cockpit!$E29:$E173,FLOAT!P:P) -> 0 | AP29: =AF29+AG29+AH29+AI29+AJ29+AK29+AM29+AN29+AO29 -> 0
A30: 544254620372 | C30: 544254630435 | D30: 544254630435 | E30: 54420825A | F30: Altroz XZ+, XZ+ DARK, XZ+ TC | G30: 0 | H30: =SUM(G30:G36) -> 0 | I30: 0 | J30: =Q30 -> 0 | K30: =SUM(R30:R36) -> 0 | L30: =H30-K30 -> 0 | M30: =I30+J30-K30 -> 0 | N30: =SUMIF('3 D P'!$D:$D,Cockpit!$E$5:$E$146,'3 D P'!L:L) -> 0 | O30: =SUMIF('3 D P'!$D:$D,Cockpit!$E$5:$E$146,'3 D P'!M:M) -> 0 | P30: =SUMIF('3 D P'!$D:$D,Cockpit!$E$5:$E$146,'3 D P'!N:N) -> 0 | Q30: =IFERROR(VLOOKUP($D30,'Aptiv Dispatch'!$A:$B,2,FALSE),0) -> 0 | R30: =SUMIF('Consumption MTD'!B:B,Cockpit!$E$5:$E$146,'Consumption MTD'!C:C) -> 0 | S30: =SUMIF('BIW Lifting A Shift'!$B:$B,Cockpit!$E$5:$E$146,'BIW Lifting A Shift'!C:C) -> 0 | T30: =SUMIF('BIW Lifting A Shift'!$B:$B,Cockpit!$E$5:$E$146,'BIW Lifting A Shift'!#REF!) -> #REF! | U30: =M30-X30-X31-X32-X33-X34-X35-X36 -> 0 | V30: =M30-SUM(X30:X36)-SUM(S30:S36) -> 0 | W30: =V30-SUM(T30:T36) -> #REF! | X30: =SUMIF(FLOAT!$D:$D,Cockpit!$E$5:$E$146,FLOAT!F:F) -> 0 | Y30: =IFERROR(VLOOKUP(E30,[4]Sheet1!$D$4:$G$83,4,0),0) -> 0 | Z30: =IFERROR(VLOOKUP(E30,'[5]Cockpit Main'!$D$4:$G$83,4,0),0) -> 0 | AA30: 0 | AC30: 0 | AF30: =SUMIF(FLOAT!$D:$D,Cockpit!$E30:$E174,FLOAT!G:G) -> 0 | AG30: =SUMIF(FLOAT!$D:$D,Cockpit!$E30:$E174,FLOAT!H:H) -> 0 | AH30: =SUMIF(FLOAT!$D:$D,Cockpit!$E30:$E174,FLOAT!I:I) -> 0 | AI30: =SUMIF(FLOAT!$D:$D,Cockpit!$E30:$E174,FLOAT!J:J) -> 0 | AJ30: =SUMIF(FLOAT!$D:$D,Cockpit!$E30:$E174,FLOAT!K:K) -> 0 | AK30: =SUMIF(FLOAT!$D:$D,Cockpit!$E30:$E174,FLOAT!L:L) -> 0 | AL30: =SUMIF(FLOAT!$D:$D,Cockpit!$E30:$E174,FLOAT!M:M) -> 0 | AM30: =SUMIF(FLOAT!$D:$D,Cockpit!$E30:$E174,FLOAT!N:N) -> 0 | AN30: =SUMIF(FLOAT!$D:$D,Cockpit!$E30:$E174,FLOAT!O:O) -> 0 | AO30: =SUMIF(FLOAT!$D:$D,Cockpit!$E30:$E174,FLOAT!P:P) -> 0 | AP30: =AF30+AG30+AH30+AI30+AJ30+AK30+AM30+AN30+AO30 -> 0
E31: 54420725A | G31: 0 | N31: =SUMIF('3 D P'!$D:$D,Cockpit!$E$5:$E$146,'3 D P'!L:L) -> 0 | O31: =SUMIF('3 D P'!$D:$D,Cockpit!$E$5:$E$146,'3 D P'!M:M) -> 0 | P31: =SUMIF('3 D P'!$D:$D,Cockpit!$E$5:$E$146,'3 D P'!N:N) -> 0 | Q31: =IFERROR(VLOOKUP($D31,'Aptiv Dispatch'!$A:$B,2,FALSE),0) -> 0 | R31: =SUMIF('Consumption MTD'!B:B,Cockpit!$E$5:$E$146,'Consumption MTD'!C:C) -> 0 | S31: =SUMIF('BIW Lifting A Shift'!$B:$B,Cockpit!$E$5:$E$146,'BIW Lifting A Shift'!C:C) -> 0 | T31: =SUMIF('BIW Lifting A Shift'!$B:$B,Cockpit!$E$5:$E$146,'BIW Lifting A Shift'!#REF!) -> #REF! | X31: =SUMIF(FLOAT!$D:$D,Cockpit!$E$5:$E$146,FLOAT!F:F) -> 0 | Y31: =IFERROR(VLOOKUP(E31,[4]Sheet1!$D$4:$G$83,4,0),0) -> 0 | Z31: =IFERROR(VLOOKUP(E31,'[5]Cockpit Main'!$D$4:$G$83,4,0),0) -> 0 | AA31: 0 | AF31: =SUMIF(FLOAT!$D:$D,Cockpit!$E31:$E175,FLOAT!G:G) -> 0 | AG31: =SUMIF(FLOAT!$D:$D,Cockpit!$E31:$E175,FLOAT!H:H) -> 0 | AH31: =SUMIF(FLOAT!$D:$D,Cockpit!$E31:$E175,FLOAT!I:I) -> 0 | AI31: =SUMIF(FLOAT!$D:$D,Cockpit!$E31:$E175,FLOAT!J:J) -> 0 | AJ31: =SUMIF(FLOAT!$D:$D,Cockpit!$E31:$E175,FLOAT!K:K) -> 0 | AK31: =SUMIF(FLOAT!$D:$D,Cockpit!$E31:$E175,FLOAT!L:L) -> 0 | AL31: =SUMIF(FLOAT!$D:$D,Cockpit!$E31:$E175,FLOAT!M:M) -> 0 | AM31: =SUMIF(FLOAT!$D:$D,Cockpit!$E31:$E175,FLOAT!N:N) -> 0 | AN31: =SUMIF(FLOAT!$D:$D,Cockpit!$E31:$E175,FLOAT!O:O) -> 0 | AO31: =SUMIF(FLOAT!$D:$D,Cockpit!$E31:$E175,FLOAT!P:P) -> 0 | AP31: =AF31+AG31+AH31+AI31+AJ31+AK31+AM31+AN31+AO31 -> 0
E32: 54427725A | G32: 0 | N32: =SUMIF('3 D P'!$D:$D,Cockpit!$E$5:$E$146,'3 D P'!L:L) -> 0 | O32: =SUMIF('3 D P'!$D:$D,Cockpit!$E$5:$E$146,'3 D P'!M:M) -> 0 | P32: =SUMIF('3 D P'!$D:$D,Cockpit!$E$5:$E$146,'3 D P'!N:N) -> 0 | Q32: =IFERROR(VLOOKUP($D32,'Aptiv Dispatch'!$A:$B,2,FALSE),0) -> 0 | R32: =SUMIF('Consumption MTD'!B:B,Cockpit!$E$5:$E$146,'Consumption MTD'!C:C) -> 0 | S32: =SUMIF('BIW Lifting A Shift'!$B:$B,Cockpit!$E$5:$E$146,'BIW Lifting A Shift'!C:C) -> 0 | T32: =SUMIF('BIW Lifting A Shift'!$B:$B,Cockpit!$E$5:$E$146,'BIW Lifting A Shift'!#REF!) -> #REF! | X32: =SUMIF(FLOAT!$D:$D,Cockpit!$E$5:$E$146,FLOAT!F:F) -> 0 | Y32: =IFERROR(VLOOKUP(E32,[4]Sheet1!$D$4:$G$83,4,0),0) -> 0 | Z32: =IFERROR(VLOOKUP(E32,'[5]Cockpit Main'!$D$4:$G$83,4,0),0) -> 0 | AA32: 0 | AF32: =SUMIF(FLOAT!$D:$D,Cockpit!$E32:$E176,FLOAT!G:G) -> 0 | AG32: =SUMIF(FLOAT!$D:$D,Cockpit!$E32:$E176,FLOAT!H:H) -> 0 | AH32: =SUMIF(FLOAT!$D:$D,Cockpit!$E32:$E176,FLOAT!I:I) -> 0 | AI32: =SUMIF(FLOAT!$D:$D,Cockpit!$E32:$E176,FLOAT!J:J) -> 0 | AJ32: =SUMIF(FLOAT!$D:$D,Cockpit!$E32:$E176,FLOAT!K:K) -> 0 | AK32: =SUMIF(FLOAT!$D:$D,Cockpit!$E32:$E176,FLOAT!L:L) -> 0 | AL32: =SUMIF(FLOAT!$D:$D,Cockpit!$E32:$E176,FLOAT!M:M) -> 0 | AM32: =SUMIF(FLOAT!$D:$D,Cockpit!$E32:$E176,FLOAT!N:N) -> 0 | AN32: =SUMIF(FLOAT!$D:$D,Cockpit!$E32:$E176,FLOAT!O:O) -> 0 | AO32: =SUMIF(FLOAT!$D:$D,Cockpit!$E32:$E176,FLOAT!P:P) -> 0 | AP32: =AF32+AG32+AH32+AI32+AJ32+AK32+AM32+AN32+AO32 -> 0
E33: 54422225A | G33: 0 | N33: =SUMIF('3 D P'!$D:$D,Cockpit!$E$5:$E$146,'3 D P'!L:L) -> 0 | O33: =SUMIF('3 D P'!$D:$D,Cockpit!$E$5:$E$146,'3 D P'!M:M) -> 0 | P33: =SUMIF('3 D P'!$D:$D,Cockpit!$E$5:$E$146,'3 D P'!N:N) -> 0 | Q33: =IFERROR(VLOOKUP($D33,'Aptiv Dispatch'!$A:$B,2,FALSE),0) -> 0 | R33: =SUMIF('Consumption MTD'!B:B,Cockpit!$E$5:$E$146,'Consumption MTD'!C:C) -> 0 | S33: =SUMIF('BIW Lifting A Shift'!$B:$B,Cockpit!$E$5:$E$146,'BIW Lifting A Shift'!C:C) -> 0 | T33: =SUMIF('BIW Lifting A Shift'!$B:$B,Cockpit!$E$5:$E$146,'BIW Lifting A Shift'!#REF!) -> #REF! | X33: =SUMIF(FLOAT!$D:$D,Cockpit!$E$5:$E$146,FLOAT!F:F) -> 0 | Y33: =IFERROR(VLOOKUP(E33,[4]Sheet1!$D$4:$G$83,4,0),0) -> 0 | Z33: =IFERROR(VLOOKUP(E33,'[5]Cockpit Main'!$D$4:$G$83,4,0),0) -> 0 | AA33: 0 | AF33: =SUMIF(FLOAT!$D:$D,Cockpit!$E33:$E177,FLOAT!G:G) -> 0 | AG33: =SUMIF(FLOAT!$D:$D,Cockpit!$E33:$E177,FLOAT!H:H) -> 0 | AH33: =SUMIF(FLOAT!$D:$D,Cockpit!$E33:$E177,FLOAT!I:I) -> 0 | AI33: =SUMIF(FLOAT!$D:$D,Cockpit!$E33:$E177,FLOAT!J:J) -> 0 | AJ33: =SUMIF(FLOAT!$D:$D,Cockpit!$E33:$E177,FLOAT!K:K) -> 0 | AK33: =SUMIF(FLOAT!$D:$D,Cockpit!$E33:$E177,FLOAT!L:L) -> 0 | AL33: =SUMIF(FLOAT!$D:$D,Cockpit!$E33:$E177,FLOAT!M:M) -> 0 | AM33: =SUMIF(FLOAT!$D:$D,Cockpit!$E33:$E177,FLOAT!N:N) -> 0 | AN33: =SUMIF(FLOAT!$D:$D,Cockpit!$E33:$E177,FLOAT!O:O) -> 0 | AO33: =SUMIF(FLOAT!$D:$D,Cockpit!$E33:$E177,FLOAT!P:P) -> 0 | AP33: =AF33+AG33+AH33+AI33+AJ33+AK33+AM33+AN33+AO33 -> 0
E34: 54427625A | G34: 0 | N34: =SUMIF('3 D P'!$D:$D,Cockpit!$E$5:$E$146,'3 D P'!L:L) -> 0 | O34: =SUMIF('3 D P'!$D:$D,Cockpit!$E$5:$E$146,'3 D P'!M:M) -> 0 | P34: =SUMIF('3 D P'!$D:$D,Cockpit!$E$5:$E$146,'3 D P'!N:N) -> 0 | Q34: =IFERROR(VLOOKUP($D34,'Aptiv Dispatch'!$A:$B,2,FALSE),0) -> 0 | R34: =SUMIF('Consumption MTD'!B:B,Cockpit!$E$5:$E$146,'Consumption MTD'!C:C) -> 0 | S34: =SUMIF('BIW Lifting A Shift'!$B:$B,Cockpit!$E$5:$E$146,'BIW Lifting A Shift'!C:C) -> 0 | T34: =SUMIF('BIW Lifting A Shift'!$B:$B,Cockpit!$E$5:$E$146,'BIW Lifting A Shift'!#REF!) -> #REF! | X34: =SUMIF(FLOAT!$D:$D,Cockpit!$E$5:$E$146,FLOAT!F:F) -> 0 | Y34: =IFERROR(VLOOKUP(E34,[4]Sheet1!$D$4:$G$83,4,0),0) -> 0 | Z34: =IFERROR(VLOOKUP(E34,'[5]Cockpit Main'!$D$4:$G$83,4,0),0) -> 0 | AA34: 0 | AF34: =SUMIF(FLOAT!$D:$D,Cockpit!$E34:$E178,FLOAT!G:G) -> 0 | AG34: =SUMIF(FLOAT!$D:$D,Cockpit!$E34:$E178,FLOAT!H:H) -> 0 | AH34: =SUMIF(FLOAT!$D:$D,Cockpit!$E34:$E178,FLOAT!I:I) -> 0 | AI34: =SUMIF(FLOAT!$D:$D,Cockpit!$E34:$E178,FLOAT!J:J) -> 0 | AJ34: =SUMIF(FLOAT!$D:$D,Cockpit!$E34:$E178,FLOAT!K:K) -> 0 | AK34: =SUMIF(FLOAT!$D:$D,Cockpit!$E34:$E178,FLOAT!L:L) -> 0 | AL34: =SUMIF(FLOAT!$D:$D,Cockpit!$E34:$E178,FLOAT!M:M) -> 0 | AM34: =SUMIF(FLOAT!$D:$D,Cockpit!$E34:$E178,FLOAT!N:N) -> 0 | AN34: =SUMIF(FLOAT!$D:$D,Cockpit!$E34:$E178,FLOAT!O:O) -> 0 | AO34: =SUMIF(FLOAT!$D:$D,Cockpit!$E34:$E178,FLOAT!P:P) -> 0 | AP34: =AF34+AG34+AH34+AI34+AJ34+AK34+AM34+AN34+AO34 -> 0
E35: 54426125B | G35: 0 | N35: =SUMIF('3 D P'!$D:$D,Cockpit!$E$5:$E$146,'3 D P'!L:L) -> 0 | O35: =SUMIF('3 D P'!$D:$D,Cockpit!$E$5:$E$146,'3 D P'!M:M) -> 0 | P35: =SUMIF('3 D P'!$D:$D,Cockpit!$E$5:$E$146,'3 D P'!N:N) -> 0 | Q35: =IFERROR(VLOOKUP($D35,'Aptiv Dispatch'!$A:$B,2,FALSE),0) -> 0 | R35: =SUMIF('Consumption MTD'!B:B,Cockpit!$E$5:$E$146,'Consumption MTD'!C:C) -> 0 | S35: =SUMIF('BIW Lifting A Shift'!$B:$B,Cockpit!$E$5:$E$146,'BIW Lifting A Shift'!C:C) -> 0 | T35: =SUMIF('BIW Lifting A Shift'!$B:$B,Cockpit!$E$5:$E$146,'BIW Lifting A Shift'!#REF!) -> #REF! | X35: =SUMIF(FLOAT!$D:$D,Cockpit!$E$5:$E$146,FLOAT!F:F) -> 0 | Y35: =IFERROR(VLOOKUP(E35,[4]Sheet1!$D$4:$G$83,4,0),0) -> 0 | Z35: =IFERROR(VLOOKUP(E35,'[5]Cockpit Main'!$D$4:$G$83,4,0),0) -> 0 | AA35: 0 | AF35: =SUMIF(FLOAT!$D:$D,Cockpit!$E35:$E178,FLOAT!G:G) -> 0 | AG35: =SUMIF(FLOAT!$D:$D,Cockpit!$E35:$E178,FLOAT!H:H) -> 0 | AH35: =SUMIF(FLOAT!$D:$D,Cockpit!$E35:$E178,FLOAT!I:I) -> 0 | AI35: =SUMIF(FLOAT!$D:$D,Cockpit!$E35:$E178,FLOAT!J:J) -> 0 | AJ35: =SUMIF(FLOAT!$D:$D,Cockpit!$E35:$E178,FLOAT!K:K) -> 0 | AK35: =SUMIF(FLOAT!$D:$D,Cockpit!$E35:$E178,FLOAT!L:L) -> 0 | AL35: =SUMIF(FLOAT!$D:$D,Cockpit!$E35:$E178,FLOAT!M:M) -> 0 | AM35: =SUMIF(FLOAT!$D:$D,Cockpit!$E35:$E178,FLOAT!N:N) -> 0 | AN35: =SUMIF(FLOAT!$D:$D,Cockpit!$E35:$E178,FLOAT!O:O) -> 0 | AO35: =SUMIF(FLOAT!$D:$D,Cockpit!$E35:$E178,FLOAT!P:P) -> 0 | AP35: =AF35+AG35+AH35+AI35+AJ35+AK35+AM35+AN35+AO35 -> 0
E36: 54426125A | G36: 0 | N36: =SUMIF('3 D P'!$D:$D,Cockpit!$E$5:$E$146,'3 D P'!L:L) -> 0 | O36: =SUMIF('3 D P'!$D:$D,Cockpit!$E$5:$E$146,'3 D P'!M:M) -> 0 | P36: =SUMIF('3 D P'!$D:$D,Cockpit!$E$5:$E$146,'3 D P'!N:N) -> 0 | Q36: =IFERROR(VLOOKUP($D36,'Aptiv Dispatch'!$A:$B,2,FALSE),0) -> 0 | R36: =SUMIF('Consumption MTD'!B:B,Cockpit!$E$5:$E$146,'Consumption MTD'!C:C) -> 0 | S36: =SUMIF('BIW Lifting A Shift'!$B:$B,Cockpit!$E$5:$E$146,'BIW Lifting A Shift'!C:C) -> 0 | T36: =SUMIF('BIW Lifting A Shift'!$B:$B,Cockpit!$E$5:$E$146,'BIW Lifting A Shift'!#REF!) -> #REF! | X36: =SUMIF(FLOAT!$D:$D,Cockpit!$E$5:$E$146,FLOAT!F:F) -> 0 | Y36: =IFERROR(VLOOKUP(E36,[4]Sheet1!$D$4:$G$83,4,0),0) -> 0 | Z36: =IFERROR(VLOOKUP(E36,'[5]Cockpit Main'!$D$4:$G$83,4,0),0) -> 0 | AA36: 0 | AF36: =SUMIF(FLOAT!$D:$D,Cockpit!$E36:$E178,FLOAT!G:G) -> 0 | AG36: =SUMIF(FLOAT!$D:$D,Cockpit!$E36:$E178,FLOAT!H:H) -> 0 | AH36: =SUMIF(FLOAT!$D:$D,Cockpit!$E36:$E178,FLOAT!I:I) -> 0 | AI36: =SUMIF(FLOAT!$D:$D,Cockpit!$E36:$E178,FLOAT!J:J) -> 0 | AJ36: =SUMIF(FLOAT!$D:$D,Cockpit!$E36:$E178,FLOAT!K:K) -> 0 | AK36: =SUMIF(FLOAT!$D:$D,Cockpit!$E36:$E178,FLOAT!L:L) -> 0 | AL36: =SUMIF(FLOAT!$D:$D,Cockpit!$E36:$E178,FLOAT!M:M) -> 0 | AM36: =SUMIF(FLOAT!$D:$D,Cockpit!$E36:$E178,FLOAT!N:N) -> 0 | AN36: =SUMIF(FLOAT!$D:$D,Cockpit!$E36:$E178,FLOAT!O:O) -> 0 | AO36: =SUMIF(FLOAT!$D:$D,Cockpit!$E36:$E178,FLOAT!P:P) -> 0 | AP36: =AF36+AG36+AH36+AI36+AJ36+AK36+AM36+AN36+AO36 -> 0
C37: 544254630419 | D37: 544254640172 | E37: 54423425A | F37: ALTROZ XZ+(S) 1.5 RTQ BS6 | G37: 0 | H37: =SUM(G37:G42) -> 0 | I37: 0 | J37: =Q37 -> 0 | K37: =SUM(R37:R42) -> 0 | L37: =H37-K37 -> 0 | M37: =I37+J37-K37 -> 0 | N37: =SUMIF('3 D P'!$D:$D,Cockpit!$E$5:$E$146,'3 D P'!L:L) -> 0 | O37: =SUMIF('3 D P'!$D:$D,Cockpit!$E$5:$E$146,'3 D P'!M:M) -> 0 | P37: =SUMIF('3 D P'!$D:$D,Cockpit!$E$5:$E$146,'3 D P'!N:N) -> 0 | Q37: =IFERROR(VLOOKUP($D37,'Aptiv Dispatch'!$A:$B,2,FALSE),0) -> 0 | R37: =SUMIF('Consumption MTD'!B:B,Cockpit!$E$5:$E$146,'Consumption MTD'!C:C) -> 0 | S37: =SUMIF('BIW Lifting A Shift'!$B:$B,Cockpit!$E$5:$E$146,'BIW Lifting A Shift'!C:C) -> 0 | T37: =SUMIF('BIW Lifting A Shift'!$B:$B,Cockpit!$E$5:$E$146,'BIW Lifting A Shift'!#REF!) -> #REF! | U37: =M37-X37-X38-X39-X40-X41-X42 -> 0 | V37: =M37-SUM(X37:X42)-SUM(S37:S42) -> 0 | W37: =V37-SUM(T37:T42) -> #REF! | X37: =SUMIF(FLOAT!$D:$D,Cockpit!$E$5:$E$146,FLOAT!F:F) -> 0 | Y37: =IFERROR(VLOOKUP(E37,[4]Sheet1!$D$4:$G$83,4,0),0) -> 0 | Z37: =IFERROR(VLOOKUP(E37,'[5]Cockpit Main'!$D$4:$G$83,4,0),0) -> 0 | AA37: 5 | AC37: 29 | AF37: =SUMIF(FLOAT!$D:$D,Cockpit!$E37:$E178,FLOAT!G:G) -> 0 | AG37: =SUMIF(FLOAT!$D:$D,Cockpit!$E37:$E178,FLOAT!H:H) -> 0 | AH37: =SUMIF(FLOAT!$D:$D,Cockpit!$E37:$E178,FLOAT!I:I) -> 0 | AI37: =SUMIF(FLOAT!$D:$D,Cockpit!$E37:$E178,FLOAT!J:J) -> 0 | AJ37: =SUMIF(FLOAT!$D:$D,Cockpit!$E37:$E178,FLOAT!K:K) -> 0 | AK37: =SUMIF(FLOAT!$D:$D,Cockpit!$E37:$E178,FLOAT!L:L) -> 0 | AL37: =SUMIF(FLOAT!$D:$D,Cockpit!$E37:$E178,FLOAT!M:M) -> 0 | AM37: =SUMIF(FLOAT!$D:$D,Cockpit!$E37:$E178,FLOAT!N:N) -> 0 | AN37: =SUMIF(FLOAT!$D:$D,Cockpit!$E37:$E178,FLOAT!O:O) -> 0 | AO37: =SUMIF(FLOAT!$D:$D,Cockpit!$E37:$E178,FLOAT!P:P) -> 0 | AP37: =AF37+AG37+AH37+AI37+AJ37+AK37+AM37+AN37+AO37 -> 0
E38: 54420126A | F38: ALTROZ XZ+(S) 1.5 RTQ BS6 DARK | G38: 0 | N38: =SUMIF('3 D P'!$D:$D,Cockpit!$E$5:$E$146,'3 D P'!L:L) -> 0 | O38: =SUMIF('3 D P'!$D:$D,Cockpit!$E$5:$E$146,'3 D P'!M:M) -> 0 | P38: =SUMIF('3 D P'!$D:$D,Cockpit!$E$5:$E$146,'3 D P'!N:N) -> 0 | Q38: =IFERROR(VLOOKUP($D38,'Aptiv Dispatch'!$A:$B,2,FALSE),0) -> 0 | R38: =SUMIF('Consumption MTD'!B:B,Cockpit!$E$5:$E$146,'Consumption MTD'!C:C) -> 0 | S38: =SUMIF('BIW Lifting A Shift'!$B:$B,Cockpit!$E$5:$E$146,'BIW Lifting A Shift'!C:C) -> 0 | T38: =SUMIF('BIW Lifting A Shift'!$B:$B,Cockpit!$E$5:$E$146,'BIW Lifting A Shift'!#REF!) -> #REF! | X38: =SUMIF(FLOAT!$D:$D,Cockpit!$E$5:$E$146,FLOAT!F:F) -> 0 | Y38: =IFERROR(VLOOKUP(E38,[4]Sheet1!$D$4:$G$83,4,0),0) -> 0 | Z38: =IFERROR(VLOOKUP(E38,'[5]Cockpit Main'!$D$4:$G$83,4,0),0) -> 0 | AA38: 0 | AF38: =SUMIF(FLOAT!$D:$D,Cockpit!$E38:$E178,FLOAT!G:G) -> 0 | AG38: =SUMIF(FLOAT!$D:$D,Cockpit!$E38:$E178,FLOAT!H:H) -> 0 | AH38: =SUMIF(FLOAT!$D:$D,Cockpit!$E38:$E178,FLOAT!I:I) -> 0 | AI38: =SUMIF(FLOAT!$D:$D,Cockpit!$E38:$E178,FLOAT!J:J) -> 0 | AJ38: =SUMIF(FLOAT!$D:$D,Cockpit!$E38:$E178,FLOAT!K:K) -> 0 | AK38: =SUMIF(FLOAT!$D:$D,Cockpit!$E38:$E178,FLOAT!L:L) -> 0 | AL38: =SUMIF(FLOAT!$D:$D,Cockpit!$E38:$E178,FLOAT!M:M) -> 0 | AM38: =SUMIF(FLOAT!$D:$D,Cockpit!$E38:$E178,FLOAT!N:N) -> 0 | AN38: =SUMIF(FLOAT!$D:$D,Cockpit!$E38:$E178,FLOAT!O:O) -> 0 | AO38: =SUMIF(FLOAT!$D:$D,Cockpit!$E38:$E178,FLOAT!P:P) -> 0 | AP38: =AF38+AG38+AH38+AI38+AJ38+AK38+AM38+AN38+AO38 -> 0
E39: 54423125A | F39: ALTROZ XZ+(S) 1.2P MT BS6 | G39: 0 | N39: =SUMIF('3 D P'!$D:$D,Cockpit!$E$5:$E$146,'3 D P'!L:L) -> 0 | O39: =SUMIF('3 D P'!$D:$D,Cockpit!$E$5:$E$146,'3 D P'!M:M) -> 0 | P39: =SUMIF('3 D P'!$D:$D,Cockpit!$E$5:$E$146,'3 D P'!N:N) -> 0 | Q39: =IFERROR(VLOOKUP($D39,'Aptiv Dispatch'!$A:$B,2,FALSE),0) -> 0 | R39: =SUMIF('Consumption MTD'!B:B,Cockpit!$E$5:$E$146,'Consumption MTD'!C:C) -> 0 | S39: =SUMIF('BIW Lifting A Shift'!$B:$B,Cockpit!$E$5:$E$146,'BIW Lifting A Shift'!C:C) -> 0 | T39: =SUMIF('BIW Lifting A Shift'!$B:$B,Cockpit!$E$5:$E$146,'BIW Lifting A Shift'!#REF!) -> #REF! | X39: =SUMIF(FLOAT!$D:$D,Cockpit!$E$5:$E$146,FLOAT!F:F) -> 0 | Y39: =IFERROR(VLOOKUP(E39,[4]Sheet1!$D$4:$G$83,4,0),0) -> 0 | Z39: =IFERROR(VLOOKUP(E39,'[5]Cockpit Main'!$D$4:$G$83,4,0),0) -> 0 | AA39: 0 | AF39: =SUMIF(FLOAT!$D:$D,Cockpit!$E39:$E178,FLOAT!G:G) -> 0 | AG39: =SUMIF(FLOAT!$D:$D,Cockpit!$E39:$E178,FLOAT!H:H) -> 0 | AH39: =SUMIF(FLOAT!$D:$D,Cockpit!$E39:$E178,FLOAT!I:I) -> 0 | AI39: =SUMIF(FLOAT!$D:$D,Cockpit!$E39:$E178,FLOAT!J:J) -> 0 | AJ39: =SUMIF(FLOAT!$D:$D,Cockpit!$E39:$E178,FLOAT!K:K) -> 0 | AK39: =SUMIF(FLOAT!$D:$D,Cockpit!$E39:$E178,FLOAT!L:L) -> 0 | AL39: =SUMIF(FLOAT!$D:$D,Cockpit!$E39:$E178,FLOAT!M:M) -> 0 | AM39: =SUMIF(FLOAT!$D:$D,Cockpit!$E39:$E178,FLOAT!N:N) -> 0 | AN39: =SUMIF(FLOAT!$D:$D,Cockpit!$E39:$E178,FLOAT!O:O) -> 0 | AO39: =SUMIF(FLOAT!$D:$D,Cockpit!$E39:$E178,FLOAT!P:P) -> 0 | AP39: =AF39+AG39+AH39+AI39+AJ39+AK39+AM39+AN39+AO39 -> 0
