Workbook

Sheet Fresh VIN PPC
J2: =J19 -> 438 | P2: =P8 -> 0 | Q2: =Q8 -> 0 | U2: =U8 -> 0
A3: Cockpit WH Number | B3: Short VC No | C3: Model | D3: PLAN | E3: W/H Requirement | F3: Month O/P | G3: Inwards | H3: Consumption | I3: Balance Production | J3: Today's O/P | K3: =TODAY() -> 46221 | L3: =TODAY()+1 -> 46222 | M3: =TODAY()+2 -> 46223 | N3: Cumulative Dispatch | O3: Consumption | P3: A SHIFT BIW LIFTING | Q3: B SHIFT BIW LIFTING | R3: Float Coverage at 6:30am | S3: Float Coverage at 3 pm | T3: Float Coverage at 11:30 pm | U3: Paint float 06:30am | W3: Safety | Y3: TOTAL FLOAT | Z3: PBS FLOAT | AA3: PBS TO POLISHING | AB3: POLISHING TO TOPCOAT | AC3: TOPCOAT TO WETSANDING ROOFBLACK | AD3: TOPCOAT TO WETSANDING FRESH | AE3: WETSANDING TO SEALANT | AF3: TOTAL UPTO SEALANT | AG3: PT ENTRY TO SEALENT | AH3: BIW LIFTING TO PT | AI3: PT BYPASS | AJ3: Total
A4: 546854600231 | B4: 54680224A | C4: Persona 3 - Base VC + Everything Pack | D4: 0 | E4: =SUM(D4:D7) -> 75 | F4: 8 | G4: =N4 -> 0 | H4: =SUM(O4:O7) -> 0 | I4: =E4-H4 -> 75 | J4: =F4+G4-H4 -> 8 | K4: =SUMIF('3 D P'!$E:$E,'Fresh VIN PPC'!$B:$B,'3 D P'!$J:$J) -> 0 | L4: =SUMIF('3 D P'!$E:$E,'Fresh VIN PPC'!$B:$B,'3 D P'!$K:$K) -> 0 | M4: =SUMIF('3 D P'!$E:$E,'Fresh VIN PPC'!$B:$B,'3 D P'!$L:$L) -> 0 | N4: =IFERROR(VLOOKUP(A4,'Daywise Dispatch'!$A:$B,2,FALSE),0) -> 0 | O4: =SUMIF('Consumption MTD'!$B:$B,$B$4:$B$7,'Consumption MTD'!$C:$C) -> 0 | P4: =SUMIF('BIW Lifting A Shift'!$B:$B,$B$4:$B$7,'BIW Lifting A Shift'!$C:$C) -> 0 | Q4: =SUMIF('BIW Lifting B Shift'!$B:$B,$B$4:$B$7,'BIW Lifting B Shift'!$C:$C) -> 0 | R4: =J4-U4-U6-U7-U5 -> 8 | S4: =J4-P4-P6-P7-U4-U6-U7-U5-P5 -> 8 | T4: =S4-Q4-Q6-Q7-Q5 -> 8 | U4: =SUMIF(FLOAT!$D:$D,$B$4:$B$7,FLOAT!$F:$F) -> 0 | Y4: =SUMIF(FLOAT!$D:$D,$B$4:$B$7,FLOAT!$F:$F) -> 0 | Z4: =SUMIF(FLOAT!$D:$D,$B$4:$B$7,FLOAT!$G:$G) -> 0 | AA4: =SUMIF(FLOAT!$D:$D,$B$4:$B$7,FLOAT!$H:$H) -> 0 | AB4: =SUMIF(FLOAT!$D:$D,$B$4:$B$7,FLOAT!$I:$I) -> 0 | AC4: =SUMIF(FLOAT!$D:$D,$B$4:$B$7,FLOAT!$J:$J) -> 0 | AD4: =SUMIF(FLOAT!$D:$D,$B$4:$B$7,FLOAT!$K:$K) -> 0 | AE4: =SUMIF(FLOAT!$D:$D,$B$4:$B$7,FLOAT!$L:$L) -> 0 | AF4: =SUMIF(FLOAT!$D:$D,$B$4:$B$7,FLOAT!$M:$M) -> 0 | AG4: =SUMIF(FLOAT!$D:$D,$B$4:$B$7,FLOAT!$N:$N) -> 0 | AH4: =SUMIF(FLOAT!$D:$D,$B$4:$B$7,FLOAT!$O:$O) -> 0 | AI4: =SUMIF(FLOAT!$D:$D,$B$4:$B$7,FLOAT!$P:$P) -> 0 | AJ4: =SUM(Z4:AE4)+SUM(AG4:AI4) -> 0
B5: 54683524A | C5: PUNCH.EV EMP + S LR ACFC | D5: 0 | K5: =SUMIF('3 D P'!$E:$E,'Fresh VIN PPC'!$B:$B,'3 D P'!$J:$J) -> 0 | L5: =SUMIF('3 D P'!$E:$E,'Fresh VIN PPC'!$B:$B,'3 D P'!$K:$K) -> 0 | M5: =SUMIF('3 D P'!$E:$E,'Fresh VIN PPC'!$B:$B,'3 D P'!$L:$L) -> 0 | N5: =IFERROR(VLOOKUP(A5,'Daywise Dispatch'!$A:$B,2,FALSE),0) -> 0 | O5: =SUMIF('Consumption MTD'!$B:$B,$B$4:$B$7,'Consumption MTD'!$C:$C) -> 0 | P5: =SUMIF('BIW Lifting A Shift'!$B:$B,$B$4:$B$7,'BIW Lifting A Shift'!$C:$C) -> 0 | Q5: =SUMIF('BIW Lifting B Shift'!$B:$B,$B$4:$B$7,'BIW Lifting B Shift'!$C:$C) -> 0 | U5: =SUMIF(FLOAT!$D:$D,$B$4:$B$7,FLOAT!$F:$F) -> 0 | Y5: =SUMIF(FLOAT!$D:$D,$B$4:$B$7,FLOAT!$F:$F) -> 0 | Z5: =SUMIF(FLOAT!$D:$D,$B$4:$B$7,FLOAT!$G:$G) -> 0 | AA5: =SUMIF(FLOAT!$D:$D,$B$4:$B$7,FLOAT!$H:$H) -> 0 | AB5: =SUMIF(FLOAT!$D:$D,$B$4:$B$7,FLOAT!$I:$I) -> 0 | AC5: =SUMIF(FLOAT!$D:$D,$B$4:$B$7,FLOAT!$J:$J) -> 0 | AD5: =SUMIF(FLOAT!$D:$D,$B$4:$B$7,FLOAT!$K:$K) -> 0 | AE5: =SUMIF(FLOAT!$D:$D,$B$4:$B$7,FLOAT!$L:$L) -> 0 | AF5: =SUMIF(FLOAT!$D:$D,$B$4:$B$7,FLOAT!$M:$M) -> 0 | AG5: =SUMIF(FLOAT!$D:$D,$B$4:$B$7,FLOAT!$N:$N) -> 0 | AH5: =SUMIF(FLOAT!$D:$D,$B$4:$B$7,FLOAT!$O:$O) -> 0 | AI5: =SUMIF(FLOAT!$D:$D,$B$4:$B$7,FLOAT!$P:$P) -> 0 | AJ5: =SUM(Z5:AE5)+SUM(AG5:AI5) -> 0
B6: 54681824A | C6: Persona 3 - Base VC + Everything Pack | D6: 0 | K6: =SUMIF('3 D P'!$E:$E,'Fresh VIN PPC'!$B:$B,'3 D P'!$J:$J) -> 0 | L6: =SUMIF('3 D P'!$E:$E,'Fresh VIN PPC'!$B:$B,'3 D P'!$K:$K) -> 0 | M6: =SUMIF('3 D P'!$E:$E,'Fresh VIN PPC'!$B:$B,'3 D P'!$L:$L) -> 0 | N6: =IFERROR(VLOOKUP(A6,'Daywise Dispatch'!$A:$B,2,FALSE),0) -> 0 | O6: =SUMIF('Consumption MTD'!$B:$B,$B$4:$B$7,'Consumption MTD'!$C:$C) -> 0 | P6: =SUMIF('BIW Lifting A Shift'!$B:$B,$B$4:$B$7,'BIW Lifting A Shift'!$C:$C) -> 0 | Q6: =SUMIF('BIW Lifting B Shift'!$B:$B,$B$4:$B$7,'BIW Lifting B Shift'!$C:$C) -> 0 | U6: =SUMIF(FLOAT!$D:$D,$B$4:$B$7,FLOAT!$F:$F) -> 0 | Y6: =SUMIF(FLOAT!$D:$D,$B$4:$B$7,FLOAT!$F:$F) -> 0 | Z6: =SUMIF(FLOAT!$D:$D,$B$4:$B$7,FLOAT!$G:$G) -> 0 | AA6: =SUMIF(FLOAT!$D:$D,$B$4:$B$7,FLOAT!$H:$H) -> 0 | AB6: =SUMIF(FLOAT!$D:$D,$B$4:$B$7,FLOAT!$I:$I) -> 0 | AC6: =SUMIF(FLOAT!$D:$D,$B$4:$B$7,FLOAT!$J:$J) -> 0 | AD6: =SUMIF(FLOAT!$D:$D,$B$4:$B$7,FLOAT!$K:$K) -> 0 | AE6: =SUMIF(FLOAT!$D:$D,$B$4:$B$7,FLOAT!$L:$L) -> 0 | AF6: =SUMIF(FLOAT!$D:$D,$B$4:$B$7,FLOAT!$M:$M) -> 0 | AG6: =SUMIF(FLOAT!$D:$D,$B$4:$B$7,FLOAT!$N:$N) -> 0 | AH6: =SUMIF(FLOAT!$D:$D,$B$4:$B$7,FLOAT!$O:$O) -> 0 | AI6: =SUMIF(FLOAT!$D:$D,$B$4:$B$7,FLOAT!$P:$P) -> 0 | AJ6: =SUM(Z6:AE6)+SUM(AG6:AI6) -> 0
B7: 54683124A | C7: PUNCH.EV EMP + S LR SA | D7: 75 | K7: =SUMIF('3 D P'!$E:$E,'Fresh VIN PPC'!$B:$B,'3 D P'!$J:$J) -> 0 | L7: =SUMIF('3 D P'!$E:$E,'Fresh VIN PPC'!$B:$B,'3 D P'!$K:$K) -> 0 | M7: =SUMIF('3 D P'!$E:$E,'Fresh VIN PPC'!$B:$B,'3 D P'!$L:$L) -> 0 | N7: =IFERROR(VLOOKUP(A7,'Daywise Dispatch'!$A:$B,2,FALSE),0) -> 0 | O7: =SUMIF('Consumption MTD'!$B:$B,$B$4:$B$7,'Consumption MTD'!$C:$C) -> 0 | P7: =SUMIF('BIW Lifting A Shift'!$B:$B,$B$4:$B$7,'BIW Lifting A Shift'!$C:$C) -> 0 | Q7: =SUMIF('BIW Lifting B Shift'!$B:$B,$B$4:$B$7,'BIW Lifting B Shift'!$C:$C) -> 0 | U7: =SUMIF(FLOAT!$D:$D,$B$4:$B$7,FLOAT!$F:$F) -> 0 | Y7: =SUMIF(FLOAT!$D:$D,$B$4:$B$7,FLOAT!$F:$F) -> 0 | Z7: =SUMIF(FLOAT!$D:$D,$B$4:$B$7,FLOAT!$G:$G) -> 0 | AA7: =SUMIF(FLOAT!$D:$D,$B$4:$B$7,FLOAT!$H:$H) -> 0 | AB7: =SUMIF(FLOAT!$D:$D,$B$4:$B$7,FLOAT!$I:$I) -> 0 | AC7: =SUMIF(FLOAT!$D:$D,$B$4:$B$7,FLOAT!$J:$J) -> 0 | AD7: =SUMIF(FLOAT!$D:$D,$B$4:$B$7,FLOAT!$K:$K) -> 0 | AE7: =SUMIF(FLOAT!$D:$D,$B$4:$B$7,FLOAT!$L:$L) -> 0 | AF7: =SUMIF(FLOAT!$D:$D,$B$4:$B$7,FLOAT!$M:$M) -> 0 | AG7: =SUMIF(FLOAT!$D:$D,$B$4:$B$7,FLOAT!$N:$N) -> 0 | AH7: =SUMIF(FLOAT!$D:$D,$B$4:$B$7,FLOAT!$O:$O) -> 0 | AI7: =SUMIF(FLOAT!$D:$D,$B$4:$B$7,FLOAT!$P:$P) -> 0 | AJ7: =SUM(Z7:AE7)+SUM(AG7:AI7) -> 0
D8: =SUM(D4:D7) -> 75 | E8: =SUM(E4:E7) -> 75 | F8: 786 | G8: =SUM(G4:G7) -> 0 | H8: =SUM(H4:H7) -> 0 | I8: =SUM(I4:I7) -> 75 | J8: =SUM(J4:J7) -> 8 | K8: =SUM(K4:K7) -> 0 | L8: =SUM(L4:L7) -> 0 | M8: =SUM(M4:M7) -> 0 | N8: =SUM(N4:N7) -> 0 | ... Q8: =SUM(Q4:Q7) -> 0 | U8: =SUM(U4:U7) -> 0 | Y8: =SUM(Y4:Y7) -> 0 | Z8: =SUM(Z4:Z7) -> 0 | AA8: =SUM(AA4:AA7) -> 0 | AB8: =SUM(AB4:AB7) -> 0 | AC8: =SUM(AC4:AC7) -> 0 | AD8: =SUM(AD4:AD7) -> 0 | AE8: =SUM(AE4:AE7) -> 0 | AF8: =SUM(AF4:AF7) -> 0 | ... AJ8: =SUM(AJ4:AJ7) -> 0
A10: Cockpit WH Number | B10: Short VC No | C10: Model | D10: PLAN | E10: W/H Requirement | F10: Month O/P | G10: Inwards | H10: Consumption | I10: Balance Production | J10: Today's O/P | K10: =TODAY() -> 46221 | L10: =TODAY()+1 -> 46222 | M10: =TODAY()+2 -> 46223 | N10: Cumulative Dispatch | O10: Consumption | P10: A SHIFT BIW LIFTING | Q10: B SHIFT BIW LIFTING | R10: Float Coverage at 6:30am | S10: Float Coverage at 3 pm | T10: Float Coverage at 11:30 pm | U10: Paint float 06:30am | V10: opening | Y10: TOTAL FLOAT | Z10: PBS FLOAT | AA10: PBS TO POLISHING | AB10: POLISHING TO TOPCOAT | AC10: TOPCOAT TO WETSANDING ROOFBLACK | AD10: TOPCOAT TO WETSANDING FRESH | AE10: WETSANDING TO SEALANT | AF10: TOTAL UPTO SEALANT | AG10: PT ENTRY TO SEALENT | AH10: BIW LIFTING TO PT | AI10: PT BYPASS | AJ10: Total
A11: 546854650101 | B11: 54684124A | C11: PUNCH.EV SMT | D11: 16 | E11: 16 | F11: 5 | G11: =N11 -> 0 | H11: =O11 -> 0 | I11: =E11-H11 -> 16 | J11: =F11+G11-H11 -> 5 | K11: =SUMIF('3 D P'!$E:$E,'Fresh VIN PPC'!$B:$B,'3 D P'!$J:$J) -> 0 | L11: =SUMIF('3 D P'!$E:$E,'Fresh VIN PPC'!$B:$B,'3 D P'!$K:$K) -> 0 | M11: =SUMIF('3 D P'!$E:$E,'Fresh VIN PPC'!$B:$B,'3 D P'!$L:$L) -> 0 | N11: =IFERROR(VLOOKUP(A11,'Daywise Dispatch'!$A:$B,2,FALSE),0) -> 0 | O11: =SUMIF('Consumption MTD'!$B:$B,$B$4:$B$20,'Consumption MTD'!$C:$C) -> 0 | P11: =SUMIF('BIW Lifting A Shift'!$B:$B,$B$4:$B$18,'BIW Lifting A Shift'!$C:$C) -> 0 | Q11: =SUMIF('BIW Lifting B Shift'!$B:$B,$B$4:$B$18,'BIW Lifting B Shift'!$C:$C) -> 0 | R11: =J11-U11 -> 5 | S11: =J11-P11-U11 -> 5 | T11: =S11-Q11 -> 5 | U11: =SUMIF(FLOAT!$D:$D,$B$4:$B$18,FLOAT!$F:$F) -> 0 | V11: 5 | W11: 1 | X11: 5 | Y11: =SUMIF(FLOAT!$D:$D,$B$4:$B$18,FLOAT!$F:$F) -> 0 | Z11: =SUMIF(FLOAT!$D:$D,$B$4:$B$18,FLOAT!$G:$G) -> 0 | AA11: =SUMIF(FLOAT!$D:$D,$B$4:$B$18,FLOAT!$H:$H) -> 0 | AB11: =SUMIF(FLOAT!$D:$D,$B$4:$B$18,FLOAT!$I:$I) -> 0 | AC11: =SUMIF(FLOAT!$D:$D,$B$4:$B$18,FLOAT!$J:$J) -> 0 | AD11: =SUMIF(FLOAT!$D:$D,$B$4:$B$19,FLOAT!$K:$K) -> 0 | AE11: =SUMIF(FLOAT!$D:$D,$B$4:$B$20,FLOAT!$L:$L) -> 0 | AF11: =SUMIF(FLOAT!$D:$D,$B$4:$B$18,FLOAT!$M:$M) -> 0 | AG11: =SUMIF(FLOAT!$D:$D,$B$4:$B$19,FLOAT!$N:$N) -> 0 | AH11: =SUMIF(FLOAT!$D:$D,$B$4:$B$19,FLOAT!$O:$O) -> 0 | AI11: =SUMIF(FLOAT!$D:$D,$B$4:$B$719,FLOAT!$P:$P) -> 0 | AJ11: =SUM(Z11:AE11)+SUM(AG11:AI11) -> 0
A12: 546854650102 | B12: 54684224A | C12: PUNCH.EV SMT + | D12: 22 | E12: 22 | F12: 6 | G12: =N12 -> 0 | H12: =O12 -> 0 | I12: =E12-H12 -> 22 | J12: =F12+G12-H12 -> 6 | K12: =SUMIF('3 D P'!$E:$E,'Fresh VIN PPC'!$B:$B,'3 D P'!$J:$J) -> 0 | L12: =SUMIF('3 D P'!$E:$E,'Fresh VIN PPC'!$B:$B,'3 D P'!$K:$K) -> 0 | M12: =SUMIF('3 D P'!$E:$E,'Fresh VIN PPC'!$B:$B,'3 D P'!$L:$L) -> 0 | N12: =IFERROR(VLOOKUP(A12,'Daywise Dispatch'!$A:$B,2,FALSE),0) -> 0 | O12: =SUMIF('Consumption MTD'!$B:$B,$B$4:$B$20,'Consumption MTD'!$C:$C) -> 0 | P12: =SUMIF('BIW Lifting A Shift'!$B:$B,$B$4:$B$18,'BIW Lifting A Shift'!$C:$C) -> 0 | Q12: =SUMIF('BIW Lifting B Shift'!$B:$B,$B$4:$B$18,'BIW Lifting B Shift'!$C:$C) -> 0 | R12: =J12-U12 -> 6 | S12: =J12-P12-U12 -> 6 | T12: =S12-Q12 -> 6 | U12: =SUMIF(FLOAT!$D:$D,$B$4:$B$18,FLOAT!$F:$F) -> 0 | V12: 6 | W12: 1 | X12: 6 | Y12: =SUMIF(FLOAT!$D:$D,$B$4:$B$18,FLOAT!$F:$F) -> 0 | Z12: =SUMIF(FLOAT!$D:$D,$B$4:$B$18,FLOAT!$G:$G) -> 0 | AA12: =SUMIF(FLOAT!$D:$D,$B$4:$B$18,FLOAT!$H:$H) -> 0 | AB12: =SUMIF(FLOAT!$D:$D,$B$4:$B$18,FLOAT!$I:$I) -> 0 | AC12: =SUMIF(FLOAT!$D:$D,$B$4:$B$18,FLOAT!$J:$J) -> 0 | AD12: =SUMIF(FLOAT!$D:$D,$B$4:$B$19,FLOAT!$K:$K) -> 0 | AE12: =SUMIF(FLOAT!$D:$D,$B$4:$B$20,FLOAT!$L:$L) -> 0 | AF12: =SUMIF(FLOAT!$D:$D,$B$4:$B$18,FLOAT!$M:$M) -> 0 | AG12: =SUMIF(FLOAT!$D:$D,$B$4:$B$19,FLOAT!$N:$N) -> 0 | AH12: =SUMIF(FLOAT!$D:$D,$B$4:$B$19,FLOAT!$O:$O) -> 0 | AI12: =SUMIF(FLOAT!$D:$D,$B$4:$B$719,FLOAT!$P:$P) -> 0 | AJ12: =SUM(Z12:AE12)+SUM(AG12:AI12) -> 0
A13: 546854650110 | B13: 54686224A | C13: PUNCH.EV SMT + LR | D13: 412 | E13: 412 | F13: =19-5 -> 14 | G13: =N13 -> 385 | H13: =O13 -> 300 | I13: =E13-H13 -> 112 | J13: =F13+G13-H13 -> 99 | K13: =SUMIF('3 D P'!$E:$E,'Fresh VIN PPC'!$B:$B,'3 D P'!$J:$J) -> 3 | L13: =SUMIF('3 D P'!$E:$E,'Fresh VIN PPC'!$B:$B,'3 D P'!$K:$K) -> 51 | M13: =SUMIF('3 D P'!$E:$E,'Fresh VIN PPC'!$B:$B,'3 D P'!$L:$L) -> 49 | N13: =IFERROR(VLOOKUP(A13,'Daywise Dispatch'!$A:$B,2,FALSE),0) -> 385 | O13: =SUMIF('Consumption MTD'!$B:$B,$B$4:$B$20,'Consumption MTD'!$C:$C) -> 300 | P13: =SUMIF('BIW Lifting A Shift'!$B:$B,$B$4:$B$18,'BIW Lifting A Shift'!$C:$C) -> 0 | Q13: =SUMIF('BIW Lifting B Shift'!$B:$B,$B$4:$B$18,'BIW Lifting B Shift'!$C:$C) -> 0 | R13: =J13-U13 -> 89 | S13: =J13-P13-U13 -> 89 | T13: =S13-Q13 -> 89 | U13: =SUMIF(FLOAT!$D:$D,$B$4:$B$18,FLOAT!$F:$F) -> 10 | V13: 15 | X13: 17 | Y13: =SUMIF(FLOAT!$D:$D,$B$4:$B$18,FLOAT!$F:$F) -> 10 | Z13: =SUMIF(FLOAT!$D:$D,$B$4:$B$18,FLOAT!$G:$G) -> 3 | AA13: =SUMIF(FLOAT!$D:$D,$B$4:$B$18,FLOAT!$H:$H) -> 1 | AB13: =SUMIF(FLOAT!$D:$D,$B$4:$B$18,FLOAT!$I:$I) -> 0 | AC13: =SUMIF(FLOAT!$D:$D,$B$4:$B$18,FLOAT!$J:$J) -> 0 | AD13: =SUMIF(FLOAT!$D:$D,$B$4:$B$19,FLOAT!$K:$K) -> 1 | AE13: =SUMIF(FLOAT!$D:$D,$B$4:$B$20,FLOAT!$L:$L) -> 1 | AF13: =SUMIF(FLOAT!$D:$D,$B$4:$B$18,FLOAT!$M:$M) -> 6 | AG13: =SUMIF(FLOAT!$D:$D,$B$4:$B$19,FLOAT!$N:$N) -> 0 | AH13: =SUMIF(FLOAT!$D:$D,$B$4:$B$19,FLOAT!$O:$O) -> 4 | AI13: =SUMIF(FLOAT!$D:$D,$B$4:$B$719,FLOAT!$P:$P) -> 0 | AJ13: =SUM(Z13:AE13)+SUM(AG13:AI13) -> 10
A14: 546854650111 | B14: 54686324A | C14: PUNCH.EV ADV LR | D14: 376 | E14: 376 | F14: =122-1 -> 121 | G14: =N14 -> 369 | H14: =O14 -> 290 | I14: =E14-H14 -> 86 | J14: =F14+G14-H14 -> 200 | K14: =SUMIF('3 D P'!$E:$E,'Fresh VIN PPC'!$B:$B,'3 D P'!$J:$J) -> 174 | L14: =SUMIF('3 D P'!$E:$E,'Fresh VIN PPC'!$B:$B,'3 D P'!$K:$K) -> 158 | M14: =SUMIF('3 D P'!$E:$E,'Fresh VIN PPC'!$B:$B,'3 D P'!$L:$L) -> 98 | N14: =IFERROR(VLOOKUP(A14,'Daywise Dispatch'!$A:$B,2,FALSE),0) -> 369 | O14: =SUMIF('Consumption MTD'!$B:$B,$B$4:$B$20,'Consumption MTD'!$C:$C) -> 290 | P14: =SUMIF('BIW Lifting A Shift'!$B:$B,$B$4:$B$18,'BIW Lifting A Shift'!$C:$C) -> 0 | Q14: =SUMIF('BIW Lifting B Shift'!$B:$B,$B$4:$B$18,'BIW Lifting B Shift'!$C:$C) -> 0 | R14: =J14-U14 -> 148 | S14: =J14-P14-U14 -> 148 | T14: =S14-Q14 -> 148 | U14: =SUMIF(FLOAT!$D:$D,$B$4:$B$18,FLOAT!$F:$F) -> 52 | V14: 9 | X14: 34 | Y14: =SUMIF(FLOAT!$D:$D,$B$4:$B$18,FLOAT!$F:$F) -> 52 | Z14: =SUMIF(FLOAT!$D:$D,$B$4:$B$18,FLOAT!$G:$G) -> 2 | AA14: =SUMIF(FLOAT!$D:$D,$B$4:$B$18,FLOAT!$H:$H) -> 2 | AB14: =SUMIF(FLOAT!$D:$D,$B$4:$B$18,FLOAT!$I:$I) -> 8 | AC14: =SUMIF(FLOAT!$D:$D,$B$4:$B$18,FLOAT!$J:$J) -> 0 | AD14: =SUMIF(FLOAT!$D:$D,$B$4:$B$19,FLOAT!$K:$K) -> 5 | AE14: =SUMIF(FLOAT!$D:$D,$B$4:$B$20,FLOAT!$L:$L) -> 11 | AF14: =SUMIF(FLOAT!$D:$D,$B$4:$B$18,FLOAT!$M:$M) -> 28 | AG14: =SUMIF(FLOAT!$D:$D,$B$4:$B$19,FLOAT!$N:$N) -> 13 | AH14: =SUMIF(FLOAT!$D:$D,$B$4:$B$19,FLOAT!$O:$O) -> 11 | AI14: =SUMIF(FLOAT!$D:$D,$B$4:$B$719,FLOAT!$P:$P) -> 0 | AJ14: =SUM(Z14:AE14)+SUM(AG14:AI14) -> 52
A15: 546854650115 | B15: 54686724A | C15: PUNCH.EV EMP + LR | D15: 309 | E15: 309 | F15: 38 | G15: =N15 -> 99 | H15: =O15 -> 132 | I15: =E15-H15 -> 177 | J15: =F15+G15-H15 -> 5 | K15: =SUMIF('3 D P'!$E:$E,'Fresh VIN PPC'!$B:$B,'3 D P'!$J:$J) -> 7 | L15: =SUMIF('3 D P'!$E:$E,'Fresh VIN PPC'!$B:$B,'3 D P'!$K:$K) -> 19 | M15: =SUMIF('3 D P'!$E:$E,'Fresh VIN PPC'!$B:$B,'3 D P'!$L:$L) -> 3 | N15: =IFERROR(VLOOKUP(A15,'Daywise Dispatch'!$A:$B,2,FALSE),0) -> 99 | O15: =SUMIF('Consumption MTD'!$B:$B,$B$4:$B$20,'Consumption MTD'!$C:$C) -> 132 | P15: =SUMIF('BIW Lifting A Shift'!$B:$B,$B$4:$B$18,'BIW Lifting A Shift'!$C:$C) -> 0 | Q15: =SUMIF('BIW Lifting B Shift'!$B:$B,$B$4:$B$18,'BIW Lifting B Shift'!$C:$C) -> 0 | R15: =J15-U15 -> 1 | S15: =J15-P15-U15 -> 1 | T15: =S15-Q15 -> 1 | U15: =SUMIF(FLOAT!$D:$D,$B$4:$B$18,FLOAT!$F:$F) -> 4 | V15: 6 | W15: 1 | X15: 53 | Y15: =SUMIF(FLOAT!$D:$D,$B$4:$B$18,FLOAT!$F:$F) -> 4 | Z15: =SUMIF(FLOAT!$D:$D,$B$4:$B$18,FLOAT!$G:$G) -> 1 | AA15: =SUMIF(FLOAT!$D:$D,$B$4:$B$18,FLOAT!$H:$H) -> 1 | AB15: =SUMIF(FLOAT!$D:$D,$B$4:$B$18,FLOAT!$I:$I) -> 0 | AC15: =SUMIF(FLOAT!$D:$D,$B$4:$B$18,FLOAT!$J:$J) -> 0 | AD15: =SUMIF(FLOAT!$D:$D,$B$4:$B$19,FLOAT!$K:$K) -> 0 | AE15: =SUMIF(FLOAT!$D:$D,$B$4:$B$20,FLOAT!$L:$L) -> 0 | AF15: =SUMIF(FLOAT!$D:$D,$B$4:$B$18,FLOAT!$M:$M) -> 2 | AG15: =SUMIF(FLOAT!$D:$D,$B$4:$B$19,FLOAT!$N:$N) -> 1 | AH15: =SUMIF(FLOAT!$D:$D,$B$4:$B$19,FLOAT!$O:$O) -> 1 | AI15: =SUMIF(FLOAT!$D:$D,$B$4:$B$719,FLOAT!$P:$P) -> 0 | AJ15: =SUM(Z15:AE15)+SUM(AG15:AI15) -> 4
A16: 546854650116 | B16: 54686824A | C16: PUNCH.EV EMP + S LR | D16: 2976 | E16: 2976 | F16: =167 -> 167 | G16: =N16 -> 1282 | H16: =O16 -> 1326 | I16: =E16-H16 -> 1650 | J16: =F16+G16-H16 -> 123 | K16: =SUMIF('3 D P'!$E:$E,'Fresh VIN PPC'!$B:$B,'3 D P'!$J:$J) -> 78 | L16: =SUMIF('3 D P'!$E:$E,'Fresh VIN PPC'!$B:$B,'3 D P'!$K:$K) -> 37 | M16: =SUMIF('3 D P'!$E:$E,'Fresh VIN PPC'!$B:$B,'3 D P'!$L:$L) -> 115 | N16: =IFERROR(VLOOKUP(A16,'Daywise Dispatch'!$A:$B,2,FALSE),0) -> 1282 | O16: =SUMIF('Consumption MTD'!$B:$B,$B$4:$B$20,'Consumption MTD'!$C:$C) -> 1326 | P16: =SUMIF('BIW Lifting A Shift'!$B:$B,$B$4:$B$18,'BIW Lifting A Shift'!$C:$C) -> 0 | Q16: =SUMIF('BIW Lifting B Shift'!$B:$B,$B$4:$B$18,'BIW Lifting B Shift'!$C:$C) -> 0 | R16: =J16-U16 -> 8 | S16: =J16-P16-U16 -> 8 | T16: =S16-Q16 -> 8 | U16: =SUMIF(FLOAT!$D:$D,$B$4:$B$18,FLOAT!$F:$F) -> 115 | V16: 194 | W16: 1 | X16: 68 | Y16: =SUMIF(FLOAT!$D:$D,$B$4:$B$18,FLOAT!$F:$F) -> 115 | Z16: =SUMIF(FLOAT!$D:$D,$B$4:$B$18,FLOAT!$G:$G) -> 24 | AA16: =SUMIF(FLOAT!$D:$D,$B$4:$B$18,FLOAT!$H:$H) -> 5 | AB16: =SUMIF(FLOAT!$D:$D,$B$4:$B$18,FLOAT!$I:$I) -> 14 | AC16: =SUMIF(FLOAT!$D:$D,$B$4:$B$18,FLOAT!$J:$J) -> 1 | AD16: =SUMIF(FLOAT!$D:$D,$B$4:$B$19,FLOAT!$K:$K) -> 5 | AE16: =SUMIF(FLOAT!$D:$D,$B$4:$B$20,FLOAT!$L:$L) -> 24 | AF16: =SUMIF(FLOAT!$D:$D,$B$4:$B$18,FLOAT!$M:$M) -> 73 | AG16: =SUMIF(FLOAT!$D:$D,$B$4:$B$19,FLOAT!$N:$N) -> 16 | AH16: =SUMIF(FLOAT!$D:$D,$B$4:$B$19,FLOAT!$O:$O) -> 26 | AI16: =SUMIF(FLOAT!$D:$D,$B$4:$B$719,FLOAT!$P:$P) -> 0 | AJ16: =SUM(Z16:AE16)+SUM(AG16:AI16) -> 115
D17: 0 | E17: 0 | F17: 0 | G17: =N17 -> 0 | H17: =O17 -> 0 | I17: =E17-H17 -> 0 | J17: =F17+G17-H17 -> 0 | K17: =SUMIF('3 D P'!$E:$E,'Fresh VIN PPC'!$B:$B,'3 D P'!$J:$J) -> 0 | L17: =SUMIF('3 D P'!$E:$E,'Fresh VIN PPC'!$B:$B,'3 D P'!$K:$K) -> 0 | M17: =SUMIF('3 D P'!$E:$E,'Fresh VIN PPC'!$B:$B,'3 D P'!$L:$L) -> 0 | N17: =IFERROR(VLOOKUP(A17,'Daywise Dispatch'!$A:$B,2,FALSE),0) -> 0 | O17: =SUMIF('Consumption MTD'!$B:$B,$B$4:$B$20,'Consumption MTD'!$C:$C) -> 0 | P17: =SUMIF('BIW Lifting A Shift'!$B:$B,$B$4:$B$18,'BIW Lifting A Shift'!$C:$C) -> 0 | Q17: =SUMIF('BIW Lifting B Shift'!$B:$B,$B$4:$B$18,'BIW Lifting B Shift'!$C:$C) -> 0 | R17: =J17-U17 -> 0 | S17: =J17-P17-U17 -> 0 | T17: =S17-Q17 -> 0 | U17: =SUMIF(FLOAT!$D:$D,$B$4:$B$18,FLOAT!$F:$F) -> 0 | Y17: =SUMIF(FLOAT!$D:$D,$B$4:$B$18,FLOAT!$F:$F) -> 0 | Z17: =SUMIF(FLOAT!$D:$D,$B$4:$B$18,FLOAT!$G:$G) -> 0 | AA17: =SUMIF(FLOAT!$D:$D,$B$4:$B$18,FLOAT!$H:$H) -> 0 | AB17: =SUMIF(FLOAT!$D:$D,$B$4:$B$18,FLOAT!$I:$I) -> 0 | AC17: =SUMIF(FLOAT!$D:$D,$B$4:$B$18,FLOAT!$J:$J) -> 0 | AD17: =SUMIF(FLOAT!$D:$D,$B$4:$B$19,FLOAT!$K:$K) -> 0 | AE17: =SUMIF(FLOAT!$D:$D,$B$4:$B$20,FLOAT!$L:$L) -> 0 | AF17: =SUMIF(FLOAT!$D:$D,$B$4:$B$18,FLOAT!$M:$M) -> 0 | AG17: =SUMIF(FLOAT!$D:$D,$B$4:$B$19,FLOAT!$N:$N) -> 0 | AH17: =SUMIF(FLOAT!$D:$D,$B$4:$B$19,FLOAT!$O:$O) -> 0 | AI17: =SUMIF(FLOAT!$D:$D,$B$4:$B$719,FLOAT!$P:$P) -> 0 | AJ17: =SUM(Z17:AE17)+SUM(AG17:AI17) -> 0
D18: 0 | F18: 0 | G18: =N18 -> 0 | H18: =O18 -> 0 | I18: =E18-H18 -> 0 | J18: =F18+G18-H18 -> 0 | K18: =SUMIF('3 D P'!$E:$E,'Fresh VIN PPC'!$B:$B,'3 D P'!$J:$J) -> 0 | L18: =SUMIF('3 D P'!$E:$E,'Fresh VIN PPC'!$B:$B,'3 D P'!$K:$K) -> 0 | M18: =SUMIF('3 D P'!$E:$E,'Fresh VIN PPC'!$B:$B,'3 D P'!$L:$L) -> 0 | N18: =IFERROR(VLOOKUP(A18,'Daywise Dispatch'!$A:$B,2,FALSE),0) -> 0 | O18: =SUMIF('Consumption MTD'!$B:$B,$B$4:$B$20,'Consumption MTD'!$C:$C) -> 0 | P18: =SUMIF('BIW Lifting A Shift'!$B:$B,$B$4:$B$18,'BIW Lifting A Shift'!$C:$C) -> 0 | Q18: =SUMIF('BIW Lifting B Shift'!$B:$B,$B$4:$B$18,'BIW Lifting B Shift'!$C:$C) -> 0 | R18: =J18-U18 -> 0 | S18: =J18-P18-U18 -> 0 | T18: =S18-Q18 -> 0 | U18: =SUMIF(FLOAT!$D:$D,$B$4:$B$18,FLOAT!$F:$F) -> 0 | Y18: =SUMIF(FLOAT!$D:$D,$B$4:$B$18,FLOAT!$F:$F) -> 0 | Z18: =SUMIF(FLOAT!$D:$D,$B$4:$B$18,FLOAT!$G:$G) -> 0 | AA18: =SUMIF(FLOAT!$D:$D,$B$4:$B$18,FLOAT!$H:$H) -> 0 | AB18: =SUMIF(FLOAT!$D:$D,$B$4:$B$18,FLOAT!$I:$I) -> 0 | AC18: =SUMIF(FLOAT!$D:$D,$B$4:$B$18,FLOAT!$J:$J) -> 0 | AD18: =SUMIF(FLOAT!$D:$D,$B$4:$B$19,FLOAT!$K:$K) -> 0 | AE18: =SUMIF(FLOAT!$D:$D,$B$4:$B$20,FLOAT!$L:$L) -> 0 | AF18: =SUMIF(FLOAT!$D:$D,$B$4:$B$18,FLOAT!$M:$M) -> 0 | AG18: =SUMIF(FLOAT!$D:$D,$B$4:$B$19,FLOAT!$N:$N) -> 0 | AH18: =SUMIF(FLOAT!$D:$D,$B$4:$B$19,FLOAT!$O:$O) -> 0 | AI18: =SUMIF(FLOAT!$D:$D,$B$4:$B$719,FLOAT!$P:$P) -> 0 | AJ18: =SUM(Z18:AE18)+SUM(AG18:AI18) -> 0
D19: =SUM(D11:D18) -> 4111 | E19: =SUM(E11:E18) -> 4111 | F19: =SUM(F11:F18) -> 351 | G19: =SUM(G11:G18) -> 2135 | H19: =SUM(H11:H18) -> 2048 | I19: =SUM(I11:I18) -> 2063 | J19: =SUM(J11:J18) -> 438 | K19: =SUM(K11:K18) -> 262 | ... Q19: =SUM(Q11:Q18) -> 0 | U19: =SUM(U11:U18) -> 181 | V19: =SUM(V11:V18) -> 235 | Y19: =SUM(Y4:Y18) -> 181 | Z19: =SUM(Z4:Z18) -> 30 | AA19: =SUM(AA4:AA18) -> 9 | AB19: =SUM(AB4:AB18) -> 22 | AC19: =SUM(AC4:AC18) -> 1 | AD19: =SUM(AD4:AD18) -> 11 | AE19: =SUM(AE4:AE18) -> 36 | AF19: =SUM(AF4:AF18) -> 109 | ... AI19: =SUM(AI4:AI18) -> 0 | AJ19: =SUM(AJ11+AJ7+AJ12+AJ13+AJ14+AJ15+AJ16+AJ17+AJ18) -> 181

Sheet Cockpit sheet
D1: =D7+D16 -> 3651 | J1: =SUM(J7+J16) -> 442 | P1: =SUM(P7+P16) -> 0 | Q1: =SUM(Q7+Q16) -> 0 | U1: =SUM(U7+U16) -> 181
A2: Cockpit WH Number | B2: Short VC No | C2: Model | D2: PLAN | E2: W/H Requirement | F2: Month O/P | G2: Inwards | H2: Consumption | I2: Balance Production | J2: Today's O/P | K2: =TODAY() -> 46221 | L2: =TODAY()+1 -> 46222 | M2: =TODAY() -> 46221 | N2: Cumulative Dispatch | O2: Consumption | P2: A SHIFT BIW LIFTING | Q2: B SHIFT BIW LIFTING | R2: Float Coverage at 6:30am | S2: Float Coverage at 3 pm | T2: Float Coverage at 11:30 pm | U2: Paint float 06:30am | X2: Taco Stock 31.12.2025 | Y2: Safety Stock | Z2: TOTAL FLOAT | AA2: PBS FLOAT | AB2: PBS TO POLISHING | AC2: POLISHING TO TOPCOAT | AD2: TOPCOAT TO WETSANDING ROOFBLACK | AE2: TOPCOAT TO WETSANDING FRESH | AF2: WETSANDING TO SEALANT | AG2: TOTAL UPTO SEALANT | AH2: PT ENTRY TO SEALENT | AI2: BIW LIFTING TO PT | AJ2: PT BYPASS | AK2: Total
A3: 546854600231 | B3: 54680224A | C3: Persona 3 - Base VC + Everything Pack | D3: 0 | E3: =SUM(D3:D6) -> 0 | F3: 8 | G3: =N3 -> 0 | H3: =SUM(O3:O6) -> 0 | J3: =F3+G3-H3 -> 8 | K3: =SUMIF('3 D P'!$E:$E,'Cockpit sheet'!$B:$B,'3 D P'!$J:$J) -> 0 | L3: =SUMIF('3 D P'!$E:$E,'Cockpit sheet'!$B:$B,'3 D P'!$K:$K) -> 0 | M3: =SUMIF('3 D P'!$E:$E,'Cockpit sheet'!$B:$B,'3 D P'!$L:$L) -> 0 | N3: =IFERROR(VLOOKUP(A3,'Daywise Dispatch'!$A:$B,2,FALSE),0) -> 0 | O3: =SUMIF('Consumption MTD'!$B:$B,$B$3:$B$6,'Consumption MTD'!$C:$C) -> 0 | P3: =SUMIF('BIW Lifting A Shift'!$B:$B,$B$3:$B$6,'BIW Lifting A Shift'!$C:$C) -> 0 | Q3: =SUMIF('BIW Lifting B Shift'!$B:$B,$B$3:$B$6,'BIW Lifting B Shift'!$C:$C) -> 0 | R3: =J3-U3-U5-U6-U4 -> 8 | S3: =J3-P3-P5-P6-U3-U5-U6 -> 8 | T3: =S3-Q3-Q5-Q6 -> 8 | U3: =SUMIF(FLOAT!$D:$D,$B$3:$B$6,FLOAT!$F:$F) -> 0 | Z3: =SUMIF(FLOAT!$D:$D,$B$3:$B$6,FLOAT!$F:$F) -> 0 | AA3: =SUMIF(FLOAT!$D:$D,$B$3:$B$6,FLOAT!$G:$G) -> 0 | AB3: =SUMIF(FLOAT!$D:$D,$B$3:$B$6,FLOAT!$H:$H) -> 0 | AC3: =SUMIF(FLOAT!$D:$D,$B$3:$B$6,FLOAT!$I:$I) -> 0 | AD3: =SUMIF(FLOAT!$D:$D,$B$3:$B$6,FLOAT!$J:$J) -> 0 | AE3: =SUMIF(FLOAT!$D:$D,$B$3:$B$6,FLOAT!$K:$K) -> 0 | AF3: =SUMIF(FLOAT!$D:$D,$B$3:$B$6,FLOAT!$L:$L) -> 0 | AG3: =SUMIF(FLOAT!$D:$D,$B$3:$B$6,FLOAT!$M:$M) -> 0 | AH3: =SUMIF(FLOAT!$D:$D,$B$3:$B$6,FLOAT!$N:$N) -> 0 | AI3: =SUMIF(FLOAT!$D:$D,$B$3:$B$6,FLOAT!$O:$O) -> 0 | AJ3: =SUMIF(FLOAT!$D:$D,$B$3:$B$6,FLOAT!$P:$P) -> 0 | AK3: =SUM(AA3:AF3)+SUM(AH3:AJ3) -> 0
B4: 54683524A | C4: PUNCH.EV EMP + S LR ACFC | D4: 0 | K4: =SUMIF('3 D P'!$E:$E,'Cockpit sheet'!$B:$B,'3 D P'!$J:$J) -> 0 | L4: =SUMIF('3 D P'!$E:$E,'Cockpit sheet'!$B:$B,'3 D P'!$K:$K) -> 0 | M4: =SUMIF('3 D P'!$E:$E,'Cockpit sheet'!$B:$B,'3 D P'!$L:$L) -> 0 | N4: =IFERROR(VLOOKUP(A4,'Daywise Dispatch'!$A:$B,2,FALSE),0) -> 0 | O4: =SUMIF('Consumption MTD'!$B:$B,$B$3:$B$6,'Consumption MTD'!$C:$C) -> 0 | P4: =SUMIF('BIW Lifting A Shift'!$B:$B,$B$3:$B$6,'BIW Lifting A Shift'!$C:$C) -> 0 | Q4: =SUMIF('BIW Lifting B Shift'!$B:$B,$B$3:$B$6,'BIW Lifting B Shift'!$C:$C) -> 0 | U4: =SUMIF(FLOAT!$D:$D,$B$3:$B$6,FLOAT!$F:$F) -> 0 | AA4: =SUMIF(FLOAT!$D:$D,$B$3:$B$6,FLOAT!$G:$G) -> 0 | AB4: =SUMIF(FLOAT!$D:$D,$B$3:$B$6,FLOAT!$H:$H) -> 0 | AC4: =SUMIF(FLOAT!$D:$D,$B$3:$B$6,FLOAT!$I:$I) -> 0 | AD4: =SUMIF(FLOAT!$D:$D,$B$3:$B$6,FLOAT!$J:$J) -> 0 | AE4: =SUMIF(FLOAT!$D:$D,$B$3:$B$6,FLOAT!$K:$K) -> 0 | AF4: =SUMIF(FLOAT!$D:$D,$B$3:$B$6,FLOAT!$L:$L) -> 0 | AG4: =SUMIF(FLOAT!$D:$D,$B$3:$B$6,FLOAT!$M:$M) -> 0 | AH4: =SUMIF(FLOAT!$D:$D,$B$3:$B$6,FLOAT!$N:$N) -> 0 | AI4: =SUMIF(FLOAT!$D:$D,$B$3:$B$6,FLOAT!$O:$O) -> 0 | AJ4: =SUMIF(FLOAT!$D:$D,$B$3:$B$6,FLOAT!$P:$P) -> 0 | AK4: =SUM(AA4:AF4)+SUM(AH4:AJ4) -> 0
B5: 54681824A | C5: Persona 3 - Base VC + Everything Pack | D5: 0 | K5: =SUMIF('3 D P'!$E:$E,'Cockpit sheet'!$B:$B,'3 D P'!$J:$J) -> 0 | L5: =SUMIF('3 D P'!$E:$E,'Cockpit sheet'!$B:$B,'3 D P'!$K:$K) -> 0 | M5: =SUMIF('3 D P'!$E:$E,'Cockpit sheet'!$B:$B,'3 D P'!$L:$L) -> 0 | N5: =IFERROR(VLOOKUP(A5,'Daywise Dispatch'!$A:$B,2,FALSE),0) -> 0 | O5: =SUMIF('Consumption MTD'!$B:$B,$B$3:$B$6,'Consumption MTD'!$C:$C) -> 0 | P5: =SUMIF('BIW Lifting A Shift'!$B:$B,$B$3:$B$6,'BIW Lifting A Shift'!$C:$C) -> 0 | Q5: =SUMIF('BIW Lifting B Shift'!$B:$B,$B$3:$B$6,'BIW Lifting B Shift'!$C:$C) -> 0 | U5: =SUMIF(FLOAT!$D:$D,$B$3:$B$6,FLOAT!$F:$F) -> 0 | Z5: =SUMIF(FLOAT!$D:$D,$B$3:$B$6,FLOAT!$F:$F) -> 0 | AA5: =SUMIF(FLOAT!$D:$D,$B$3:$B$6,FLOAT!$G:$G) -> 0 | AB5: =SUMIF(FLOAT!$D:$D,$B$3:$B$6,FLOAT!$H:$H) -> 0 | AC5: =SUMIF(FLOAT!$D:$D,$B$3:$B$6,FLOAT!$I:$I) -> 0 | AD5: =SUMIF(FLOAT!$D:$D,$B$3:$B$6,FLOAT!$J:$J) -> 0 | AE5: =SUMIF(FLOAT!$D:$D,$B$3:$B$6,FLOAT!$K:$K) -> 0 | AF5: =SUMIF(FLOAT!$D:$D,$B$3:$B$6,FLOAT!$L:$L) -> 0 | AG5: =SUMIF(FLOAT!$D:$D,$B$3:$B$6,FLOAT!$M:$M) -> 0 | AH5: =SUMIF(FLOAT!$D:$D,$B$3:$B$6,FLOAT!$N:$N) -> 0 | AI5: =SUMIF(FLOAT!$D:$D,$B$3:$B$6,FLOAT!$O:$O) -> 0 | AJ5: =SUMIF(FLOAT!$D:$D,$B$3:$B$6,FLOAT!$P:$P) -> 0 | AK5: =SUM(AA5:AF5)+SUM(AH5:AJ5) -> 0
B6: 54683124A | C6: PUNCH.EV EMP + S LR | D6: 0 | K6: =SUMIF('3 D P'!$E:$E,'Cockpit sheet'!$B:$B,'3 D P'!$J:$J) -> 0 | L6: =SUMIF('3 D P'!$E:$E,'Cockpit sheet'!$B:$B,'3 D P'!$K:$K) -> 0 | M6: =SUMIF('3 D P'!$E:$E,'Cockpit sheet'!$B:$B,'3 D P'!$L:$L) -> 0 | N6: =IFERROR(VLOOKUP(A6,'Daywise Dispatch'!$A:$B,2,FALSE),0) -> 0 | O6: =SUMIF('Consumption MTD'!$B:$B,$B$3:$B$6,'Consumption MTD'!$C:$C) -> 0 | P6: =SUMIF('BIW Lifting A Shift'!$B:$B,$B$3:$B$6,'BIW Lifting A Shift'!$C:$C) -> 0 | Q6: =SUMIF('BIW Lifting B Shift'!$B:$B,$B$3:$B$6,'BIW Lifting B Shift'!$C:$C) -> 0 | U6: =SUMIF(FLOAT!$D:$D,$B$3:$B$6,FLOAT!$F:$F) -> 0
D7: =SUM(D3:D6) -> 0 | E7: =SUM(E3:E6) -> 0 | F7: =SUM(F3:F6) -> 8 | G7: =SUM(G3:G6) -> 0 | H7: =SUM(H3:H6) -> 0 | I7: =SUM(I3:I6) -> 0 | J7: =SUM(J3:J6) -> 8 | K7: =SUM(K3:K6) -> 0 | ... Q7: =SUM(Q3:Q6) -> 0 | U7: =SUM(U3:U6) -> 0 | Z7: =SUM(Z3:Z10) -> 0 | AA7: =SUM(AA3:AA10) -> 0 | AB7: =SUM(AB3:AB10) -> 0 | AC7: =SUM(AC3:AC10) -> 0 | AD7: =SUM(AD3:AD10) -> 0 | AE7: =SUM(AE3:AE10) -> 0 | AF7: =SUM(AF3:AF10) -> 0 | AG7: =SUM(AG3:AG10) -> 0 | ... AK7: =SUM(AK3:AK10) -> 0
A9: Cockpit WH Number | B9: Short VC No | C9: Model | D9: PLAN | E9: W/H Requirement | F9: Month O/P | G9: Inwards | H9: Consumption | I9: Balance Production | J9: Today's O/P | K9: =TODAY() -> 46221 | L9: =TODAY()+1 -> 46222 | M9: =TODAY()+2 -> 46223 | N9: Cumulative Dispatch | O9: Consumption | P9: A SHIFT BIW LIFTING | Q9: B SHIFT BIW LIFTING | R9: Float Coverage at 6:30am | S9: Float Coverage at 3 pm | T9: Float Coverage at 11:30 pm | U9: Paint float 06:30am | Z9: TOTAL FLOAT | AA9: PBS FLOAT | AB9: PBS TO POLISHING | AC9: POLISHING TO TOPCOAT | AD9: TOPCOAT TO WETSANDING ROOFBLACK | AE9: TOPCOAT TO WETSANDING FRESH | AF9: WETSANDING TO SEALANT | AG9: TOTAL UPTO SEALANT | AH9: PT ENTRY TO SEALENT | AI9: BIW LIFTING TO PT | AJ9: PT BYPASS | AK9: Total | AM9: Safty
A10: 546854650101 | B10: 54684124A | C10: PUNCH.EV SMT 30 | D10: 0 | E10: =D10 -> 0 | F10: 5 | G10: =N10 -> 0 | H10: =O10 -> 0 | I10: =E10-H10 -> 0 | J10: =F10+G10-H10 -> 5 | K10: =SUMIF('3 D P'!$E:$E,'Fresh VIN PPC'!$B:$B,'3 D P'!$J:$J) -> 0 | L10: =SUMIF('3 D P'!$E:$E,'Fresh VIN PPC'!$B:$B,'3 D P'!$K:$K) -> 0 | M10: =SUMIF('3 D P'!$E:$E,'Fresh VIN PPC'!$B:$B,'3 D P'!$L:$L) -> 0 | N10: =IFERROR(VLOOKUP(A10,'Daywise Dispatch'!$A:$B,2,FALSE),0) -> 0 | O10: =SUMIF('Consumption MTD'!$B:$B,$B$3:$B$17,'Consumption MTD'!$C:$C) -> 0 | P10: =SUMIF('BIW Lifting A Shift'!$B:$B,$B$3:$B$15,'BIW Lifting A Shift'!$C:$C) -> 0 | Q10: =SUMIF('BIW Lifting B Shift'!$B:$B,$B$3:$B$15,'BIW Lifting B Shift'!$C:$C) -> 0 | R10: =J10-U10 -> 5 | S10: =J10-P10-U10 -> 5 | T10: =S10-Q10 -> 5 | U10: =SUMIF(FLOAT!$D:$D,$B$3:$B$15,FLOAT!$F:$F) -> 0 | V10: 5 | Y10: 1 | Z10: =SUMIF(FLOAT!$D:$D,$B$3:$B$15,FLOAT!$F:$F) -> 0 | AA10: =SUMIF(FLOAT!$D:$D,$B$3:$B$15,FLOAT!$G:$G) -> 0 | AB10: =SUMIF(FLOAT!$D:$D,$B$3:$B$15,FLOAT!$H:$H) -> 0 | AC10: =SUMIF(FLOAT!$D:$D,$B$3:$B$15,FLOAT!$I:$I) -> 0 | AD10: =SUMIF(FLOAT!$D:$D,$B$3:$B$15,FLOAT!$J:$J) -> 0 | AE10: =SUMIF(FLOAT!$D:$D,$B$3:$B$15,FLOAT!$K:$K) -> 0 | AF10: =SUMIF(FLOAT!$D:$D,$B$3:$B$15,FLOAT!$L:$L) -> 0 | AG10: =SUMIF(FLOAT!$D:$D,$B$3:$B$6,FLOAT!$M:$M) -> 0 | AH10: =SUMIF(FLOAT!$D:$D,$B$3:$B$15,FLOAT!$N:$N) -> 0 | AI10: =SUMIF(FLOAT!$D:$D,$B$3:$B$15,FLOAT!$O:$O) -> 0 | AJ10: =SUMIF(FLOAT!$D:$D,$B$3:$B$15,FLOAT!$P:$P) -> 0 | AK10: =SUM(AA10:AF10)+SUM(AH10:AJ10) -> 0 | AM10: 1 | AN10: 5
A11: 546854650102 | B11: 54684224A | C11: PUNCH.EV SMT+ 30 | D11: 0 | E11: =D11 -> 0 | F11: 6 | G11: =N11 -> 0 | H11: =O11 -> 0 | I11: =E11-H11 -> 0 | J11: =F11+G11-H11 -> 6 | K11: =SUMIF('3 D P'!$E:$E,'Fresh VIN PPC'!$B:$B,'3 D P'!$J:$J) -> 0 | L11: =SUMIF('3 D P'!$E:$E,'Fresh VIN PPC'!$B:$B,'3 D P'!$K:$K) -> 0 | M11: =SUMIF('3 D P'!$E:$E,'Fresh VIN PPC'!$B:$B,'3 D P'!$L:$L) -> 0 | N11: =IFERROR(VLOOKUP(A11,'Daywise Dispatch'!$A:$B,2,FALSE),0) -> 0 | O11: =SUMIF('Consumption MTD'!$B:$B,$B$3:$B$17,'Consumption MTD'!$C:$C) -> 0 | P11: =SUMIF('BIW Lifting A Shift'!$B:$B,$B$3:$B$15,'BIW Lifting A Shift'!$C:$C) -> 0 | Q11: =SUMIF('BIW Lifting B Shift'!$B:$B,$B$3:$B$15,'BIW Lifting B Shift'!$C:$C) -> 0 | R11: =J11-U11 -> 6 | S11: =J11-P11-U11 -> 6 | T11: =S11-Q11 -> 6 | U11: =SUMIF(FLOAT!$D:$D,$B$3:$B$15,FLOAT!$F:$F) -> 0 | V11: 6 | Y11: 1 | Z11: =SUMIF(FLOAT!$D:$D,$B$3:$B$6,FLOAT!$F:$F) -> 0 | AA11: =SUMIF(FLOAT!$D:$D,$B$3:$B$15,FLOAT!$G:$G) -> 0 | AB11: =SUMIF(FLOAT!$D:$D,$B$3:$B$15,FLOAT!$H:$H) -> 0 | AC11: =SUMIF(FLOAT!$D:$D,$B$3:$B$15,FLOAT!$I:$I) -> 0 | AD11: =SUMIF(FLOAT!$D:$D,$B$3:$B$15,FLOAT!$J:$J) -> 0 | AE11: =SUMIF(FLOAT!$D:$D,$B$3:$B$15,FLOAT!$K:$K) -> 0 | AF11: =SUMIF(FLOAT!$D:$D,$B$3:$B$15,FLOAT!$L:$L) -> 0 | AG11: =SUMIF(FLOAT!$D:$D,$B$3:$B$6,FLOAT!$M:$M) -> 0 | AH11: =SUMIF(FLOAT!$D:$D,$B$3:$B$15,FLOAT!$N:$N) -> 0 | AI11: =SUMIF(FLOAT!$D:$D,$B$3:$B$15,FLOAT!$O:$O) -> 0 | AJ11: =SUMIF(FLOAT!$D:$D,$B$3:$B$15,FLOAT!$P:$P) -> 0 | AK11: =SUM(AA11:AF11)+SUM(AH11:AJ11) -> 0 | AM11: 1 | AN11: 6
A12: 546854650110 | B12: 54686224A | C12: PUNCH.EV SMT+ 40 | D12: 294 | E12: =D12 -> 294 | F12: =19-5 -> 14 | G12: =N12 -> 385 | H12: =O12 -> 300 | I12: =E12-H12 -> -6 | J12: =F12+G12-H12 -> 99 | K12: =SUMIF('3 D P'!$E:$E,'Fresh VIN PPC'!$B:$B,'3 D P'!$J:$J) -> 0 | L12: =SUMIF('3 D P'!$E:$E,'Fresh VIN PPC'!$B:$B,'3 D P'!$K:$K) -> 0 | M12: =SUMIF('3 D P'!$E:$E,'Fresh VIN PPC'!$B:$B,'3 D P'!$L:$L) -> 0 | N12: =IFERROR(VLOOKUP(A12,'Daywise Dispatch'!$A:$B,2,FALSE),0) -> 385 | O12: =SUMIF('Consumption MTD'!$B:$B,$B$3:$B$17,'Consumption MTD'!$C:$C) -> 300 | P12: =SUMIF('BIW Lifting A Shift'!$B:$B,$B$3:$B$15,'BIW Lifting A Shift'!$C:$C) -> 0 | Q12: =SUMIF('BIW Lifting B Shift'!$B:$B,$B$3:$B$15,'BIW Lifting B Shift'!$C:$C) -> 0 | R12: =J12-U12 -> 89 | S12: =J12-P12-U12 -> 89 | T12: =S12-Q12 -> 89 | U12: =SUMIF(FLOAT!$D:$D,$B$3:$B$15,FLOAT!$F:$F) -> 10 | V12: 17 | Y12: 1 | Z12: =SUMIF(FLOAT!$D:$D,$B$3:$B$6,FLOAT!$F:$F) -> 0 | AA12: =SUMIF(FLOAT!$D:$D,$B$3:$B$15,FLOAT!$G:$G) -> 3 | AB12: =SUMIF(FLOAT!$D:$D,$B$3:$B$15,FLOAT!$H:$H) -> 1 | AC12: =SUMIF(FLOAT!$D:$D,$B$3:$B$15,FLOAT!$I:$I) -> 0 | AD12: =SUMIF(FLOAT!$D:$D,$B$3:$B$15,FLOAT!$J:$J) -> 0 | AE12: =SUMIF(FLOAT!$D:$D,$B$3:$B$15,FLOAT!$K:$K) -> 1 | AF12: =SUMIF(FLOAT!$D:$D,$B$3:$B$15,FLOAT!$L:$L) -> 1 | AG12: =SUMIF(FLOAT!$D:$D,$B$3:$B$6,FLOAT!$M:$M) -> 0 | AH12: =SUMIF(FLOAT!$D:$D,$B$3:$B$15,FLOAT!$N:$N) -> 0 | AI12: =SUMIF(FLOAT!$D:$D,$B$3:$B$15,FLOAT!$O:$O) -> 4 | AJ12: =SUMIF(FLOAT!$D:$D,$B$3:$B$15,FLOAT!$P:$P) -> 0 | AK12: =SUM(AA12:AF12)+SUM(AH12:AJ12) -> 10 | AM12: 4 | AN12: 19
A13: 546854650111 | B13: 54686324A | C13: PUNCH.EV ADV 40 | D13: 830 | E13: =D13 -> 830 | F13: =122-5 -> 117 | G13: =N13 -> 369 | H13: =O13 -> 290 | I13: =E13-H13 -> 540 | J13: =F13+G13-H13 -> 196 | K13: =SUMIF('3 D P'!$E:$E,'Fresh VIN PPC'!$B:$B,'3 D P'!$J:$J) -> 3 | L13: =SUMIF('3 D P'!$E:$E,'Fresh VIN PPC'!$B:$B,'3 D P'!$K:$K) -> 51 | M13: =SUMIF('3 D P'!$E:$E,'Fresh VIN PPC'!$B:$B,'3 D P'!$L:$L) -> 49 | N13: =IFERROR(VLOOKUP(A13,'Daywise Dispatch'!$A:$B,2,FALSE),0) -> 369 | O13: =SUMIF('Consumption MTD'!$B:$B,$B$3:$B$17,'Consumption MTD'!$C:$C) -> 290 | P13: =SUMIF('BIW Lifting A Shift'!$B:$B,$B$3:$B$15,'BIW Lifting A Shift'!$C:$C) -> 0 | Q13: =SUMIF('BIW Lifting B Shift'!$B:$B,$B$3:$B$15,'BIW Lifting B Shift'!$C:$C) -> 0 | R13: =J13-U13 -> 144 | S13: =J13-P13-U13 -> 144 | T13: =S13-Q13 -> 144 | U13: =SUMIF(FLOAT!$D:$D,$B$3:$B$15,FLOAT!$F:$F) -> 52 | V13: 34 | Y13: 1 | Z13: =SUMIF(FLOAT!$D:$D,$B$3:$B$6,FLOAT!$F:$F) -> 0 | AA13: =SUMIF(FLOAT!$D:$D,$B$3:$B$15,FLOAT!$G:$G) -> 2 | AB13: =SUMIF(FLOAT!$D:$D,$B$3:$B$15,FLOAT!$H:$H) -> 2 | AC13: =SUMIF(FLOAT!$D:$D,$B$3:$B$15,FLOAT!$I:$I) -> 8 | AD13: =SUMIF(FLOAT!$D:$D,$B$3:$B$15,FLOAT!$J:$J) -> 0 | AE13: =SUMIF(FLOAT!$D:$D,$B$3:$B$15,FLOAT!$K:$K) -> 5 | AF13: =SUMIF(FLOAT!$D:$D,$B$3:$B$15,FLOAT!$L:$L) -> 11 | AG13: =SUMIF(FLOAT!$D:$D,$B$3:$B$6,FLOAT!$M:$M) -> 0 | AH13: =SUMIF(FLOAT!$D:$D,$B$3:$B$15,FLOAT!$N:$N) -> 13 | AI13: =SUMIF(FLOAT!$D:$D,$B$3:$B$15,FLOAT!$O:$O) -> 11 | AJ13: =SUMIF(FLOAT!$D:$D,$B$3:$B$15,FLOAT!$P:$P) -> 0 | AK13: =SUM(AA13:AF13)+SUM(AH13:AJ13) -> 52 | AM13: 3 | AN13: 122
A14: 546854650115 | B14: 54686724A | C14: PUNCH.EV EMP 40 | D14: 230 | E14: =D14 -> 230 | F14: 38 | G14: =N14 -> 99 | H14: =O14 -> 132 | I14: =E14-H14 -> 98 | J14: =F14+G14-H14 -> 5 | K14: =SUMIF('3 D P'!$E:$E,'Fresh VIN PPC'!$B:$B,'3 D P'!$J:$J) -> 174 | L14: =SUMIF('3 D P'!$E:$E,'Fresh VIN PPC'!$B:$B,'3 D P'!$K:$K) -> 158 | M14: =SUMIF('3 D P'!$E:$E,'Fresh VIN PPC'!$B:$B,'3 D P'!$L:$L) -> 98 | N14: =IFERROR(VLOOKUP(A14,'Daywise Dispatch'!$A:$B,2,FALSE),0) -> 99 | O14: =SUMIF('Consumption MTD'!$B:$B,$B$3:$B$17,'Consumption MTD'!$C:$C) -> 132 | P14: =SUMIF('BIW Lifting A Shift'!$B:$B,$B$3:$B$15,'BIW Lifting A Shift'!$C:$C) -> 0 | Q14: =SUMIF('BIW Lifting B Shift'!$B:$B,$B$3:$B$15,'BIW Lifting B Shift'!$C:$C) -> 0 | R14: =J14-U14 -> 1 | S14: =J14-P14-U14 -> 1 | T14: =S14-Q14 -> 1 | U14: =SUMIF(FLOAT!$D:$D,$B$3:$B$15,FLOAT!$F:$F) -> 4 | V14: 53 | Y14: 1 | Z14: =SUMIF(FLOAT!$D:$D,$B$3:$B$6,FLOAT!$F:$F) -> 0 | AA14: =SUMIF(FLOAT!$D:$D,$B$3:$B$15,FLOAT!$G:$G) -> 1 | AB14: =SUMIF(FLOAT!$D:$D,$B$3:$B$15,FLOAT!$H:$H) -> 1 | AC14: =SUMIF(FLOAT!$D:$D,$B$3:$B$15,FLOAT!$I:$I) -> 0 | AD14: =SUMIF(FLOAT!$D:$D,$B$3:$B$15,FLOAT!$J:$J) -> 0 | AE14: =SUMIF(FLOAT!$D:$D,$B$3:$B$15,FLOAT!$K:$K) -> 0 | AF14: =SUMIF(FLOAT!$D:$D,$B$3:$B$15,FLOAT!$L:$L) -> 0 | AG14: =SUMIF(FLOAT!$D:$D,$B$3:$B$6,FLOAT!$M:$M) -> 0 | AH14: =SUMIF(FLOAT!$D:$D,$B$3:$B$15,FLOAT!$N:$N) -> 1 | AI14: =SUMIF(FLOAT!$D:$D,$B$3:$B$15,FLOAT!$O:$O) -> 1 | AJ14: =SUMIF(FLOAT!$D:$D,$B$3:$B$15,FLOAT!$P:$P) -> 0 | AK14: =SUM(AA14:AF14)+SUM(AH14:AJ14) -> 4 | AM14: 3 | AN14: 38
A15: 546854650116 | B15: 54686824A | C15: PUNCH.EV EMP+ S 40 | D15: 2297 | E15: =D15 -> 2297 | F15: =167 -> 167 | G15: =N15 -> 1282 | H15: =O15 -> 1326 | I15: =E15-H15 -> 971 | J15: =F15+G15-H15 -> 123 | K15: =SUMIF('3 D P'!$E:$E,'Fresh VIN PPC'!$B:$B,'3 D P'!$J:$J) -> 7 | L15: =SUMIF('3 D P'!$E:$E,'Fresh VIN PPC'!$B:$B,'3 D P'!$K:$K) -> 19 | M15: =SUMIF('3 D P'!$E:$E,'Fresh VIN PPC'!$B:$B,'3 D P'!$L:$L) -> 3 | N15: =IFERROR(VLOOKUP(A15,'Daywise Dispatch'!$A:$B,2,FALSE),0) -> 1282 | O15: =SUMIF('Consumption MTD'!$B:$B,$B$3:$B$17,'Consumption MTD'!$C:$C) -> 1326 | P15: =SUMIF('BIW Lifting A Shift'!$B:$B,$B$3:$B$15,'BIW Lifting A Shift'!$C:$C) -> 0 | Q15: =SUMIF('BIW Lifting B Shift'!$B:$B,$B$3:$B$15,'BIW Lifting B Shift'!$C:$C) -> 0 | R15: =J15-U15 -> 8 | S15: =J15-P15-U15 -> 8 | T15: =S15-Q15 -> 8 | U15: =SUMIF(FLOAT!$D:$D,$B$3:$B$15,FLOAT!$F:$F) -> 115 | V15: 68 | Y15: 1 | Z15: =SUMIF(FLOAT!$D:$D,$B$3:$B$6,FLOAT!$F:$F) -> 0 | AA15: =SUMIF(FLOAT!$D:$D,$B$3:$B$15,FLOAT!$G:$G) -> 24 | AB15: =SUMIF(FLOAT!$D:$D,$B$3:$B$15,FLOAT!$H:$H) -> 5 | AC15: =SUMIF(FLOAT!$D:$D,$B$3:$B$15,FLOAT!$I:$I) -> 14 | AD15: =SUMIF(FLOAT!$D:$D,$B$3:$B$15,FLOAT!$J:$J) -> 1 | AE15: =SUMIF(FLOAT!$D:$D,$B$3:$B$15,FLOAT!$K:$K) -> 5 | AF15: =SUMIF(FLOAT!$D:$D,$B$3:$B$15,FLOAT!$L:$L) -> 24 | AG15: =SUMIF(FLOAT!$D:$D,$B$3:$B$6,FLOAT!$M:$M) -> 0 | AH15: =SUMIF(FLOAT!$D:$D,$B$3:$B$15,FLOAT!$N:$N) -> 16 | AI15: =SUMIF(FLOAT!$D:$D,$B$3:$B$15,FLOAT!$O:$O) -> 26 | AJ15: =SUMIF(FLOAT!$D:$D,$B$3:$B$15,FLOAT!$P:$P) -> 0 | AK15: =SUM(AA15:AF15)+SUM(AH15:AJ15) -> 115 | AM15: 6 | AN15: 167
D16: =SUM(D10:D15) -> 3651 | E16: =SUM(E10:E15) -> 3651 | F16: =SUM(F10:F15) -> 347 | G16: =SUM(G10:G15) -> 2135 | H16: =SUM(H10:H15) -> 2048 | I16: =SUM(I10:I15) -> 1603 | J16: =SUM(J10:J15) -> 434 | K16: =SUM(K10:K15) -> 184 | ... Q16: =SUM(Q10:Q15) -> 0 | U16: =SUM(U10:U15) -> 181 | V16: =SUM(V10:V15) -> 183 | AM16: =SUM(AM10:AM15) -> 18

Sheet Front
A1: Front WH Number | B1: Short VC No | C1: Model | D1: PLAN | E1: W/H Requirement | F1: Month O/P | G1: Inwards | H1: Consumption | I1: Balance Production | J1: Today's O/P | K1: =TODAY() -> 46221 | L1: =TODAY()+1 -> 46222 | M1: =TODAY()+2 -> 46223 | N1: Cumulative Dispatch | O1: Consumption | P1: A SHIFT BIW LIFTING | Q1: B SHIFT BIW LIFTING | R1: Float Coverage at 6:30am | S1: Float Coverage at 3 pm | T1: Float Coverage at 11:30 pm | U1: Paint float 06:30am | Z1: TOTAL FLOAT | AA1: PBS FLOAT | AB1: PBS TO POLISHING | AC1: POLISHING TO TOPCOAT | AD1: TOPCOAT TO WETSANDING ROOFBLACK | AE1: TOPCOAT TO WETSANDING FRESH | AF1: WETSANDING TO SEALANT | AG1: TOTAL UPTO SEALANT | AH1: PT ENTRY TO SEALENT | AI1: BIW LIFTING TO PT | AJ1: PT BYPASS | AK1: Total
A2: 546854620381 | B2: 54684124A | C2: PUNCH.EV SMT | D2: 0 | E2: 0 | F2: 5 | G2: =N2 -> 0 | H2: =O2 -> 0 | I2: =E2-H2 -> 0 | J2: =F2+G2-H2 -> 5 | K2: =SUMIF('3 D P'!$E:$E,Front!$B:$B,'3 D P'!J:J) -> 0 | L2: =SUMIF('3 D P'!$E:$E,Front!$B:$B,'3 D P'!K:K) -> 0 | M2: =SUMIF('3 D P'!$E:$E,Front!$B:$B,'3 D P'!L:L) -> 0 | N2: =IFERROR(VLOOKUP(A2,'Front Dispatch'!A:B,2,0),0) -> 0 | O2: =SUMIF('Consumption MTD'!$B:$B,$B$2:$B$17,'Consumption MTD'!$C:$C) -> 0 | P2: =SUMIF('BIW Lifting A Shift'!$B:$B,$B$2:$B$15,'BIW Lifting A Shift'!$C:$C) -> 0 | Q2: =SUMIF('BIW Lifting B Shift'!$B:$B,$B$2:$B$15,'BIW Lifting B Shift'!$C:$C) -> 0 | R2: =J2-U2 -> 5 | S2: =J2-P2-U2 -> 5 | T2: =S2-Q2 -> 5 | U2: =SUMIF(FLOAT!$D:$D,$B$2:$B$15,FLOAT!$F:$F) -> 0 | V2: 6 | Y2: 1 | Z2: =SUMIF(FLOAT!$D:$D,$B$2:$B$14,FLOAT!$F:$F) -> 0 | AA2: =SUMIF(FLOAT!$D:$D,$B$2:$B$13,FLOAT!$G:$G) -> 0 | AB2: =SUMIF(FLOAT!$D:$D,$B$2:$B$13,FLOAT!$H:$H) -> 0 | AC2: =SUMIF(FLOAT!$D:$D,$B$2:$B$13,FLOAT!$I:$I) -> 0 | AD2: =SUMIF(FLOAT!$D:$D,$B$2:$B$13,FLOAT!$J:$J) -> 0 | AE2: =SUMIF(FLOAT!$D:$D,$B$2:$B$13,FLOAT!$K:$K) -> 0 | AF2: =SUMIF(FLOAT!$D:$D,$B$2:$B$13,FLOAT!$L:$L) -> 0 | AG2: =SUMIF(FLOAT!$D:$D,$B$2:$B$6,FLOAT!$M:$M) -> 0 | AH2: =SUMIF(FLOAT!$D:$D,$B$2:$B$13,FLOAT!$N:$N) -> 0 | AI2: =SUMIF(FLOAT!$D:$D,$B$2:$B$13,FLOAT!$O:$O) -> 0 | AJ2: =SUMIF(FLOAT!$D:$D,$B$2:$B$13,FLOAT!$P:$P) -> 0 | AK2: =SUM(AA2:AF2)+SUM(AH2:AJ2) -> 0
A3: 546854620382 | B3: 54684224A | C3: PUNCH.EV SMT + | D3: 0 | E3: 0 | F3: 5 | G3: =N3 -> 0 | H3: =O3 -> 0 | I3: =E3-H3 -> 0 | J3: =F3+G3-H3 -> 5 | K3: =SUMIF('3 D P'!$E:$E,Front!$B:$B,'3 D P'!J:J) -> 0 | L3: =SUMIF('3 D P'!$E:$E,Front!$B:$B,'3 D P'!K:K) -> 0 | M3: =SUMIF('3 D P'!$E:$E,Front!$B:$B,'3 D P'!L:L) -> 0 | N3: =IFERROR(VLOOKUP(A3,'Front Dispatch'!A:B,2,0),0) -> 0 | O3: =SUMIF('Consumption MTD'!$B:$B,$B$2:$B$17,'Consumption MTD'!$C:$C) -> 0 | P3: =SUMIF('BIW Lifting A Shift'!$B:$B,$B$2:$B$15,'BIW Lifting A Shift'!$C:$C) -> 0 | Q3: =SUMIF('BIW Lifting B Shift'!$B:$B,$B$2:$B$15,'BIW Lifting B Shift'!$C:$C) -> 0 | R3: =J3-U3 -> 5 | S3: =J3-P3-U3 -> 5 | T3: =S3-Q3 -> 5 | U3: =SUMIF(FLOAT!$D:$D,$B$2:$B$15,FLOAT!$F:$F) -> 0 | V3: 6 | Y3: 1 | Z3: =SUMIF(FLOAT!$D:$D,$B$2:$B$14,FLOAT!$F:$F) -> 0 | AA3: =SUMIF(FLOAT!$D:$D,$B$2:$B$13,FLOAT!$G:$G) -> 0 | AB3: =SUMIF(FLOAT!$D:$D,$B$2:$B$13,FLOAT!$H:$H) -> 0 | AC3: =SUMIF(FLOAT!$D:$D,$B$2:$B$13,FLOAT!$I:$I) -> 0 | AD3: =SUMIF(FLOAT!$D:$D,$B$2:$B$13,FLOAT!$J:$J) -> 0 | AE3: =SUMIF(FLOAT!$D:$D,$B$2:$B$13,FLOAT!$K:$K) -> 0 | AF3: =SUMIF(FLOAT!$D:$D,$B$2:$B$13,FLOAT!$L:$L) -> 0 | AG3: =SUMIF(FLOAT!$D:$D,$B$2:$B$6,FLOAT!$M:$M) -> 0 | AH3: =SUMIF(FLOAT!$D:$D,$B$2:$B$13,FLOAT!$N:$N) -> 0 | AI3: =SUMIF(FLOAT!$D:$D,$B$2:$B$13,FLOAT!$O:$O) -> 0 | AJ3: =SUMIF(FLOAT!$D:$D,$B$2:$B$13,FLOAT!$P:$P) -> 0 | AK3: =SUM(AA3:AF3)+SUM(AH3:AJ3) -> 0
A4: 546854620355 | B4: 54686224A | C4: PUNCH.EV SMT + LR | D4: 750 | E4: 294 | F4: 44 | G4: =N4 -> 289 | H4: =O4 -> 300 | I4: =E4-H4 -> -6 | J4: =F4+G4-H4 -> 33 | K4: =SUMIF('3 D P'!$E:$E,Front!$B:$B,'3 D P'!J:J) -> 3 | L4: =SUMIF('3 D P'!$E:$E,Front!$B:$B,'3 D P'!K:K) -> 51 | M4: =SUMIF('3 D P'!$E:$E,Front!$B:$B,'3 D P'!L:L) -> 49 | N4: =IFERROR(VLOOKUP(A4,'Front Dispatch'!A:B,2,0),0) -> 289 | O4: =SUMIF('Consumption MTD'!$B:$B,$B$2:$B$17,'Consumption MTD'!$C:$C) -> 300 | P4: =SUMIF('BIW Lifting A Shift'!$B:$B,$B$2:$B$15,'BIW Lifting A Shift'!$C:$C) -> 0 | Q4: =SUMIF('BIW Lifting B Shift'!$B:$B,$B$2:$B$15,'BIW Lifting B Shift'!$C:$C) -> 0 | R4: =J4-U4 -> 23 | S4: =J4-P4-U4 -> 23 | T4: =S4-Q4 -> 23 | U4: =SUMIF(FLOAT!$D:$D,$B$2:$B$15,FLOAT!$F:$F) -> 10 | V4: 23 | Y4: 1 | Z4: =SUMIF(FLOAT!$D:$D,$B$2:$B$14,FLOAT!$F:$F) -> 10 | AA4: =SUMIF(FLOAT!$D:$D,$B$2:$B$13,FLOAT!$G:$G) -> 3 | AB4: =SUMIF(FLOAT!$D:$D,$B$2:$B$13,FLOAT!$H:$H) -> 1 | AC4: =SUMIF(FLOAT!$D:$D,$B$2:$B$13,FLOAT!$I:$I) -> 0 | AD4: =SUMIF(FLOAT!$D:$D,$B$2:$B$13,FLOAT!$J:$J) -> 0 | AE4: =SUMIF(FLOAT!$D:$D,$B$2:$B$13,FLOAT!$K:$K) -> 1 | AF4: =SUMIF(FLOAT!$D:$D,$B$2:$B$13,FLOAT!$L:$L) -> 1 | AG4: =SUMIF(FLOAT!$D:$D,$B$2:$B$6,FLOAT!$M:$M) -> 6 | AH4: =SUMIF(FLOAT!$D:$D,$B$2:$B$13,FLOAT!$N:$N) -> 0 | AI4: =SUMIF(FLOAT!$D:$D,$B$2:$B$13,FLOAT!$O:$O) -> 4 | AJ4: =SUMIF(FLOAT!$D:$D,$B$2:$B$13,FLOAT!$P:$P) -> 0 | AK4: =SUM(AA4:AF4)+SUM(AH4:AJ4) -> 10 | AO4: 1
A5: 546854620387 | B5: 54686324A | C5: PUNCH.EV ADV LR | D5: 335 | E5: 830 | F5: 29 | G5: =N5 -> 326 | H5: =O5 -> 290 | I5: =E5-H5 -> 540 | J5: =F5+G5-H5 -> 65 | K5: =SUMIF('3 D P'!$E:$E,Front!$B:$B,'3 D P'!J:J) -> 174 | L5: =SUMIF('3 D P'!$E:$E,Front!$B:$B,'3 D P'!K:K) -> 158 | M5: =SUMIF('3 D P'!$E:$E,Front!$B:$B,'3 D P'!L:L) -> 98 | N5: =IFERROR(VLOOKUP(A5,'Front Dispatch'!A:B,2,0),0) -> 326 | O5: =SUMIF('Consumption MTD'!$B:$B,$B$2:$B$17,'Consumption MTD'!$C:$C) -> 290 | P5: =SUMIF('BIW Lifting A Shift'!$B:$B,$B$2:$B$15,'BIW Lifting A Shift'!$C:$C) -> 0 | Q5: =SUMIF('BIW Lifting B Shift'!$B:$B,$B$2:$B$15,'BIW Lifting B Shift'!$C:$C) -> 0 | R5: =J5-U5 -> 13 | S5: =J5-P5-U5 -> 13 | T5: =S5-Q5 -> 13 | U5: =SUMIF(FLOAT!$D:$D,$B$2:$B$15,FLOAT!$F:$F) -> 52 | V5: 16 | Y5: 1 | Z5: =SUMIF(FLOAT!$D:$D,$B$2:$B$14,FLOAT!$F:$F) -> 52 | AA5: =SUMIF(FLOAT!$D:$D,$B$2:$B$13,FLOAT!$G:$G) -> 2 | AB5: =SUMIF(FLOAT!$D:$D,$B$2:$B$13,FLOAT!$H:$H) -> 2 | AC5: =SUMIF(FLOAT!$D:$D,$B$2:$B$13,FLOAT!$I:$I) -> 8 | AD5: =SUMIF(FLOAT!$D:$D,$B$2:$B$13,FLOAT!$J:$J) -> 0 | AE5: =SUMIF(FLOAT!$D:$D,$B$2:$B$13,FLOAT!$K:$K) -> 5 | AF5: =SUMIF(FLOAT!$D:$D,$B$2:$B$13,FLOAT!$L:$L) -> 11 | AG5: =SUMIF(FLOAT!$D:$D,$B$2:$B$6,FLOAT!$M:$M) -> 28 | AH5: =SUMIF(FLOAT!$D:$D,$B$2:$B$13,FLOAT!$N:$N) -> 13 | AI5: =SUMIF(FLOAT!$D:$D,$B$2:$B$13,FLOAT!$O:$O) -> 11 | AJ5: =SUMIF(FLOAT!$D:$D,$B$2:$B$13,FLOAT!$P:$P) -> 0 | AK5: =SUM(AA5:AF5)+SUM(AH5:AJ5) -> 52 | AO5: 1
A6: 546854620346 | B6: 54686724A | C6: PUNCH.EV EMP + LR | D6: 235 | E6: 230 | F6: =26+3 -> 29 | G6: =N6 -> 178 | H6: =O6 -> 132 | I6: =E6-H6 -> 98 | J6: =F6+G6-H6 -> 75 | K6: =SUMIF('3 D P'!$E:$E,Front!$B:$B,'3 D P'!J:J) -> 7 | L6: =SUMIF('3 D P'!$E:$E,Front!$B:$B,'3 D P'!K:K) -> 19 | M6: =SUMIF('3 D P'!$E:$E,Front!$B:$B,'3 D P'!L:L) -> 3 | N6: =IFERROR(VLOOKUP(A6,'Front Dispatch'!A:B,2,0),0) -> 178 | O6: =SUMIF('Consumption MTD'!$B:$B,$B$2:$B$17,'Consumption MTD'!$C:$C) -> 132 | P6: =SUMIF('BIW Lifting A Shift'!$B:$B,$B$2:$B$15,'BIW Lifting A Shift'!$C:$C) -> 0 | Q6: =SUMIF('BIW Lifting B Shift'!$B:$B,$B$2:$B$15,'BIW Lifting B Shift'!$C:$C) -> 0 | R6: =J6-U6 -> 71 | S6: =J6-P6-U6 -> 71 | T6: =S6-Q6 -> 71 | U6: =SUMIF(FLOAT!$D:$D,$B$2:$B$15,FLOAT!$F:$F) -> 4 | V6: 3 | Y6: 1 | Z6: =SUMIF(FLOAT!$D:$D,$B$2:$B$14,FLOAT!$F:$F) -> 4 | AA6: =SUMIF(FLOAT!$D:$D,$B$2:$B$13,FLOAT!$G:$G) -> 1 | AB6: =SUMIF(FLOAT!$D:$D,$B$2:$B$13,FLOAT!$H:$H) -> 1 | AC6: =SUMIF(FLOAT!$D:$D,$B$2:$B$13,FLOAT!$I:$I) -> 0 | AD6: =SUMIF(FLOAT!$D:$D,$B$2:$B$13,FLOAT!$J:$J) -> 0 | AE6: =SUMIF(FLOAT!$D:$D,$B$2:$B$13,FLOAT!$K:$K) -> 0 | AF6: =SUMIF(FLOAT!$D:$D,$B$2:$B$13,FLOAT!$L:$L) -> 0 | AG6: =SUMIF(FLOAT!$D:$D,$B$2:$B$6,FLOAT!$M:$M) -> 2 | AH6: =SUMIF(FLOAT!$D:$D,$B$2:$B$13,FLOAT!$N:$N) -> 1 | AI6: =SUMIF(FLOAT!$D:$D,$B$2:$B$13,FLOAT!$O:$O) -> 1 | AJ6: =SUMIF(FLOAT!$D:$D,$B$2:$B$13,FLOAT!$P:$P) -> 0 | AK6: =SUM(AA6:AF6)+SUM(AH6:AJ6) -> 4 | AO6: 1
A7: 546854620389 | B7: 54686824A | C7: PUNCH.EV EMP + S LR | D7: 2672 | E7: 2297 | F7: 64 | G7: =N7 -> 1407 | H7: =O7 -> 1326 | I7: =E7-H7 -> 971 | J7: =F7+G7-H7 -> 145 | K7: =SUMIF('3 D P'!$E:$E,Front!$B:$B,'3 D P'!J:J) -> 78 | L7: =SUMIF('3 D P'!$E:$E,Front!$B:$B,'3 D P'!K:K) -> 37 | M7: =SUMIF('3 D P'!$E:$E,Front!$B:$B,'3 D P'!L:L) -> 115 | N7: =IFERROR(VLOOKUP(A7,'Front Dispatch'!A:B,2,0),0) -> 1407 | O7: =SUMIF('Consumption MTD'!$B:$B,$B$2:$B$17,'Consumption MTD'!$C:$C) -> 1326 | P7: =SUMIF('BIW Lifting A Shift'!$B:$B,$B$2:$B$15,'BIW Lifting A Shift'!$C:$C) -> 0 | Q7: =SUMIF('BIW Lifting B Shift'!$B:$B,$B$2:$B$15,'BIW Lifting B Shift'!$C:$C) -> 0 | R7: =J7-U7 -> 30 | S7: =J7-P7-U7 -> 30 | T7: =S7-Q7 -> 30 | U7: =SUMIF(FLOAT!$D:$D,$B$2:$B$15,FLOAT!$F:$F) -> 115 | V7: 125 | Y7: 1 | Z7: =SUMIF(FLOAT!$D:$D,$B$2:$B$14,FLOAT!$F:$F) -> 115 | AA7: =SUMIF(FLOAT!$D:$D,$B$2:$B$13,FLOAT!$G:$G) -> 24 | AB7: =SUMIF(FLOAT!$D:$D,$B$2:$B$13,FLOAT!$H:$H) -> 5 | AC7: =SUMIF(FLOAT!$D:$D,$B$2:$B$13,FLOAT!$I:$I) -> 14 | AD7: =SUMIF(FLOAT!$D:$D,$B$2:$B$13,FLOAT!$J:$J) -> 1 | AE7: =SUMIF(FLOAT!$D:$D,$B$2:$B$13,FLOAT!$K:$K) -> 5 | AF7: =SUMIF(FLOAT!$D:$D,$B$2:$B$13,FLOAT!$L:$L) -> 24 | AG7: =SUMIF(FLOAT!$D:$D,$B$2:$B$8,FLOAT!$M:$M) -> 73 | AH7: =SUMIF(FLOAT!$D:$D,$B$2:$B$13,FLOAT!$N:$N) -> 16 | AI7: =SUMIF(FLOAT!$D:$D,$B$2:$B$13,FLOAT!$O:$O) -> 26 | AJ7: =SUMIF(FLOAT!$D:$D,$B$2:$B$13,FLOAT!$P:$P) -> 0 | AK7: =SUM(AA7:AF7)+SUM(AH7:AJ7) -> 115 | AO7: 4
D8: =SUM(D2:D7) -> 3992 | E8: =SUM(E2:E7) -> 3651 | F8: =SUM(F2:F7) -> 176 | G8: =SUM(G2:G7) -> 2200 | H8: =SUM(H2:H7) -> 2048 | I8: =SUM(I2:I7) -> 1603 | J8: =SUM(J2:J7) -> 328 | K8: =SUM(K2:K7) -> 262 | ... Q8: =SUM(Q2:Q7) -> 0 | U8: =SUM(U2:U7) -> 181 | V8: =SUM(V2:V7) -> 179 | W8: =SUM(W2:W7) -> 0 | X8: =SUM(X2:X7) -> 0 | Y8: =SUM(Y2:Y7) -> 6 | Z8: =SUM(Z2:Z7) -> 181 | AA8: =SUM(AA2:AA7) -> 30 | AB8: =SUM(AB2:AB7) -> 9 | ... AK8: =SUM(AK2:AK7) -> 181

Sheet Summary
B3: NOVA-Cockpit Summary | E3: NOVA-Front Summary
B4: Morning Float | C4: ='Cockpit sheet'!U16+'Cockpit sheet'!U7 -> 181 | E4: Morning Float | F4: =Front!U8 -> 181
B5: Fresh Lifting | C5: ='Cockpit sheet'!$P$16+'Cockpit sheet'!$Q$16 -> 0 | E5: Fresh Lifting | F5: =Front!P8+Front!Q8 -> 0
B6: Total Plan | C6: =C4+C5 -> 181 | E6: Total Plan | F6: =F4+F5 -> 181
B7: Coverage | C7: =C6+C10 -> 181 | E7: Coverage | F7: =F6+F10 -> 181
B8: Shortfall Against Morning Float | C8: =SUMIF('Cockpit sheet'!$R:$R,"<0") -> 0 | E8: Shortfall Against Morning Float | F8: =SUMIF(Front!$R:$R,"<0") -> 0
B9: Shortfall Against 1st Shift Lifting | C9: =SUMIF('Cockpit sheet'!$S:$S,"<0") -> 0 | E9: Shortfall Against 1st Shift Lifting | F9: =SUMIF(Front!$S:$S,"<0") -> 0
B10: Shortfall Against 2nd Shift Lifting | C10: =SUMIF('Cockpit sheet'!$T:$T,"<0") -> 0 | E10: Shortfall Against 2nd Shift Lifting | F10: =SUMIF(Front!$T:$T,"<0") -> 0

Sheet BIW Lifting A Shift
A1: MODEL | B1: VEHICLE CODE | C1: TOTAL

Sheet BIW Lifting B Shift
A1: MODEL | B1: VEHICLE CODE | C1: TOTAL

Sheet Daywise Dispatch
A1: part | B1: Cumulative Dispatch | C1: Month Plan | D1: Balance | E1: 46204 | J1: 46205 | O1: 46206 | T1: 46207 | Y1: 46208 | AD1: 46209 | AI1: 46210 | AN1: 46211 | AS1: 46212 | AX1: 46213 | BC1: 46214 | BH1: 46215 | BM1: 46216 | BR1: 46217 | BW1: 46218 | CB1: 46219 | CG1: 46220 | CL1: 46221 | CQ1: 46222 | CV1: 46223 | DA1: 46224 | DF1: 46225 | DK1: 46226 | DP1: 46227 | DU1: 46228 | DZ1: 46229 | EE1: 46230 | EJ1: 46231 | EO1: 46232 | ET1: 46233 | EY1: 46234
J2: 1946 | T2: 6033 | U2: 9785 | Y2: 6033 | AD2: 6033 | AE2: 6032 | AI2: 6032 | AJ2: 9785 | AS2: 9785 | AX2: 9785 | AY2: 9785 | BC2: 9785 | BD2: 9785 | BH2: 9785 | BM2: 9785 | BR2: 9785 | BW2: 9785 | BX2: 9785 | CB2: 9785 | CC2: 9785 | CG2: 9785 | CH2: 6032
J3: ap | T3: pa | U3: tk | Y3: pa | AD3: tk | AE3: ap | AI3: ap | AJ3: ap | AS3: pa | AX3: PA | AY3: ap | BC3: ap | BD3: ap | BH3: ap | BM3: pa | BR3: pa | BW3: pj | BX3: pa | CB3: pa | CC3: pa | CG3: pj | CH3: pa
A5: 546854600231 | B5: =SUM(E5:FC5) -> 0 | C5: =IFERROR(VLOOKUP(A5,'Cockpit sheet'!A:E,5,0),0) -> 0 | D5: =C5-B5 -> 0
A6: 546854650116 | B6: =SUM(E6:FC6) -> 1282 | C6: =IFERROR(VLOOKUP(A6,'Cockpit sheet'!A:E,5,0),0) -> 2297 | D6: =C6-B6 -> 1015 | J6: 42 | T6: 16 | U6: 58 | Y6: 56 | AD6: 66 | AE6: 32 | AI6: 105 | AJ6: 67 | AS6: 102 | AX6: 63 | AY6: 68 | BC6: 13 | BD6: 61 | BH6: 98 | BM6: 4 | BR6: 108 | BW6: 28 | BX6: 44 | CB6: 50 | CC6: 44 | CG6: 80 | CH6: 77
A7: 546854650101 | B7: =SUM(E7:FC7) -> 0 | C7: =IFERROR(VLOOKUP(A7,'Cockpit sheet'!A:E,5,0),0) -> 0 | D7: =C7-B7 -> 0
A8: 546854650102 | B8: =SUM(E8:FC8) -> 0 | C8: =IFERROR(VLOOKUP(A8,'Cockpit sheet'!A:E,5,0),0) -> 0 | D8: =C8-B8 -> 0
A9: 546854650110 | B9: =SUM(E9:FC9) -> 385 | C9: =IFERROR(VLOOKUP(A9,'Cockpit sheet'!A:E,5,0),0) -> 294 | D9: =C9-B9 -> -91 | J9: 40 | U9: 36 | Y9: 3 | AD9: 33 | AE9: 20 | AI9: 8 | AJ9: 48 | AX9: 5 | AY9: 31 | BC9: 64 | BD9: 1 | BM9: 48 | BW9: 36 | BX9: 4 | CB9: 8
A10: 546854650111 | B10: =SUM(E10:FC10) -> 369 | C10: =IFERROR(VLOOKUP(A10,'Cockpit sheet'!A:E,5,0),0) -> 830 | D10: =C10-B10 -> 461 | J10: 32 | T10: 21 | AD10: 15 | AE10: 18 | AI10: 2 | AX10: 47 | AY10: 16 | BC10: 29 | BD10: 3 | BH10: 2 | BM10: 18 | BR10: 5 | BW10: 51 | BX10: 25 | CB10: 20 | CC10: 25 | CG10: 4 | CH10: 36
A11: 546854650115 | B11: =SUM(E11:FC11) -> 99 | C11: =IFERROR(VLOOKUP(A11,'Cockpit sheet'!A:E,5,0),0) -> 230 | D11: =C11-B11 -> 131 | J11: 1 | BH11: 14 | BM11: 36 | BR11: 2 | BX11: 37 | CC11: 6 | CG11: 3
A12: Total | B12: =SUM(B5:B5) -> 0 | C12: =SUM(C5:C5) -> 0 | D12: =SUM(D5:D5) -> 0 | E12: =SUM(E5:E11) -> 0 | F12: =SUM(F5:F11) -> 0 | G12: =SUM(G5:G11) -> 0 | H12: =SUM(H5:H11) -> 0 | I12: =SUM(I5:I11) -> 0 | J12: =SUM(J5:J11) -> 115 | K12: =SUM(K5:K11) -> 0 | L12: =SUM(L5:L11) -> 0 | ... FC12: =SUM(FC5:FC11) -> 0
Y13: =SUM(Y12:AC12) -> 59 | AD13: =SUM(AD12:AH12) -> 184 | AI13: =SUM(AI12:AM12) -> 230 | AN13: =SUM(AN12:AR12) -> 0 | AS13: =SUM(AS12:AW12) -> 102 | AX13: =SUM(AX12:BB12) -> 230 | BC13: =SUM(BC12:BG12) -> 171 | BH13: =SUM(BH12:BL12) -> 114 | BM13: =SUM(BM12:BQ12) -> 106 | BR13: =SUM(BR12:BV12) -> 115 | BW13: =SUM(BW12:CA12) -> 225 | CB13: =SUM(CB12:CF12) -> 153 | CG13: =SUM(CG12:CK12) -> 200 | CL13: =SUM(CL12:CP12) -> 0 | CQ13: =SUM(CQ12:CU12) -> 0 | CV13: =SUM(CV12:CZ12) -> 0 | DA13: =SUM(DA12:DE12) -> 0 | DF13: =SUM(DF12:DJ12) -> 0 | DK13: =SUM(DK12:DO12) -> 0 | DP13: =SUM(DP12:DT12) -> 0 | DU13: =SUM(DU12:DY12) -> 0 | DZ13: =SUM(DZ12:ED12) -> 0 | EE13: =SUM(EE12:EI12) -> 0 | EJ13: =SUM(EJ12:EN12) -> 0 | EO13: =SUM(EO12:ES12) -> 0 | ET13: =SUM(ET12:EX12) -> 0 | EY13: =SUM(EY12:FC12) -> 0

Sheet Sheet4
A1: Plant | B1: Movement Type | C1: Posting Date | D1: Time of Entry | E1: Material Document | F1: Material | G1: Material Description | H1: Quantity | I1: Amount in LC | J1: Storage Location | K1: Vendor | L1: User name | M1: Text | N1: Reason for Movement | O1: Cost Center | P1: Reference
A2: 1100 | B2: 101 | C2: 46114 | D2: 0.56457176 | E2: 8401612518 | F2: 546854620346 | G2: WH FRONT | H2: 4 | I2: 36579.68 | J2: KA21 | K2: Y60391 | L2: SDM860598 | M2: SP2.PROWIZ/03.04.2026/18:45:31 | N2: 0 | P2: 2511129049 | Q2: Row Labels | R2: Sum of Quantity
A3: 1100 | B3: 101 | C3: 46114 | D3: 0.56424769 | E3: 8401612516 | F3: 546854620389 | G3: WH FRONT | H3: 75 | I3: 678325.5 | J3: KA21 | K3: Y60391 | L3: SDM860598 | M3: SP2.PROWIZ/03.04.2026/18:58:42 | N3: 0 | P3: 2511129048 | Q3: 546854620346 | R3: 87 | S3: 546854620346 | T3: 87
A4: 1100 | B4: 101 | C4: 46116 | D4: 0.34826389 | E4: 8401637959 | F4: 546854620346 | G4: WH FRONT | H4: 11 | I4: 100594.12 | J4: KA21 | K4: Y60391 | L4: CTPVCRDOKI02 | M4: CMMPVKRUSHNA/04.04.2026/12:46:59 | N4: 0 | P4: 2611000761 | Q4: 546854620355 | R4: 480 | S4: 546854620355 | T4: 480
A5: 1100 | B5: 101 | C5: 46116 | D5: 0.3471412 | E5: 8401637952 | F5: 546854620355 | G5: WH FRONT | H5: 10 | I5: 88097.7 | J5: KA21 | K5: Y60391 | L5: CTPVCRDOKI02 | M5: CMMPVKRUSHNA/04.04.2026/12:47:21 | N5: 0 | P5: 2611000754 | Q5: 546854620387 | R5: 157 | S5: 546854620387 | T5: 157
A6: 1100 | B6: 101 | C6: 46116 | D6: 0.34697917 | E6: 8401637951 | F6: 546854620389 | G6: WH FRONT | H6: 70 | I6: 633103.8 | J6: KA21 | K6: Y60391 | L6: CTPVCRDOKI02 | M6: CMMPVKRUSHNA/04.04.2026/12:46:45 | N6: 0 | P6: 2611000753 | Q6: 546854620389 | R6: 1085 | S6: 546854620389 | T6: 1085
A7: 1100 | B7: 101 | C7: 46117 | D7: 0.25494213 | E7: 8401653001 | F7: 546854620355 | G7: WH FRONT | H7: 15 | I7: 132146.55 | J7: KA21 | K7: Y60391 | L7: CTPVCRDOKI06 | M7: CMMPVKRUSHNA/05.04.2026/09:09:28 | N7: 0 | P7: 2611001145 | Q7: Grand Total | R7: 1809
A8: 1100 | B8: 101 | C8: 46117 | D8: 0.25475694 | E8: 8401653000 | F8: 546854620389 | G8: WH FRONT | H8: 10 | I8: 90443.4 | J8: KA21 | K8: Y60391 | L8: CTPVCRDOKI06 | M8: CMMPVKRUSHNA/05.04.2026/09:09:41 | N8: 0 | P8: 2611001144
A9: 1100 | B9: 101 | C9: 46118 | D9: 0.90114583 | E9: 8401672067 | F9: 546854620355 | G9: WH FRONT | H9: 40 | I9: 352390.8 | J9: KA21 | K9: Y60391 | L9: CTPVCRDOKI01 | M9: CMMPVKRUSHNA/07.04.2026/00:43:21 | N9: 0 | P9: 2611001594
A10: 1100 | B10: 101 | C10: 46118 | D10: 0.38905093 | E10: 8401657230 | F10: 546854620355 | G10: WH FRONT | H10: 10 | I10: 88097.7 | J10: KA21 | K10: Y60391 | L10: CTPVCRDOKI02 | M10: CMMPVKRUSHNA/06.04.2026/12:13:51 | N10: 0 | P10: 2611001229
A11: 1100 | B11: 101 | C11: 46118 | D11: 0.90126157 | E11: 8401672068 | F11: 546854620387 | G11: WH FRONT | H11: 5 | I11: 43729.6 | J11: KA21 | K11: Y60391 | L11: CTPVCRDOKI01 | M11: CMMPVKRUSHNA/07.04.2026/00:43:31 | N11: 0 | P11: 2611001595
A12: 1100 | B12: 101 | C12: 46118 | D12: 0.90101852 | E12: 8401672065 | F12: 546854620389 | G12: WH FRONT | H12: 5 | I12: 45221.7 | J12: KA21 | K12: Y60391 | L12: CTPVCRDOKI01 | M12: CMMPVKRUSHNA/07.04.2026/00:43:10 | N12: 0 | P12: 2611001593
A13: 1100 | B13: 101 | C13: 46118 | D13: 0.38888889 | E13: 8401657199 | F13: 546854620389 | G13: WH FRONT | H13: 30 | I13: 271330.2 | J13: KA21 | K13: Y60391 | L13: CTPVCRDOKI02 | M13: CMMPVKRUSHNA/06.04.2026/12:13:32 | N13: 0 | P13: 2611001228
A14: 1100 | B14: 101 | C14: 46119 | D14: 0.62832176 | E14: 8401683760 | F14: 546854620355 | G14: WH FRONT | H14: 81 | I14: 713591.37 | J14: KA21 | K14: Y60391 | L14: AAD860617 | M14: CMMPVKRUSHNA/07.04.2026/17:31:47 | N14: 0 | P14: 2611001048
A15: 1100 | B15: 101 | C15: 46119 | D15: 0.58386574 | E15: 8401681899 | F15: 546854620355 | G15: WH FRONT | H15: 20 | I15: 176195.4 | J15: KA21 | K15: Y60391 | L15: CTPVCRDOKI02 | M15: CMMPVKRUSHNA/07.04.2026/17:37:51 | N15: 0 | P15: 2611001877
A16: 1100 | B16: 101 | C16: 46119 | D16: 0.5840162 | E16: 8401682110 | F16: 546854620387 | G16: WH FRONT | H16: 5 | I16: 43729.6 | J16: KA21 | K16: Y60391 | L16: CTPVCRDOKI02 | M16: CMMPVKRUSHNA/07.04.2026/17:37:20 | N16: 0 | P16: 2611001878
A17: 1100 | B17: 101 | C17: 46119 | D17: 0.6255787 | E17: 8401683590 | F17: 546854620389 | G17: WH FRONT | H17: 44 | I17: 397950.96 | J17: KA21 | K17: Y60391 | L17: AAD860617 | M17: CMMPVKRUSHNA/07.04.2026/17:32:56 | N17: 0 | P17: 2611001057
A18: 1100 | B18: 101 | C18: 46119 | D18: 0.5849537 | E18: 8401682116 | F18: 546854620389 | G18: WH FRONT | H18: 40 | I18: 361773.6 | J18: KA21 | K18: Y60391 | L18: CTPVCRDOKI02 | M18: CMMPVKRUSHNA/07.04.2026/17:38:14 | N18: 0 | P18: 2611001893
A19: 1100 | B19: 101 | C19: 46120 | D19: 0.48337963 | E19: 8401696388 | F19: 546854620355 | G19: WH FRONT | H19: 11 | I19: 96907.47 | J19: KA21 | K19: Y60391 | L19: CTPVCRDOKI02 | M19: CMMPVKRUSHNA/08.04.2026/13:21:01 | N19: 0 | P19: 2611002381
... A68: 1100 | B68: 101 | C68: 46130 | D68: 0.059039352 | E68: 8401873416 | F68: 546854620389 | G68: WH FRONT | H68: 56 | I68: 513157.12 | J68: KA21 | K68: Y60391 | L68: CTPVCRDOKI02 | M68: CMMPVKRUSHNA/18.04.2026/02:55:37 | N68: 0 | P68: 2611006901

Sheet Front Dispatch
A1: Part | B1: Cumulative Dispatch | C1: SAP inwarding Till | D1: Balance | E1: 46204 | J1: 46205 | O1: 46206 | T1: 46207 | Y1: 46208 | AD1: 46209 | AI1: 46210 | AN1: 46211 | AS1: 46212 | AX1: 46213 | BC1: 46214 | BH1: 46215 | BM1: 46216 | BR1: 46217 | BW1: 46218 | CB1: 46219 | CG1: 46220 | CL1: 46221 | CQ1: 46222 | CV1: 46223 | DA1: 46224 | DF1: 46225 | DK1: 46226 | DP1: 46227 | DU1: 46228 | DZ1: 46229 | EE1: 46230 | EJ1: 46231 | EO1: 46232 | ET1: 46233 | EY1: 46234
E2: 6032 | O2: 6032 | P2: 6032 | Q2: 6032 | T2: 6032 | U2: 6032 | Y2: 6032 | Z2: 6032 | AA2: 6032 | AN2: 6032 | AS2: 6032 | AT2: 6032 | AX2: 6032 | AY2: 6032 | BC2: 6032 | BD2: 6032 | BE2: 6032 | BH2: 6032 | BM2: 6032 | BR2: 6032 | BS2: 6032 | BW2: 6032 | BX2: 6032 | CB2: 6032 | CC2: 6032 | CG2: 6032 | CH2: 6032 | CI2: 9785
E3: ap | O3: pa | P3: tk | Q3: ap | T3: tk | U3: ap | Y3: pa | Z3: TK | AA3: ap | AN3: pa | AS3: pj | AT3: ap | AX3: PA | AY3: ap | BC3: sj | BD3: ap | BE3: ap | BH3: pa | BM3: pa | BR3: pa | BS3: pa | BW3: PJ | BX3: pa | CB3: pa | CC3: pa | CG3: pj | CH3: pa | CI3: pa
A5: 546854620381 | B5: =SUM(E5:FC5) -> 0 | C5: =SUMIF(SAP!$F:$F,'Front Dispatch'!$A:$A,SAP!$H:$H) -> 0 | D5: =C5-B5 -> 0
A6: 546854620382 | B6: =SUM(E6:FC6) -> 0 | C6: =SUMIF(SAP!$F:$F,'Front Dispatch'!$A:$A,SAP!$H:$H) -> 0 | D6: =C6-B6 -> 0
A7: 546854620355 | B7: =SUM(E7:FC7) -> 289 | C7: =SUMIF(SAP!$F:$F,'Front Dispatch'!$A:$A,SAP!$H:$H) -> 192 | D7: =C7-B7 -> -97 | P7: 40 | Q7: 4 | T7: 10 | U7: 19 | Y7: 20 | Z7: 7 | AS7: 20 | AX7: 12 | AY7: 18 | BC7: 15 | BE7: 22 | BH7: 5 | BM7: 5 | BR7: 10 | BS7: 5 | BW7: 5 | BX7: 5 | CB7: 16 | CC7: 26 | CG7: 5 | CH7: 20
A8: 546854620387 | B8: =SUM(E8:FC8) -> 326 | C8: =SUMIF(SAP!$F:$F,'Front Dispatch'!$A:$A,SAP!$H:$H) -> 260 | D8: =C8-B8 -> -66 | E8: 13 | O8: 30 | P8: 22 | Q8: 70 | T8: 56 | Y8: 4 | Z8: 5 | AX8: 16 | BC8: 20 | BD8: 7 | BH8: 17 | BM8: 5 | BS8: 5 | BW8: 6 | BX8: 30 | CH8: 20
A9: 546854620346 | B9: =SUM(E9:FC9) -> 178 | C9: =SUMIF(SAP!$F:$F,'Front Dispatch'!$A:$A,SAP!$H:$H) -> 15 | D9: =C9-B9 -> -163 | Q9: 15 | BR9: 40 | BS9: 30 | BW9: 27 | BX9: 8 | CB9: 6 | CC9: 13 | CG9: 19 | CH9: 20
A10: 546854620389 | B10: =SUM(E10:FC10) -> 1407 | C10: =SUMIF(SAP!$F:$F,'Front Dispatch'!$A:$A,SAP!$H:$H) -> 891 | D10: =C10-B10 -> -516 | E10: 54 | O10: 60 | P10: 32 | Q10: 6 | T10: 20 | U10: 55 | Y10: 51 | Z10: 61 | AA10: 60 | AN10: 57 | AS10: 50 | AT10: 64 | AX10: 45 | AY10: 51 | BC10: 63 | BD10: 70 | BE10: 28 | BH10: 64 | BM10: 56 | BR10: 54 | BS10: 50 | BW10: 40 | BX10: 59 | CB10: 44 | CC10: 64 | CG10: 41 | CH10: 59 | CI10: 49
A11: Total | B11: =SUM(B5:B10) -> 2200 | C11: =SUM(C5:C10) -> 1358 | D11: =SUM(D5:D10) -> -842 | E11: =SUM(E5:E10) -> 67 | F11: =SUM(F5:F10) -> 0 | G11: =SUM(G5:G10) -> 0 | H11: =SUM(H5:H10) -> 0 | I11: =SUM(I5:I10) -> 0 | ... FC11: =SUM(FC5:FC10) -> 0

Sheet SAP
A1: Plant | B1: Movement Type | C1: Posting Date | D1: Time of Entry | E1: Material Document | F1: Material | G1: Material Description | H1: Quantity | I1: Amount in LC | J1: Storage Location | K1: Vendor | L1: User name | M1: Text | N1: Reason for Movement | O1: Cost Center | P1: Reference
A2: 1100 | B2: 101 | C2: 46205 | D2: 0.7021875 | E2: 8403264381 | F2: 546854620387 | G2: WH FRONT | H2: 13 | I2: 115246.3 | J2: KA21 | K2: Y60391 | L2: NAB860618 | M2: CMMPVKRUSHNA/04.07.2026/00:49:10 | N2: 0 | P2: 2611037242
A3: 1100 | B3: 101 | C3: 46205 | D3: 0.701875 | E3: 8403264356 | F3: 546854620389 | G3: WH FRONT | H3: 54 | I3: 494830.08 | J3: KA21 | K3: Y60391 | L3: NAB860618 | M3: CMMPVKRUSHNA/08.07.2026/15:51:44 | N3: 0 | P3: 2611037241
A4: 1100 | B4: 101 | C4: 46206 | D4: 0.86707176 | E4: 8403294585 | F4: 546854620355 | G4: WH FRONT | H4: 40 | I4: 357158 | J4: KA21 | K4: Y60391 | L4: CTPVCRDOKI01 | M4: CMMPVKRUSHNA/03.07.2026/22:34:25 | N4: 0 | P4: 2611037869
